[12/Mar/2018 08:47:51] DEBUG [/home/thqbop/workspace/Ribo/RiBo-Core/env/lib/python3.5/site-packages/django/db/backends/utils.py:89] (0.000) SET SQL_AUTO_IS_NULL = 0; args=None
[12/Mar/2018 08:48:15] DEBUG [/home/thqbop/workspace/Ribo/RiBo-Core/env/lib/python3.5/site-packages/django/db/backends/utils.py:89] (0.000) SET SQL_AUTO_IS_NULL = 0; args=None
[12/Mar/2018 08:48:54] DEBUG [/home/thqbop/workspace/Ribo/RiBo-Core/env/lib/python3.5/site-packages/django/db/backends/utils.py:89] (0.000) SET SQL_AUTO_IS_NULL = 0; args=None
[12/Mar/2018 08:48:54] DEBUG [/home/thqbop/workspace/Ribo/RiBo-Core/env/lib/python3.5/site-packages/django/db/backends/utils.py:89] (0.000) SET SQL_AUTO_IS_NULL = 0; args=None
[12/Mar/2018 08:48:54] DEBUG [/home/thqbop/workspace/Ribo/RiBo-Core/env/lib/python3.5/site-packages/django/db/backends/utils.py:89] (0.000) SHOW FULL TABLES; args=None
[12/Mar/2018 08:48:54] DEBUG [/home/thqbop/workspace/Ribo/RiBo-Core/env/lib/python3.5/site-packages/django/db/backends/base/schema.py:101] CREATE TABLE `django_migrations` (`id` integer AUTO_INCREMENT NOT NULL PRIMARY KEY, `app` varchar(255) NOT NULL, `name` varchar(255) NOT NULL, `applied` datetime(6) NOT NULL); (params None)
[12/Mar/2018 08:48:54] DEBUG [/home/thqbop/workspace/Ribo/RiBo-Core/env/lib/python3.5/site-packages/django/db/backends/utils.py:89] (0.039) CREATE TABLE `django_migrations` (`id` integer AUTO_INCREMENT NOT NULL PRIMARY KEY, `app` varchar(255) NOT NULL, `name` varchar(255) NOT NULL, `applied` datetime(6) NOT NULL); args=None
[12/Mar/2018 08:48:54] DEBUG [/home/thqbop/workspace/Ribo/RiBo-Core/env/lib/python3.5/site-packages/django/db/backends/utils.py:89] (0.003) SELECT engine FROM information_schema.tables WHERE table_name = 'django_migrations'; args=['django_migrations']
[12/Mar/2018 08:48:54] DEBUG [/home/thqbop/workspace/Ribo/RiBo-Core/env/lib/python3.5/site-packages/django/db/backends/utils.py:89] (0.002) SELECT `django_migrations`.`app`, `django_migrations`.`name` FROM `django_migrations`; args=()
[13/Mar/2018 16:19:17] DEBUG [/media/thqbop/data/Hoctap/NNLaptrinh/Python/Projects/RiBo-Core/env/lib/python3.5/site-packages/django/db/backends/utils.py:89] (0.000) SET SQL_AUTO_IS_NULL = 0; args=None
[13/Mar/2018 16:19:18] DEBUG [/media/thqbop/data/Hoctap/NNLaptrinh/Python/Projects/RiBo-Core/env/lib/python3.5/site-packages/django/db/backends/utils.py:89] (0.000) SET SQL_AUTO_IS_NULL = 0; args=None
[13/Mar/2018 16:19:18] DEBUG [/media/thqbop/data/Hoctap/NNLaptrinh/Python/Projects/RiBo-Core/env/lib/python3.5/site-packages/django/db/backends/utils.py:89] (0.001) SHOW FULL TABLES; args=None
[13/Mar/2018 16:19:18] DEBUG [/media/thqbop/data/Hoctap/NNLaptrinh/Python/Projects/RiBo-Core/env/lib/python3.5/site-packages/django/db/backends/utils.py:89] (0.018) SELECT `django_migrations`.`app`, `django_migrations`.`name` FROM `django_migrations`; args=()
[13/Mar/2018 16:21:36] DEBUG [/media/thqbop/data/Hoctap/NNLaptrinh/Python/Projects/RiBo-Core/env/lib/python3.5/site-packages/django/db/backends/utils.py:89] (0.000) SET SQL_AUTO_IS_NULL = 0; args=None
[13/Mar/2018 16:21:43] DEBUG [/media/thqbop/data/Hoctap/NNLaptrinh/Python/Projects/RiBo-Core/env/lib/python3.5/site-packages/django/db/backends/utils.py:89] (0.000) SET SQL_AUTO_IS_NULL = 0; args=None
[13/Mar/2018 16:21:53] DEBUG [/media/thqbop/data/Hoctap/NNLaptrinh/Python/Projects/RiBo-Core/env/lib/python3.5/site-packages/django/db/backends/utils.py:89] (0.000) SET SQL_AUTO_IS_NULL = 0; args=None
[13/Mar/2018 16:22:03] DEBUG [/media/thqbop/data/Hoctap/NNLaptrinh/Python/Projects/RiBo-Core/env/lib/python3.5/site-packages/django/db/backends/utils.py:89] (0.000) SET SQL_AUTO_IS_NULL = 0; args=None
[13/Mar/2018 16:22:31] DEBUG [/media/thqbop/data/Hoctap/NNLaptrinh/Python/Projects/RiBo-Core/env/lib/python3.5/site-packages/django/db/backends/utils.py:89] (0.000) SET SQL_AUTO_IS_NULL = 0; args=None
[13/Mar/2018 16:22:38] DEBUG [/media/thqbop/data/Hoctap/NNLaptrinh/Python/Projects/RiBo-Core/env/lib/python3.5/site-packages/django/db/backends/utils.py:89] (0.000) SET SQL_AUTO_IS_NULL = 0; args=None
[13/Mar/2018 16:22:57] DEBUG [/media/thqbop/data/Hoctap/NNLaptrinh/Python/Projects/RiBo-Core/env/lib/python3.5/site-packages/django/db/backends/utils.py:89] (0.000) SET SQL_AUTO_IS_NULL = 0; args=None
[13/Mar/2018 16:23:20] DEBUG [/media/thqbop/data/Hoctap/NNLaptrinh/Python/Projects/RiBo-Core/env/lib/python3.5/site-packages/django/db/backends/utils.py:89] (0.000) SET SQL_AUTO_IS_NULL = 0; args=None
[13/Mar/2018 16:26:09] DEBUG [/media/thqbop/data/Hoctap/NNLaptrinh/Python/Projects/RiBo-Core/env/lib/python3.5/site-packages/django/db/backends/utils.py:89] (0.000) SET SQL_AUTO_IS_NULL = 0; args=None
[13/Mar/2018 16:26:11] DEBUG [/media/thqbop/data/Hoctap/NNLaptrinh/Python/Projects/RiBo-Core/env/lib/python3.5/site-packages/django/db/backends/utils.py:89] (0.000) SET SQL_AUTO_IS_NULL = 0; args=None
[13/Mar/2018 16:26:11] DEBUG [/media/thqbop/data/Hoctap/NNLaptrinh/Python/Projects/RiBo-Core/env/lib/python3.5/site-packages/django/db/backends/utils.py:89] (0.011) SHOW FULL TABLES; args=None
[13/Mar/2018 16:26:11] DEBUG [/media/thqbop/data/Hoctap/NNLaptrinh/Python/Projects/RiBo-Core/env/lib/python3.5/site-packages/django/db/backends/utils.py:89] (0.012) SELECT `django_migrations`.`app`, `django_migrations`.`name` FROM `django_migrations`; args=()
[13/Mar/2018 16:30:16] DEBUG [/media/thqbop/data/Hoctap/NNLaptrinh/Python/Projects/RiBo-Core/env/lib/python3.5/site-packages/django/db/backends/utils.py:89] (0.000) SET SQL_AUTO_IS_NULL = 0; args=None
[13/Mar/2018 16:30:19] DEBUG [/media/thqbop/data/Hoctap/NNLaptrinh/Python/Projects/RiBo-Core/env/lib/python3.5/site-packages/django/db/backends/utils.py:89] (0.000) SET SQL_AUTO_IS_NULL = 0; args=None
[13/Mar/2018 16:30:19] DEBUG [/media/thqbop/data/Hoctap/NNLaptrinh/Python/Projects/RiBo-Core/env/lib/python3.5/site-packages/django/db/backends/utils.py:89] (0.038) SHOW FULL TABLES; args=None
[13/Mar/2018 16:30:19] DEBUG [/media/thqbop/data/Hoctap/NNLaptrinh/Python/Projects/RiBo-Core/env/lib/python3.5/site-packages/django/db/backends/utils.py:89] (0.039) SELECT `django_migrations`.`app`, `django_migrations`.`name` FROM `django_migrations`; args=()
[13/Mar/2018 16:35:14] DEBUG [/media/thqbop/data/Hoctap/NNLaptrinh/Python/Projects/RiBo-Core/env/lib/python3.5/site-packages/django/db/backends/utils.py:89] (0.000) SET SQL_AUTO_IS_NULL = 0; args=None
[13/Mar/2018 16:35:16] DEBUG [/media/thqbop/data/Hoctap/NNLaptrinh/Python/Projects/RiBo-Core/env/lib/python3.5/site-packages/django/db/backends/utils.py:89] (0.000) SET SQL_AUTO_IS_NULL = 0; args=None
[13/Mar/2018 16:35:16] DEBUG [/media/thqbop/data/Hoctap/NNLaptrinh/Python/Projects/RiBo-Core/env/lib/python3.5/site-packages/django/db/backends/utils.py:89] (0.005) SHOW FULL TABLES; args=None
[13/Mar/2018 16:35:16] DEBUG [/media/thqbop/data/Hoctap/NNLaptrinh/Python/Projects/RiBo-Core/env/lib/python3.5/site-packages/django/db/backends/utils.py:89] (0.007) SELECT `django_migrations`.`app`, `django_migrations`.`name` FROM `django_migrations`; args=()
[13/Mar/2018 16:35:21] ERROR [/media/thqbop/data/Hoctap/NNLaptrinh/Python/Projects/RiBo-Core/env/lib/python3.5/site-packages/django/core/handlers/base.py:284] Internal Server Error: /api/v1/user
Traceback (most recent call last):
  File "/media/thqbop/data/Hoctap/NNLaptrinh/Python/Projects/RiBo-Core/env/lib/python3.5/site-packages/rest_framework_mongoengine/serializers.py", line 151, in create
    instance = self.recursive_save(validated_data)
  File "/media/thqbop/data/Hoctap/NNLaptrinh/Python/Projects/RiBo-Core/env/lib/python3.5/site-packages/rest_framework_mongoengine/serializers.py", line 262, in recursive_save
    instance.save()
  File "/media/thqbop/data/Hoctap/NNLaptrinh/Python/Projects/RiBo-Core/env/lib/python3.5/site-packages/mongoengine/document.py", line 355, in save
    self.validate(clean=clean)
  File "/media/thqbop/data/Hoctap/NNLaptrinh/Python/Projects/RiBo-Core/env/lib/python3.5/site-packages/mongoengine/base/document.py", line 395, in validate
    raise ValidationError(message, errors=errors)
mongoengine.errors.ValidationError: ValidationError (User:None) (Field is required: ['email'])

During handling of the above exception, another exception occurred:

Traceback (most recent call last):
  File "/media/thqbop/data/Hoctap/NNLaptrinh/Python/Projects/RiBo-Core/env/lib/python3.5/site-packages/django/core/handlers/base.py", line 149, in get_response
    response = self.process_exception_by_middleware(e, request)
  File "/media/thqbop/data/Hoctap/NNLaptrinh/Python/Projects/RiBo-Core/env/lib/python3.5/site-packages/django/core/handlers/base.py", line 147, in get_response
    response = wrapped_callback(request, *callback_args, **callback_kwargs)
  File "/media/thqbop/data/Hoctap/NNLaptrinh/Python/Projects/RiBo-Core/env/lib/python3.5/site-packages/django/views/decorators/csrf.py", line 58, in wrapped_view
    return view_func(*args, **kwargs)
  File "/media/thqbop/data/Hoctap/NNLaptrinh/Python/Projects/RiBo-Core/env/lib/python3.5/site-packages/rest_framework/viewsets.py", line 87, in view
    return self.dispatch(request, *args, **kwargs)
  File "/media/thqbop/data/Hoctap/NNLaptrinh/Python/Projects/RiBo-Core/env/lib/python3.5/site-packages/rest_framework/views.py", line 466, in dispatch
    response = self.handle_exception(exc)
  File "/media/thqbop/data/Hoctap/NNLaptrinh/Python/Projects/RiBo-Core/env/lib/python3.5/site-packages/rest_framework/views.py", line 463, in dispatch
    response = handler(request, *args, **kwargs)
  File "/media/thqbop/data/Hoctap/NNLaptrinh/Python/Projects/RiBo-Core/src/ribo_api/views/user.py", line 67, in create
    raise e
  File "/media/thqbop/data/Hoctap/NNLaptrinh/Python/Projects/RiBo-Core/src/ribo_api/views/user.py", line 63, in create
    serializer.save()
  File "/media/thqbop/data/Hoctap/NNLaptrinh/Python/Projects/RiBo-Core/env/lib/python3.5/site-packages/rest_framework/serializers.py", line 191, in save
    self.instance = self.create(validated_data)
  File "/media/thqbop/data/Hoctap/NNLaptrinh/Python/Projects/RiBo-Core/env/lib/python3.5/site-packages/rest_framework_mongoengine/serializers.py", line 183, in create
    raise me_ValidationError(msg)
mongoengine.errors.ValidationError: Got a `ValidationError` when calling `User.objects.create()`. This may be because request data satisfies serializer validations but not Mongoengine`s. You may need to check consistency between User and UserSerializer.
If that is not the case, please open a ticket regarding this issue on https://github.com/umutbozkurt/django-rest-framework-mongoengine/issues
Original exception was: ValidationError (User:None) (Field is required: ['email'])
[13/Mar/2018 16:35:54] ERROR [/media/thqbop/data/Hoctap/NNLaptrinh/Python/Projects/RiBo-Core/env/lib/python3.5/site-packages/django/core/handlers/base.py:284] Internal Server Error: /api/v1/user
Traceback (most recent call last):
  File "/media/thqbop/data/Hoctap/NNLaptrinh/Python/Projects/RiBo-Core/env/lib/python3.5/site-packages/rest_framework_mongoengine/serializers.py", line 151, in create
    instance = self.recursive_save(validated_data)
  File "/media/thqbop/data/Hoctap/NNLaptrinh/Python/Projects/RiBo-Core/env/lib/python3.5/site-packages/rest_framework_mongoengine/serializers.py", line 262, in recursive_save
    instance.save()
  File "/media/thqbop/data/Hoctap/NNLaptrinh/Python/Projects/RiBo-Core/env/lib/python3.5/site-packages/mongoengine/document.py", line 355, in save
    self.validate(clean=clean)
  File "/media/thqbop/data/Hoctap/NNLaptrinh/Python/Projects/RiBo-Core/env/lib/python3.5/site-packages/mongoengine/base/document.py", line 395, in validate
    raise ValidationError(message, errors=errors)
mongoengine.errors.ValidationError: ValidationError (User:None) (Field is required: ['email'])

During handling of the above exception, another exception occurred:

Traceback (most recent call last):
  File "/media/thqbop/data/Hoctap/NNLaptrinh/Python/Projects/RiBo-Core/env/lib/python3.5/site-packages/django/core/handlers/base.py", line 149, in get_response
    response = self.process_exception_by_middleware(e, request)
  File "/media/thqbop/data/Hoctap/NNLaptrinh/Python/Projects/RiBo-Core/env/lib/python3.5/site-packages/django/core/handlers/base.py", line 147, in get_response
    response = wrapped_callback(request, *callback_args, **callback_kwargs)
  File "/media/thqbop/data/Hoctap/NNLaptrinh/Python/Projects/RiBo-Core/env/lib/python3.5/site-packages/django/views/decorators/csrf.py", line 58, in wrapped_view
    return view_func(*args, **kwargs)
  File "/media/thqbop/data/Hoctap/NNLaptrinh/Python/Projects/RiBo-Core/env/lib/python3.5/site-packages/rest_framework/viewsets.py", line 87, in view
    return self.dispatch(request, *args, **kwargs)
  File "/media/thqbop/data/Hoctap/NNLaptrinh/Python/Projects/RiBo-Core/env/lib/python3.5/site-packages/rest_framework/views.py", line 466, in dispatch
    response = self.handle_exception(exc)
  File "/media/thqbop/data/Hoctap/NNLaptrinh/Python/Projects/RiBo-Core/env/lib/python3.5/site-packages/rest_framework/views.py", line 463, in dispatch
    response = handler(request, *args, **kwargs)
  File "/media/thqbop/data/Hoctap/NNLaptrinh/Python/Projects/RiBo-Core/src/ribo_api/views/user.py", line 67, in create
    raise e
  File "/media/thqbop/data/Hoctap/NNLaptrinh/Python/Projects/RiBo-Core/src/ribo_api/views/user.py", line 63, in create
    serializer.save()
  File "/media/thqbop/data/Hoctap/NNLaptrinh/Python/Projects/RiBo-Core/env/lib/python3.5/site-packages/rest_framework/serializers.py", line 191, in save
    self.instance = self.create(validated_data)
  File "/media/thqbop/data/Hoctap/NNLaptrinh/Python/Projects/RiBo-Core/env/lib/python3.5/site-packages/rest_framework_mongoengine/serializers.py", line 183, in create
    raise me_ValidationError(msg)
mongoengine.errors.ValidationError: Got a `ValidationError` when calling `User.objects.create()`. This may be because request data satisfies serializer validations but not Mongoengine`s. You may need to check consistency between User and UserSerializer.
If that is not the case, please open a ticket regarding this issue on https://github.com/umutbozkurt/django-rest-framework-mongoengine/issues
Original exception was: ValidationError (User:None) (Field is required: ['email'])
[13/Mar/2018 16:37:01] ERROR [/media/thqbop/data/Hoctap/NNLaptrinh/Python/Projects/RiBo-Core/env/lib/python3.5/site-packages/django/core/handlers/base.py:284] Internal Server Error: /api/v1/user
Traceback (most recent call last):
  File "/media/thqbop/data/Hoctap/NNLaptrinh/Python/Projects/RiBo-Core/env/lib/python3.5/site-packages/rest_framework_mongoengine/serializers.py", line 151, in create
    instance = self.recursive_save(validated_data)
  File "/media/thqbop/data/Hoctap/NNLaptrinh/Python/Projects/RiBo-Core/env/lib/python3.5/site-packages/rest_framework_mongoengine/serializers.py", line 262, in recursive_save
    instance.save()
  File "/media/thqbop/data/Hoctap/NNLaptrinh/Python/Projects/RiBo-Core/env/lib/python3.5/site-packages/mongoengine/document.py", line 355, in save
    self.validate(clean=clean)
  File "/media/thqbop/data/Hoctap/NNLaptrinh/Python/Projects/RiBo-Core/env/lib/python3.5/site-packages/mongoengine/base/document.py", line 395, in validate
    raise ValidationError(message, errors=errors)
mongoengine.errors.ValidationError: ValidationError (User:None) (Field is required: ['email'])

During handling of the above exception, another exception occurred:

Traceback (most recent call last):
  File "/media/thqbop/data/Hoctap/NNLaptrinh/Python/Projects/RiBo-Core/env/lib/python3.5/site-packages/django/core/handlers/base.py", line 149, in get_response
    response = self.process_exception_by_middleware(e, request)
  File "/media/thqbop/data/Hoctap/NNLaptrinh/Python/Projects/RiBo-Core/env/lib/python3.5/site-packages/django/core/handlers/base.py", line 147, in get_response
    response = wrapped_callback(request, *callback_args, **callback_kwargs)
  File "/media/thqbop/data/Hoctap/NNLaptrinh/Python/Projects/RiBo-Core/env/lib/python3.5/site-packages/django/views/decorators/csrf.py", line 58, in wrapped_view
    return view_func(*args, **kwargs)
  File "/media/thqbop/data/Hoctap/NNLaptrinh/Python/Projects/RiBo-Core/env/lib/python3.5/site-packages/rest_framework/viewsets.py", line 87, in view
    return self.dispatch(request, *args, **kwargs)
  File "/media/thqbop/data/Hoctap/NNLaptrinh/Python/Projects/RiBo-Core/env/lib/python3.5/site-packages/rest_framework/views.py", line 466, in dispatch
    response = self.handle_exception(exc)
  File "/media/thqbop/data/Hoctap/NNLaptrinh/Python/Projects/RiBo-Core/env/lib/python3.5/site-packages/rest_framework/views.py", line 463, in dispatch
    response = handler(request, *args, **kwargs)
  File "/media/thqbop/data/Hoctap/NNLaptrinh/Python/Projects/RiBo-Core/src/ribo_api/views/user.py", line 67, in create
    raise e
  File "/media/thqbop/data/Hoctap/NNLaptrinh/Python/Projects/RiBo-Core/src/ribo_api/views/user.py", line 63, in create
    serializer.save()
  File "/media/thqbop/data/Hoctap/NNLaptrinh/Python/Projects/RiBo-Core/env/lib/python3.5/site-packages/rest_framework/serializers.py", line 191, in save
    self.instance = self.create(validated_data)
  File "/media/thqbop/data/Hoctap/NNLaptrinh/Python/Projects/RiBo-Core/env/lib/python3.5/site-packages/rest_framework_mongoengine/serializers.py", line 183, in create
    raise me_ValidationError(msg)
mongoengine.errors.ValidationError: Got a `ValidationError` when calling `User.objects.create()`. This may be because request data satisfies serializer validations but not Mongoengine`s. You may need to check consistency between User and UserSerializer.
If that is not the case, please open a ticket regarding this issue on https://github.com/umutbozkurt/django-rest-framework-mongoengine/issues
Original exception was: ValidationError (User:None) (Field is required: ['email'])
[13/Mar/2018 16:37:20] DEBUG [/media/thqbop/data/Hoctap/NNLaptrinh/Python/Projects/RiBo-Core/env/lib/python3.5/site-packages/django/db/backends/utils.py:89] (0.000) SET SQL_AUTO_IS_NULL = 0; args=None
[13/Mar/2018 16:37:22] DEBUG [/media/thqbop/data/Hoctap/NNLaptrinh/Python/Projects/RiBo-Core/env/lib/python3.5/site-packages/django/db/backends/utils.py:89] (0.000) SET SQL_AUTO_IS_NULL = 0; args=None
[13/Mar/2018 16:37:22] DEBUG [/media/thqbop/data/Hoctap/NNLaptrinh/Python/Projects/RiBo-Core/env/lib/python3.5/site-packages/django/db/backends/utils.py:89] (0.005) SHOW FULL TABLES; args=None
[13/Mar/2018 16:37:22] DEBUG [/media/thqbop/data/Hoctap/NNLaptrinh/Python/Projects/RiBo-Core/env/lib/python3.5/site-packages/django/db/backends/utils.py:89] (0.002) SELECT `django_migrations`.`app`, `django_migrations`.`name` FROM `django_migrations`; args=()
[13/Mar/2018 16:38:07] ERROR [/media/thqbop/data/Hoctap/NNLaptrinh/Python/Projects/RiBo-Core/env/lib/python3.5/site-packages/django/core/handlers/base.py:284] Internal Server Error: /api/v1/user
Traceback (most recent call last):
  File "/media/thqbop/data/Hoctap/NNLaptrinh/Python/Projects/RiBo-Core/env/lib/python3.5/site-packages/rest_framework_mongoengine/serializers.py", line 151, in create
    instance = self.recursive_save(validated_data)
  File "/media/thqbop/data/Hoctap/NNLaptrinh/Python/Projects/RiBo-Core/env/lib/python3.5/site-packages/rest_framework_mongoengine/serializers.py", line 262, in recursive_save
    instance.save()
  File "/media/thqbop/data/Hoctap/NNLaptrinh/Python/Projects/RiBo-Core/env/lib/python3.5/site-packages/mongoengine/document.py", line 355, in save
    self.validate(clean=clean)
  File "/media/thqbop/data/Hoctap/NNLaptrinh/Python/Projects/RiBo-Core/env/lib/python3.5/site-packages/mongoengine/base/document.py", line 395, in validate
    raise ValidationError(message, errors=errors)
mongoengine.errors.ValidationError: ValidationError (User:None) (Field is required: ['email'])

During handling of the above exception, another exception occurred:

Traceback (most recent call last):
  File "/media/thqbop/data/Hoctap/NNLaptrinh/Python/Projects/RiBo-Core/env/lib/python3.5/site-packages/django/core/handlers/base.py", line 149, in get_response
    response = self.process_exception_by_middleware(e, request)
  File "/media/thqbop/data/Hoctap/NNLaptrinh/Python/Projects/RiBo-Core/env/lib/python3.5/site-packages/django/core/handlers/base.py", line 147, in get_response
    response = wrapped_callback(request, *callback_args, **callback_kwargs)
  File "/media/thqbop/data/Hoctap/NNLaptrinh/Python/Projects/RiBo-Core/env/lib/python3.5/site-packages/django/views/decorators/csrf.py", line 58, in wrapped_view
    return view_func(*args, **kwargs)
  File "/media/thqbop/data/Hoctap/NNLaptrinh/Python/Projects/RiBo-Core/env/lib/python3.5/site-packages/rest_framework/viewsets.py", line 87, in view
    return self.dispatch(request, *args, **kwargs)
  File "/media/thqbop/data/Hoctap/NNLaptrinh/Python/Projects/RiBo-Core/env/lib/python3.5/site-packages/rest_framework/views.py", line 466, in dispatch
    response = self.handle_exception(exc)
  File "/media/thqbop/data/Hoctap/NNLaptrinh/Python/Projects/RiBo-Core/env/lib/python3.5/site-packages/rest_framework/views.py", line 463, in dispatch
    response = handler(request, *args, **kwargs)
  File "/media/thqbop/data/Hoctap/NNLaptrinh/Python/Projects/RiBo-Core/src/ribo_api/views/user.py", line 67, in create
    raise e
  File "/media/thqbop/data/Hoctap/NNLaptrinh/Python/Projects/RiBo-Core/src/ribo_api/views/user.py", line 63, in create
    serializer.save()
  File "/media/thqbop/data/Hoctap/NNLaptrinh/Python/Projects/RiBo-Core/env/lib/python3.5/site-packages/rest_framework/serializers.py", line 191, in save
    self.instance = self.create(validated_data)
  File "/media/thqbop/data/Hoctap/NNLaptrinh/Python/Projects/RiBo-Core/env/lib/python3.5/site-packages/rest_framework_mongoengine/serializers.py", line 183, in create
    raise me_ValidationError(msg)
mongoengine.errors.ValidationError: Got a `ValidationError` when calling `User.objects.create()`. This may be because request data satisfies serializer validations but not Mongoengine`s. You may need to check consistency between User and UserSerializer.
If that is not the case, please open a ticket regarding this issue on https://github.com/umutbozkurt/django-rest-framework-mongoengine/issues
Original exception was: ValidationError (User:None) (Field is required: ['email'])
[13/Mar/2018 16:38:24] DEBUG [/media/thqbop/data/Hoctap/NNLaptrinh/Python/Projects/RiBo-Core/env/lib/python3.5/site-packages/django/db/backends/utils.py:89] (0.000) SET SQL_AUTO_IS_NULL = 0; args=None
[13/Mar/2018 16:38:25] DEBUG [/media/thqbop/data/Hoctap/NNLaptrinh/Python/Projects/RiBo-Core/env/lib/python3.5/site-packages/django/db/backends/utils.py:89] (0.000) SET SQL_AUTO_IS_NULL = 0; args=None
[13/Mar/2018 16:38:25] DEBUG [/media/thqbop/data/Hoctap/NNLaptrinh/Python/Projects/RiBo-Core/env/lib/python3.5/site-packages/django/db/backends/utils.py:89] (0.001) SHOW FULL TABLES; args=None
[13/Mar/2018 16:38:25] DEBUG [/media/thqbop/data/Hoctap/NNLaptrinh/Python/Projects/RiBo-Core/env/lib/python3.5/site-packages/django/db/backends/utils.py:89] (0.003) SELECT `django_migrations`.`app`, `django_migrations`.`name` FROM `django_migrations`; args=()
[13/Mar/2018 16:38:29] DEBUG [/media/thqbop/data/Hoctap/NNLaptrinh/Python/Projects/RiBo-Core/env/lib/python3.5/site-packages/django/db/backends/utils.py:89] (0.000) SET SQL_AUTO_IS_NULL = 0; args=None
[13/Mar/2018 16:38:29] DEBUG [/media/thqbop/data/Hoctap/NNLaptrinh/Python/Projects/RiBo-Core/env/lib/python3.5/site-packages/django/db/backends/utils.py:89] (0.000) SET SQL_AUTO_IS_NULL = 0; args=None
[13/Mar/2018 16:38:29] DEBUG [/media/thqbop/data/Hoctap/NNLaptrinh/Python/Projects/RiBo-Core/env/lib/python3.5/site-packages/django/db/backends/utils.py:89] (0.001) SHOW FULL TABLES; args=None
[13/Mar/2018 16:38:29] DEBUG [/media/thqbop/data/Hoctap/NNLaptrinh/Python/Projects/RiBo-Core/env/lib/python3.5/site-packages/django/db/backends/utils.py:89] (0.002) SELECT `django_migrations`.`app`, `django_migrations`.`name` FROM `django_migrations`; args=()
[13/Mar/2018 16:38:51] ERROR [/media/thqbop/data/Hoctap/NNLaptrinh/Python/Projects/RiBo-Core/env/lib/python3.5/site-packages/django/core/handlers/base.py:284] Internal Server Error: /api/v1/user
Traceback (most recent call last):
  File "/media/thqbop/data/Hoctap/NNLaptrinh/Python/Projects/RiBo-Core/env/lib/python3.5/site-packages/rest_framework_mongoengine/serializers.py", line 151, in create
    instance = self.recursive_save(validated_data)
  File "/media/thqbop/data/Hoctap/NNLaptrinh/Python/Projects/RiBo-Core/env/lib/python3.5/site-packages/rest_framework_mongoengine/serializers.py", line 262, in recursive_save
    instance.save()
  File "/media/thqbop/data/Hoctap/NNLaptrinh/Python/Projects/RiBo-Core/env/lib/python3.5/site-packages/mongoengine/document.py", line 355, in save
    self.validate(clean=clean)
  File "/media/thqbop/data/Hoctap/NNLaptrinh/Python/Projects/RiBo-Core/env/lib/python3.5/site-packages/mongoengine/base/document.py", line 395, in validate
    raise ValidationError(message, errors=errors)
mongoengine.errors.ValidationError: ValidationError (User:None) (Field is required: ['email_address'])

During handling of the above exception, another exception occurred:

Traceback (most recent call last):
  File "/media/thqbop/data/Hoctap/NNLaptrinh/Python/Projects/RiBo-Core/env/lib/python3.5/site-packages/django/core/handlers/base.py", line 149, in get_response
    response = self.process_exception_by_middleware(e, request)
  File "/media/thqbop/data/Hoctap/NNLaptrinh/Python/Projects/RiBo-Core/env/lib/python3.5/site-packages/django/core/handlers/base.py", line 147, in get_response
    response = wrapped_callback(request, *callback_args, **callback_kwargs)
  File "/media/thqbop/data/Hoctap/NNLaptrinh/Python/Projects/RiBo-Core/env/lib/python3.5/site-packages/django/views/decorators/csrf.py", line 58, in wrapped_view
    return view_func(*args, **kwargs)
  File "/media/thqbop/data/Hoctap/NNLaptrinh/Python/Projects/RiBo-Core/env/lib/python3.5/site-packages/rest_framework/viewsets.py", line 87, in view
    return self.dispatch(request, *args, **kwargs)
  File "/media/thqbop/data/Hoctap/NNLaptrinh/Python/Projects/RiBo-Core/env/lib/python3.5/site-packages/rest_framework/views.py", line 466, in dispatch
    response = self.handle_exception(exc)
  File "/media/thqbop/data/Hoctap/NNLaptrinh/Python/Projects/RiBo-Core/env/lib/python3.5/site-packages/rest_framework/views.py", line 463, in dispatch
    response = handler(request, *args, **kwargs)
  File "/media/thqbop/data/Hoctap/NNLaptrinh/Python/Projects/RiBo-Core/src/ribo_api/views/user.py", line 67, in create
    raise e
  File "/media/thqbop/data/Hoctap/NNLaptrinh/Python/Projects/RiBo-Core/src/ribo_api/views/user.py", line 63, in create
    serializer.save()
  File "/media/thqbop/data/Hoctap/NNLaptrinh/Python/Projects/RiBo-Core/env/lib/python3.5/site-packages/rest_framework/serializers.py", line 191, in save
    self.instance = self.create(validated_data)
  File "/media/thqbop/data/Hoctap/NNLaptrinh/Python/Projects/RiBo-Core/env/lib/python3.5/site-packages/rest_framework_mongoengine/serializers.py", line 183, in create
    raise me_ValidationError(msg)
mongoengine.errors.ValidationError: Got a `ValidationError` when calling `User.objects.create()`. This may be because request data satisfies serializer validations but not Mongoengine`s. You may need to check consistency between User and UserSerializer.
If that is not the case, please open a ticket regarding this issue on https://github.com/umutbozkurt/django-rest-framework-mongoengine/issues
Original exception was: ValidationError (User:None) (Field is required: ['email_address'])
[13/Mar/2018 16:40:06] ERROR [/media/thqbop/data/Hoctap/NNLaptrinh/Python/Projects/RiBo-Core/env/lib/python3.5/site-packages/django/core/handlers/base.py:284] Internal Server Error: /api/v1/user
Traceback (most recent call last):
  File "/media/thqbop/data/Hoctap/NNLaptrinh/Python/Projects/RiBo-Core/env/lib/python3.5/site-packages/rest_framework_mongoengine/serializers.py", line 151, in create
    instance = self.recursive_save(validated_data)
  File "/media/thqbop/data/Hoctap/NNLaptrinh/Python/Projects/RiBo-Core/env/lib/python3.5/site-packages/rest_framework_mongoengine/serializers.py", line 262, in recursive_save
    instance.save()
  File "/media/thqbop/data/Hoctap/NNLaptrinh/Python/Projects/RiBo-Core/env/lib/python3.5/site-packages/mongoengine/document.py", line 355, in save
    self.validate(clean=clean)
  File "/media/thqbop/data/Hoctap/NNLaptrinh/Python/Projects/RiBo-Core/env/lib/python3.5/site-packages/mongoengine/base/document.py", line 395, in validate
    raise ValidationError(message, errors=errors)
mongoengine.errors.ValidationError: ValidationError (User:None) (Field is required: ['email_address'])

During handling of the above exception, another exception occurred:

Traceback (most recent call last):
  File "/media/thqbop/data/Hoctap/NNLaptrinh/Python/Projects/RiBo-Core/env/lib/python3.5/site-packages/django/core/handlers/base.py", line 149, in get_response
    response = self.process_exception_by_middleware(e, request)
  File "/media/thqbop/data/Hoctap/NNLaptrinh/Python/Projects/RiBo-Core/env/lib/python3.5/site-packages/django/core/handlers/base.py", line 147, in get_response
    response = wrapped_callback(request, *callback_args, **callback_kwargs)
  File "/media/thqbop/data/Hoctap/NNLaptrinh/Python/Projects/RiBo-Core/env/lib/python3.5/site-packages/django/views/decorators/csrf.py", line 58, in wrapped_view
    return view_func(*args, **kwargs)
  File "/media/thqbop/data/Hoctap/NNLaptrinh/Python/Projects/RiBo-Core/env/lib/python3.5/site-packages/rest_framework/viewsets.py", line 87, in view
    return self.dispatch(request, *args, **kwargs)
  File "/media/thqbop/data/Hoctap/NNLaptrinh/Python/Projects/RiBo-Core/env/lib/python3.5/site-packages/rest_framework/views.py", line 466, in dispatch
    response = self.handle_exception(exc)
  File "/media/thqbop/data/Hoctap/NNLaptrinh/Python/Projects/RiBo-Core/env/lib/python3.5/site-packages/rest_framework/views.py", line 463, in dispatch
    response = handler(request, *args, **kwargs)
  File "/media/thqbop/data/Hoctap/NNLaptrinh/Python/Projects/RiBo-Core/src/ribo_api/views/user.py", line 67, in create
    raise e
  File "/media/thqbop/data/Hoctap/NNLaptrinh/Python/Projects/RiBo-Core/src/ribo_api/views/user.py", line 63, in create
    serializer.save()
  File "/media/thqbop/data/Hoctap/NNLaptrinh/Python/Projects/RiBo-Core/env/lib/python3.5/site-packages/rest_framework/serializers.py", line 191, in save
    self.instance = self.create(validated_data)
  File "/media/thqbop/data/Hoctap/NNLaptrinh/Python/Projects/RiBo-Core/env/lib/python3.5/site-packages/rest_framework_mongoengine/serializers.py", line 183, in create
    raise me_ValidationError(msg)
mongoengine.errors.ValidationError: Got a `ValidationError` when calling `User.objects.create()`. This may be because request data satisfies serializer validations but not Mongoengine`s. You may need to check consistency between User and UserSerializer.
If that is not the case, please open a ticket regarding this issue on https://github.com/umutbozkurt/django-rest-framework-mongoengine/issues
Original exception was: ValidationError (User:None) (Field is required: ['email_address'])
[13/Mar/2018 16:40:13] DEBUG [/media/thqbop/data/Hoctap/NNLaptrinh/Python/Projects/RiBo-Core/env/lib/python3.5/site-packages/django/db/backends/utils.py:89] (0.000) SET SQL_AUTO_IS_NULL = 0; args=None
[13/Mar/2018 16:40:14] DEBUG [/media/thqbop/data/Hoctap/NNLaptrinh/Python/Projects/RiBo-Core/env/lib/python3.5/site-packages/django/db/backends/utils.py:89] (0.001) SET SQL_AUTO_IS_NULL = 0; args=None
[13/Mar/2018 16:40:14] DEBUG [/media/thqbop/data/Hoctap/NNLaptrinh/Python/Projects/RiBo-Core/env/lib/python3.5/site-packages/django/db/backends/utils.py:89] (0.001) SHOW FULL TABLES; args=None
[13/Mar/2018 16:40:14] DEBUG [/media/thqbop/data/Hoctap/NNLaptrinh/Python/Projects/RiBo-Core/env/lib/python3.5/site-packages/django/db/backends/utils.py:89] (0.001) SELECT `django_migrations`.`app`, `django_migrations`.`name` FROM `django_migrations`; args=()
[13/Mar/2018 16:40:40] ERROR [/media/thqbop/data/Hoctap/NNLaptrinh/Python/Projects/RiBo-Core/env/lib/python3.5/site-packages/django/core/handlers/base.py:284] Internal Server Error: /api/v1/user
Traceback (most recent call last):
  File "/media/thqbop/data/Hoctap/NNLaptrinh/Python/Projects/RiBo-Core/env/lib/python3.5/site-packages/rest_framework_mongoengine/serializers.py", line 151, in create
    instance = self.recursive_save(validated_data)
  File "/media/thqbop/data/Hoctap/NNLaptrinh/Python/Projects/RiBo-Core/env/lib/python3.5/site-packages/rest_framework_mongoengine/serializers.py", line 262, in recursive_save
    instance.save()
  File "/media/thqbop/data/Hoctap/NNLaptrinh/Python/Projects/RiBo-Core/env/lib/python3.5/site-packages/mongoengine/document.py", line 355, in save
    self.validate(clean=clean)
  File "/media/thqbop/data/Hoctap/NNLaptrinh/Python/Projects/RiBo-Core/env/lib/python3.5/site-packages/mongoengine/base/document.py", line 395, in validate
    raise ValidationError(message, errors=errors)
mongoengine.errors.ValidationError: ValidationError (User:None) (Field is required: ['email_address'])

During handling of the above exception, another exception occurred:

Traceback (most recent call last):
  File "/media/thqbop/data/Hoctap/NNLaptrinh/Python/Projects/RiBo-Core/env/lib/python3.5/site-packages/django/core/handlers/base.py", line 149, in get_response
    response = self.process_exception_by_middleware(e, request)
  File "/media/thqbop/data/Hoctap/NNLaptrinh/Python/Projects/RiBo-Core/env/lib/python3.5/site-packages/django/core/handlers/base.py", line 147, in get_response
    response = wrapped_callback(request, *callback_args, **callback_kwargs)
  File "/media/thqbop/data/Hoctap/NNLaptrinh/Python/Projects/RiBo-Core/env/lib/python3.5/site-packages/django/views/decorators/csrf.py", line 58, in wrapped_view
    return view_func(*args, **kwargs)
  File "/media/thqbop/data/Hoctap/NNLaptrinh/Python/Projects/RiBo-Core/env/lib/python3.5/site-packages/rest_framework/viewsets.py", line 87, in view
    return self.dispatch(request, *args, **kwargs)
  File "/media/thqbop/data/Hoctap/NNLaptrinh/Python/Projects/RiBo-Core/env/lib/python3.5/site-packages/rest_framework/views.py", line 466, in dispatch
    response = self.handle_exception(exc)
  File "/media/thqbop/data/Hoctap/NNLaptrinh/Python/Projects/RiBo-Core/env/lib/python3.5/site-packages/rest_framework/views.py", line 463, in dispatch
    response = handler(request, *args, **kwargs)
  File "/media/thqbop/data/Hoctap/NNLaptrinh/Python/Projects/RiBo-Core/src/ribo_api/views/user.py", line 67, in create
    raise e
  File "/media/thqbop/data/Hoctap/NNLaptrinh/Python/Projects/RiBo-Core/src/ribo_api/views/user.py", line 63, in create
    serializer.save()
  File "/media/thqbop/data/Hoctap/NNLaptrinh/Python/Projects/RiBo-Core/env/lib/python3.5/site-packages/rest_framework/serializers.py", line 191, in save
    self.instance = self.create(validated_data)
  File "/media/thqbop/data/Hoctap/NNLaptrinh/Python/Projects/RiBo-Core/env/lib/python3.5/site-packages/rest_framework_mongoengine/serializers.py", line 183, in create
    raise me_ValidationError(msg)
mongoengine.errors.ValidationError: Got a `ValidationError` when calling `User.objects.create()`. This may be because request data satisfies serializer validations but not Mongoengine`s. You may need to check consistency between User and UserSerializer.
If that is not the case, please open a ticket regarding this issue on https://github.com/umutbozkurt/django-rest-framework-mongoengine/issues
Original exception was: ValidationError (User:None) (Field is required: ['email_address'])
[13/Mar/2018 16:40:53] DEBUG [/media/thqbop/data/Hoctap/NNLaptrinh/Python/Projects/RiBo-Core/env/lib/python3.5/site-packages/django/db/backends/utils.py:89] (0.000) SET SQL_AUTO_IS_NULL = 0; args=None
[13/Mar/2018 16:40:54] DEBUG [/media/thqbop/data/Hoctap/NNLaptrinh/Python/Projects/RiBo-Core/env/lib/python3.5/site-packages/django/db/backends/utils.py:89] (0.000) SET SQL_AUTO_IS_NULL = 0; args=None
[13/Mar/2018 16:40:54] DEBUG [/media/thqbop/data/Hoctap/NNLaptrinh/Python/Projects/RiBo-Core/env/lib/python3.5/site-packages/django/db/backends/utils.py:89] (0.001) SHOW FULL TABLES; args=None
[13/Mar/2018 16:40:54] DEBUG [/media/thqbop/data/Hoctap/NNLaptrinh/Python/Projects/RiBo-Core/env/lib/python3.5/site-packages/django/db/backends/utils.py:89] (0.001) SELECT `django_migrations`.`app`, `django_migrations`.`name` FROM `django_migrations`; args=()
[13/Mar/2018 16:41:04] ERROR [/media/thqbop/data/Hoctap/NNLaptrinh/Python/Projects/RiBo-Core/env/lib/python3.5/site-packages/django/core/handlers/base.py:284] Internal Server Error: /api/v1/user
Traceback (most recent call last):
  File "/media/thqbop/data/Hoctap/NNLaptrinh/Python/Projects/RiBo-Core/env/lib/python3.5/site-packages/rest_framework_mongoengine/serializers.py", line 151, in create
    instance = self.recursive_save(validated_data)
  File "/media/thqbop/data/Hoctap/NNLaptrinh/Python/Projects/RiBo-Core/env/lib/python3.5/site-packages/rest_framework_mongoengine/serializers.py", line 262, in recursive_save
    instance.save()
  File "/media/thqbop/data/Hoctap/NNLaptrinh/Python/Projects/RiBo-Core/env/lib/python3.5/site-packages/mongoengine/document.py", line 360, in save
    doc = self.to_mongo()
  File "/media/thqbop/data/Hoctap/NNLaptrinh/Python/Projects/RiBo-Core/env/lib/python3.5/site-packages/mongoengine/document.py", line 242, in to_mongo
    data = super(Document, self).to_mongo(*args, **kwargs)
  File "/media/thqbop/data/Hoctap/NNLaptrinh/Python/Projects/RiBo-Core/env/lib/python3.5/site-packages/mongoengine/base/document.py", line 333, in to_mongo
    value = field.to_mongo(value, **ex_vars)
  File "/media/thqbop/data/Hoctap/NNLaptrinh/Python/Projects/RiBo-Core/env/lib/python3.5/site-packages/mongoengine/fields.py", line 1403, in to_mongo
    return Binary(value)
  File "/media/thqbop/data/Hoctap/NNLaptrinh/Python/Projects/RiBo-Core/env/lib/python3.5/site-packages/bson/binary.py", line 147, in __new__
    raise TypeError("data must be an instance of bytes")
TypeError: data must be an instance of bytes

During handling of the above exception, another exception occurred:

Traceback (most recent call last):
  File "/media/thqbop/data/Hoctap/NNLaptrinh/Python/Projects/RiBo-Core/env/lib/python3.5/site-packages/django/core/handlers/base.py", line 149, in get_response
    response = self.process_exception_by_middleware(e, request)
  File "/media/thqbop/data/Hoctap/NNLaptrinh/Python/Projects/RiBo-Core/env/lib/python3.5/site-packages/django/core/handlers/base.py", line 147, in get_response
    response = wrapped_callback(request, *callback_args, **callback_kwargs)
  File "/media/thqbop/data/Hoctap/NNLaptrinh/Python/Projects/RiBo-Core/env/lib/python3.5/site-packages/django/views/decorators/csrf.py", line 58, in wrapped_view
    return view_func(*args, **kwargs)
  File "/media/thqbop/data/Hoctap/NNLaptrinh/Python/Projects/RiBo-Core/env/lib/python3.5/site-packages/rest_framework/viewsets.py", line 87, in view
    return self.dispatch(request, *args, **kwargs)
  File "/media/thqbop/data/Hoctap/NNLaptrinh/Python/Projects/RiBo-Core/env/lib/python3.5/site-packages/rest_framework/views.py", line 466, in dispatch
    response = self.handle_exception(exc)
  File "/media/thqbop/data/Hoctap/NNLaptrinh/Python/Projects/RiBo-Core/env/lib/python3.5/site-packages/rest_framework/views.py", line 463, in dispatch
    response = handler(request, *args, **kwargs)
  File "/media/thqbop/data/Hoctap/NNLaptrinh/Python/Projects/RiBo-Core/src/ribo_api/views/user.py", line 67, in create
    raise e
  File "/media/thqbop/data/Hoctap/NNLaptrinh/Python/Projects/RiBo-Core/src/ribo_api/views/user.py", line 63, in create
    serializer.save()
  File "/media/thqbop/data/Hoctap/NNLaptrinh/Python/Projects/RiBo-Core/env/lib/python3.5/site-packages/rest_framework/serializers.py", line 191, in save
    self.instance = self.create(validated_data)
  File "/media/thqbop/data/Hoctap/NNLaptrinh/Python/Projects/RiBo-Core/env/lib/python3.5/site-packages/rest_framework_mongoengine/serializers.py", line 167, in create
    raise TypeError(msg)
TypeError: Got a `TypeError` when calling `User.objects.create()`. This may be because you have a writable field on the serializer class that is not a valid argument to `User.objects.create()`. You may need to make the field read-only, or override the UserSerializer.create() method to handle this correctly.
Original exception text was: data must be an instance of bytes.
[13/Mar/2018 16:42:16] ERROR [/media/thqbop/data/Hoctap/NNLaptrinh/Python/Projects/RiBo-Core/env/lib/python3.5/site-packages/django/core/handlers/base.py:284] Internal Server Error: /api/v1/user
Traceback (most recent call last):
  File "/media/thqbop/data/Hoctap/NNLaptrinh/Python/Projects/RiBo-Core/env/lib/python3.5/site-packages/rest_framework_mongoengine/serializers.py", line 151, in create
    instance = self.recursive_save(validated_data)
  File "/media/thqbop/data/Hoctap/NNLaptrinh/Python/Projects/RiBo-Core/env/lib/python3.5/site-packages/rest_framework_mongoengine/serializers.py", line 262, in recursive_save
    instance.save()
  File "/media/thqbop/data/Hoctap/NNLaptrinh/Python/Projects/RiBo-Core/env/lib/python3.5/site-packages/mongoengine/document.py", line 360, in save
    doc = self.to_mongo()
  File "/media/thqbop/data/Hoctap/NNLaptrinh/Python/Projects/RiBo-Core/env/lib/python3.5/site-packages/mongoengine/document.py", line 242, in to_mongo
    data = super(Document, self).to_mongo(*args, **kwargs)
  File "/media/thqbop/data/Hoctap/NNLaptrinh/Python/Projects/RiBo-Core/env/lib/python3.5/site-packages/mongoengine/base/document.py", line 333, in to_mongo
    value = field.to_mongo(value, **ex_vars)
  File "/media/thqbop/data/Hoctap/NNLaptrinh/Python/Projects/RiBo-Core/env/lib/python3.5/site-packages/mongoengine/fields.py", line 1403, in to_mongo
    return Binary(value)
  File "/media/thqbop/data/Hoctap/NNLaptrinh/Python/Projects/RiBo-Core/env/lib/python3.5/site-packages/bson/binary.py", line 147, in __new__
    raise TypeError("data must be an instance of bytes")
TypeError: data must be an instance of bytes

During handling of the above exception, another exception occurred:

Traceback (most recent call last):
  File "/media/thqbop/data/Hoctap/NNLaptrinh/Python/Projects/RiBo-Core/env/lib/python3.5/site-packages/django/core/handlers/base.py", line 149, in get_response
    response = self.process_exception_by_middleware(e, request)
  File "/media/thqbop/data/Hoctap/NNLaptrinh/Python/Projects/RiBo-Core/env/lib/python3.5/site-packages/django/core/handlers/base.py", line 147, in get_response
    response = wrapped_callback(request, *callback_args, **callback_kwargs)
  File "/media/thqbop/data/Hoctap/NNLaptrinh/Python/Projects/RiBo-Core/env/lib/python3.5/site-packages/django/views/decorators/csrf.py", line 58, in wrapped_view
    return view_func(*args, **kwargs)
  File "/media/thqbop/data/Hoctap/NNLaptrinh/Python/Projects/RiBo-Core/env/lib/python3.5/site-packages/rest_framework/viewsets.py", line 87, in view
    return self.dispatch(request, *args, **kwargs)
  File "/media/thqbop/data/Hoctap/NNLaptrinh/Python/Projects/RiBo-Core/env/lib/python3.5/site-packages/rest_framework/views.py", line 466, in dispatch
    response = self.handle_exception(exc)
  File "/media/thqbop/data/Hoctap/NNLaptrinh/Python/Projects/RiBo-Core/env/lib/python3.5/site-packages/rest_framework/views.py", line 463, in dispatch
    response = handler(request, *args, **kwargs)
  File "/media/thqbop/data/Hoctap/NNLaptrinh/Python/Projects/RiBo-Core/src/ribo_api/views/user.py", line 67, in create
    raise e
  File "/media/thqbop/data/Hoctap/NNLaptrinh/Python/Projects/RiBo-Core/src/ribo_api/views/user.py", line 63, in create
    serializer.save()
  File "/media/thqbop/data/Hoctap/NNLaptrinh/Python/Projects/RiBo-Core/env/lib/python3.5/site-packages/rest_framework/serializers.py", line 191, in save
    self.instance = self.create(validated_data)
  File "/media/thqbop/data/Hoctap/NNLaptrinh/Python/Projects/RiBo-Core/env/lib/python3.5/site-packages/rest_framework_mongoengine/serializers.py", line 167, in create
    raise TypeError(msg)
TypeError: Got a `TypeError` when calling `User.objects.create()`. This may be because you have a writable field on the serializer class that is not a valid argument to `User.objects.create()`. You may need to make the field read-only, or override the UserSerializer.create() method to handle this correctly.
Original exception text was: data must be an instance of bytes.
[13/Mar/2018 17:06:07] ERROR [/media/thqbop/data/Hoctap/NNLaptrinh/Python/Projects/RiBo-Core/env/lib/python3.5/site-packages/django/core/handlers/base.py:284] Internal Server Error: /api/v1/user
Traceback (most recent call last):
  File "/media/thqbop/data/Hoctap/NNLaptrinh/Python/Projects/RiBo-Core/env/lib/python3.5/site-packages/rest_framework_mongoengine/serializers.py", line 151, in create
    instance = self.recursive_save(validated_data)
  File "/media/thqbop/data/Hoctap/NNLaptrinh/Python/Projects/RiBo-Core/env/lib/python3.5/site-packages/rest_framework_mongoengine/serializers.py", line 262, in recursive_save
    instance.save()
  File "/media/thqbop/data/Hoctap/NNLaptrinh/Python/Projects/RiBo-Core/env/lib/python3.5/site-packages/mongoengine/document.py", line 360, in save
    doc = self.to_mongo()
  File "/media/thqbop/data/Hoctap/NNLaptrinh/Python/Projects/RiBo-Core/env/lib/python3.5/site-packages/mongoengine/document.py", line 242, in to_mongo
    data = super(Document, self).to_mongo(*args, **kwargs)
  File "/media/thqbop/data/Hoctap/NNLaptrinh/Python/Projects/RiBo-Core/env/lib/python3.5/site-packages/mongoengine/base/document.py", line 333, in to_mongo
    value = field.to_mongo(value, **ex_vars)
  File "/media/thqbop/data/Hoctap/NNLaptrinh/Python/Projects/RiBo-Core/env/lib/python3.5/site-packages/mongoengine/fields.py", line 1403, in to_mongo
    return Binary(value)
  File "/media/thqbop/data/Hoctap/NNLaptrinh/Python/Projects/RiBo-Core/env/lib/python3.5/site-packages/bson/binary.py", line 147, in __new__
    raise TypeError("data must be an instance of bytes")
TypeError: data must be an instance of bytes

During handling of the above exception, another exception occurred:

Traceback (most recent call last):
  File "/media/thqbop/data/Hoctap/NNLaptrinh/Python/Projects/RiBo-Core/env/lib/python3.5/site-packages/django/core/handlers/base.py", line 149, in get_response
    response = self.process_exception_by_middleware(e, request)
  File "/media/thqbop/data/Hoctap/NNLaptrinh/Python/Projects/RiBo-Core/env/lib/python3.5/site-packages/django/core/handlers/base.py", line 147, in get_response
    response = wrapped_callback(request, *callback_args, **callback_kwargs)
  File "/media/thqbop/data/Hoctap/NNLaptrinh/Python/Projects/RiBo-Core/env/lib/python3.5/site-packages/django/views/decorators/csrf.py", line 58, in wrapped_view
    return view_func(*args, **kwargs)
  File "/media/thqbop/data/Hoctap/NNLaptrinh/Python/Projects/RiBo-Core/env/lib/python3.5/site-packages/rest_framework/viewsets.py", line 87, in view
    return self.dispatch(request, *args, **kwargs)
  File "/media/thqbop/data/Hoctap/NNLaptrinh/Python/Projects/RiBo-Core/env/lib/python3.5/site-packages/rest_framework/views.py", line 466, in dispatch
    response = self.handle_exception(exc)
  File "/media/thqbop/data/Hoctap/NNLaptrinh/Python/Projects/RiBo-Core/env/lib/python3.5/site-packages/rest_framework/views.py", line 463, in dispatch
    response = handler(request, *args, **kwargs)
  File "/media/thqbop/data/Hoctap/NNLaptrinh/Python/Projects/RiBo-Core/src/ribo_api/views/user.py", line 67, in create
    raise e
  File "/media/thqbop/data/Hoctap/NNLaptrinh/Python/Projects/RiBo-Core/src/ribo_api/views/user.py", line 63, in create
    serializer.save()
  File "/media/thqbop/data/Hoctap/NNLaptrinh/Python/Projects/RiBo-Core/env/lib/python3.5/site-packages/rest_framework/serializers.py", line 191, in save
    self.instance = self.create(validated_data)
  File "/media/thqbop/data/Hoctap/NNLaptrinh/Python/Projects/RiBo-Core/env/lib/python3.5/site-packages/rest_framework_mongoengine/serializers.py", line 167, in create
    raise TypeError(msg)
TypeError: Got a `TypeError` when calling `User.objects.create()`. This may be because you have a writable field on the serializer class that is not a valid argument to `User.objects.create()`. You may need to make the field read-only, or override the UserSerializer.create() method to handle this correctly.
Original exception text was: data must be an instance of bytes.
[13/Mar/2018 17:08:25] DEBUG [/media/thqbop/data/Hoctap/NNLaptrinh/Python/Projects/RiBo-Core/env/lib/python3.5/site-packages/django/db/backends/utils.py:89] (0.000) SET SQL_AUTO_IS_NULL = 0; args=None
[13/Mar/2018 17:08:28] DEBUG [/media/thqbop/data/Hoctap/NNLaptrinh/Python/Projects/RiBo-Core/env/lib/python3.5/site-packages/django/db/backends/utils.py:89] (0.000) SET SQL_AUTO_IS_NULL = 0; args=None
[13/Mar/2018 17:08:28] DEBUG [/media/thqbop/data/Hoctap/NNLaptrinh/Python/Projects/RiBo-Core/env/lib/python3.5/site-packages/django/db/backends/utils.py:89] (0.012) SHOW FULL TABLES; args=None
[13/Mar/2018 17:08:28] DEBUG [/media/thqbop/data/Hoctap/NNLaptrinh/Python/Projects/RiBo-Core/env/lib/python3.5/site-packages/django/db/backends/utils.py:89] (0.011) SELECT `django_migrations`.`app`, `django_migrations`.`name` FROM `django_migrations`; args=()
[13/Mar/2018 17:08:30] ERROR [/media/thqbop/data/Hoctap/NNLaptrinh/Python/Projects/RiBo-Core/env/lib/python3.5/site-packages/django/core/handlers/base.py:284] Internal Server Error: /api/v1/user
Traceback (most recent call last):
  File "/media/thqbop/data/Hoctap/NNLaptrinh/Python/Projects/RiBo-Core/env/lib/python3.5/site-packages/rest_framework_mongoengine/serializers.py", line 151, in create
    instance = self.recursive_save(validated_data)
  File "/media/thqbop/data/Hoctap/NNLaptrinh/Python/Projects/RiBo-Core/env/lib/python3.5/site-packages/rest_framework_mongoengine/serializers.py", line 262, in recursive_save
    instance.save()
  File "/media/thqbop/data/Hoctap/NNLaptrinh/Python/Projects/RiBo-Core/env/lib/python3.5/site-packages/mongoengine/document.py", line 360, in save
    doc = self.to_mongo()
  File "/media/thqbop/data/Hoctap/NNLaptrinh/Python/Projects/RiBo-Core/env/lib/python3.5/site-packages/mongoengine/document.py", line 242, in to_mongo
    data = super(Document, self).to_mongo(*args, **kwargs)
  File "/media/thqbop/data/Hoctap/NNLaptrinh/Python/Projects/RiBo-Core/env/lib/python3.5/site-packages/mongoengine/base/document.py", line 333, in to_mongo
    value = field.to_mongo(value, **ex_vars)
  File "/media/thqbop/data/Hoctap/NNLaptrinh/Python/Projects/RiBo-Core/env/lib/python3.5/site-packages/mongoengine/fields.py", line 1403, in to_mongo
    return Binary(value)
  File "/media/thqbop/data/Hoctap/NNLaptrinh/Python/Projects/RiBo-Core/env/lib/python3.5/site-packages/bson/binary.py", line 147, in __new__
    raise TypeError("data must be an instance of bytes")
TypeError: data must be an instance of bytes

During handling of the above exception, another exception occurred:

Traceback (most recent call last):
  File "/media/thqbop/data/Hoctap/NNLaptrinh/Python/Projects/RiBo-Core/env/lib/python3.5/site-packages/django/core/handlers/base.py", line 149, in get_response
    response = self.process_exception_by_middleware(e, request)
  File "/media/thqbop/data/Hoctap/NNLaptrinh/Python/Projects/RiBo-Core/env/lib/python3.5/site-packages/django/core/handlers/base.py", line 147, in get_response
    response = wrapped_callback(request, *callback_args, **callback_kwargs)
  File "/media/thqbop/data/Hoctap/NNLaptrinh/Python/Projects/RiBo-Core/env/lib/python3.5/site-packages/django/views/decorators/csrf.py", line 58, in wrapped_view
    return view_func(*args, **kwargs)
  File "/media/thqbop/data/Hoctap/NNLaptrinh/Python/Projects/RiBo-Core/env/lib/python3.5/site-packages/rest_framework/viewsets.py", line 87, in view
    return self.dispatch(request, *args, **kwargs)
  File "/media/thqbop/data/Hoctap/NNLaptrinh/Python/Projects/RiBo-Core/env/lib/python3.5/site-packages/rest_framework/views.py", line 466, in dispatch
    response = self.handle_exception(exc)
  File "/media/thqbop/data/Hoctap/NNLaptrinh/Python/Projects/RiBo-Core/env/lib/python3.5/site-packages/rest_framework/views.py", line 463, in dispatch
    response = handler(request, *args, **kwargs)
  File "/media/thqbop/data/Hoctap/NNLaptrinh/Python/Projects/RiBo-Core/src/ribo_api/views/user.py", line 67, in create
    raise e
  File "/media/thqbop/data/Hoctap/NNLaptrinh/Python/Projects/RiBo-Core/src/ribo_api/views/user.py", line 63, in create
    serializer.save()
  File "/media/thqbop/data/Hoctap/NNLaptrinh/Python/Projects/RiBo-Core/env/lib/python3.5/site-packages/rest_framework/serializers.py", line 191, in save
    self.instance = self.create(validated_data)
  File "/media/thqbop/data/Hoctap/NNLaptrinh/Python/Projects/RiBo-Core/env/lib/python3.5/site-packages/rest_framework_mongoengine/serializers.py", line 167, in create
    raise TypeError(msg)
TypeError: Got a `TypeError` when calling `User.objects.create()`. This may be because you have a writable field on the serializer class that is not a valid argument to `User.objects.create()`. You may need to make the field read-only, or override the UserSerializer.create() method to handle this correctly.
Original exception text was: data must be an instance of bytes.
[13/Mar/2018 17:14:59] DEBUG [/media/thqbop/data/Hoctap/NNLaptrinh/Python/Projects/RiBo-Core/env/lib/python3.5/site-packages/django/db/backends/utils.py:89] (0.000) SET SQL_AUTO_IS_NULL = 0; args=None
[13/Mar/2018 17:15:01] DEBUG [/media/thqbop/data/Hoctap/NNLaptrinh/Python/Projects/RiBo-Core/env/lib/python3.5/site-packages/django/db/backends/utils.py:89] (0.000) SET SQL_AUTO_IS_NULL = 0; args=None
[13/Mar/2018 17:15:01] DEBUG [/media/thqbop/data/Hoctap/NNLaptrinh/Python/Projects/RiBo-Core/env/lib/python3.5/site-packages/django/db/backends/utils.py:89] (0.006) SHOW FULL TABLES; args=None
[13/Mar/2018 17:15:01] DEBUG [/media/thqbop/data/Hoctap/NNLaptrinh/Python/Projects/RiBo-Core/env/lib/python3.5/site-packages/django/db/backends/utils.py:89] (0.002) SELECT `django_migrations`.`app`, `django_migrations`.`name` FROM `django_migrations`; args=()
[13/Mar/2018 17:15:10] DEBUG [/media/thqbop/data/Hoctap/NNLaptrinh/Python/Projects/RiBo-Core/env/lib/python3.5/site-packages/django/db/backends/utils.py:89] (0.000) SET SQL_AUTO_IS_NULL = 0; args=None
[13/Mar/2018 17:15:11] DEBUG [/media/thqbop/data/Hoctap/NNLaptrinh/Python/Projects/RiBo-Core/env/lib/python3.5/site-packages/django/db/backends/utils.py:89] (0.000) SET SQL_AUTO_IS_NULL = 0; args=None
[13/Mar/2018 17:15:11] DEBUG [/media/thqbop/data/Hoctap/NNLaptrinh/Python/Projects/RiBo-Core/env/lib/python3.5/site-packages/django/db/backends/utils.py:89] (0.000) SHOW FULL TABLES; args=None
[13/Mar/2018 17:15:11] DEBUG [/media/thqbop/data/Hoctap/NNLaptrinh/Python/Projects/RiBo-Core/env/lib/python3.5/site-packages/django/db/backends/utils.py:89] (0.001) SELECT `django_migrations`.`app`, `django_migrations`.`name` FROM `django_migrations`; args=()
[13/Mar/2018 17:15:20] ERROR [/media/thqbop/data/Hoctap/NNLaptrinh/Python/Projects/RiBo-Core/env/lib/python3.5/site-packages/django/core/handlers/base.py:284] Internal Server Error: /api/v1/user
Traceback (most recent call last):
  File "/media/thqbop/data/Hoctap/NNLaptrinh/Python/Projects/RiBo-Core/env/lib/python3.5/site-packages/django/core/handlers/base.py", line 149, in get_response
    response = self.process_exception_by_middleware(e, request)
  File "/media/thqbop/data/Hoctap/NNLaptrinh/Python/Projects/RiBo-Core/env/lib/python3.5/site-packages/django/core/handlers/base.py", line 147, in get_response
    response = wrapped_callback(request, *callback_args, **callback_kwargs)
  File "/media/thqbop/data/Hoctap/NNLaptrinh/Python/Projects/RiBo-Core/env/lib/python3.5/site-packages/django/views/decorators/csrf.py", line 58, in wrapped_view
    return view_func(*args, **kwargs)
  File "/media/thqbop/data/Hoctap/NNLaptrinh/Python/Projects/RiBo-Core/env/lib/python3.5/site-packages/rest_framework/viewsets.py", line 87, in view
    return self.dispatch(request, *args, **kwargs)
  File "/media/thqbop/data/Hoctap/NNLaptrinh/Python/Projects/RiBo-Core/env/lib/python3.5/site-packages/rest_framework/views.py", line 466, in dispatch
    response = self.handle_exception(exc)
  File "/media/thqbop/data/Hoctap/NNLaptrinh/Python/Projects/RiBo-Core/env/lib/python3.5/site-packages/rest_framework/views.py", line 463, in dispatch
    response = handler(request, *args, **kwargs)
  File "/media/thqbop/data/Hoctap/NNLaptrinh/Python/Projects/RiBo-Core/src/ribo_api/views/user.py", line 67, in create
    raise e
  File "/media/thqbop/data/Hoctap/NNLaptrinh/Python/Projects/RiBo-Core/src/ribo_api/views/user.py", line 63, in create
    serializer.save()
  File "/media/thqbop/data/Hoctap/NNLaptrinh/Python/Projects/RiBo-Core/env/lib/python3.5/site-packages/rest_framework/serializers.py", line 191, in save
    self.instance = self.create(validated_data)
  File "/media/thqbop/data/Hoctap/NNLaptrinh/Python/Projects/RiBo-Core/src/ribo_api/serializers/user.py", line 12, in create
    obj = User.objects.create(**validated_data)
  File "/media/thqbop/data/Hoctap/NNLaptrinh/Python/Projects/RiBo-Core/env/lib/python3.5/site-packages/mongoengine/queryset/base.py", line 293, in create
    return self._document(**kwargs).save(force_insert=True)
  File "/media/thqbop/data/Hoctap/NNLaptrinh/Python/Projects/RiBo-Core/env/lib/python3.5/site-packages/mongoengine/document.py", line 360, in save
    doc = self.to_mongo()
  File "/media/thqbop/data/Hoctap/NNLaptrinh/Python/Projects/RiBo-Core/env/lib/python3.5/site-packages/mongoengine/document.py", line 242, in to_mongo
    data = super(Document, self).to_mongo(*args, **kwargs)
  File "/media/thqbop/data/Hoctap/NNLaptrinh/Python/Projects/RiBo-Core/env/lib/python3.5/site-packages/mongoengine/base/document.py", line 333, in to_mongo
    value = field.to_mongo(value, **ex_vars)
  File "/media/thqbop/data/Hoctap/NNLaptrinh/Python/Projects/RiBo-Core/env/lib/python3.5/site-packages/mongoengine/fields.py", line 1403, in to_mongo
    return Binary(value)
  File "/media/thqbop/data/Hoctap/NNLaptrinh/Python/Projects/RiBo-Core/env/lib/python3.5/site-packages/bson/binary.py", line 147, in __new__
    raise TypeError("data must be an instance of bytes")
TypeError: data must be an instance of bytes
[13/Mar/2018 17:26:19] DEBUG [/media/thqbop/data/Hoctap/NNLaptrinh/Python/Projects/RiBo-Core/env/lib/python3.5/site-packages/django/db/backends/utils.py:89] (0.000) SET SQL_AUTO_IS_NULL = 0; args=None
[13/Mar/2018 17:26:21] DEBUG [/media/thqbop/data/Hoctap/NNLaptrinh/Python/Projects/RiBo-Core/env/lib/python3.5/site-packages/django/db/backends/utils.py:89] (0.000) SET SQL_AUTO_IS_NULL = 0; args=None
[13/Mar/2018 17:26:21] DEBUG [/media/thqbop/data/Hoctap/NNLaptrinh/Python/Projects/RiBo-Core/env/lib/python3.5/site-packages/django/db/backends/utils.py:89] (0.008) SHOW FULL TABLES; args=None
[13/Mar/2018 17:26:21] DEBUG [/media/thqbop/data/Hoctap/NNLaptrinh/Python/Projects/RiBo-Core/env/lib/python3.5/site-packages/django/db/backends/utils.py:89] (0.007) SELECT `django_migrations`.`app`, `django_migrations`.`name` FROM `django_migrations`; args=()
[13/Mar/2018 17:26:56] ERROR [/media/thqbop/data/Hoctap/NNLaptrinh/Python/Projects/RiBo-Core/env/lib/python3.5/site-packages/django/core/handlers/base.py:284] Internal Server Error: /api/v1/user
Traceback (most recent call last):
  File "/media/thqbop/data/Hoctap/NNLaptrinh/Python/Projects/RiBo-Core/env/lib/python3.5/site-packages/django/core/handlers/base.py", line 149, in get_response
    response = self.process_exception_by_middleware(e, request)
  File "/media/thqbop/data/Hoctap/NNLaptrinh/Python/Projects/RiBo-Core/env/lib/python3.5/site-packages/django/core/handlers/base.py", line 147, in get_response
    response = wrapped_callback(request, *callback_args, **callback_kwargs)
  File "/media/thqbop/data/Hoctap/NNLaptrinh/Python/Projects/RiBo-Core/env/lib/python3.5/site-packages/django/views/decorators/csrf.py", line 58, in wrapped_view
    return view_func(*args, **kwargs)
  File "/media/thqbop/data/Hoctap/NNLaptrinh/Python/Projects/RiBo-Core/env/lib/python3.5/site-packages/rest_framework/viewsets.py", line 87, in view
    return self.dispatch(request, *args, **kwargs)
  File "/media/thqbop/data/Hoctap/NNLaptrinh/Python/Projects/RiBo-Core/env/lib/python3.5/site-packages/rest_framework/views.py", line 466, in dispatch
    response = self.handle_exception(exc)
  File "/media/thqbop/data/Hoctap/NNLaptrinh/Python/Projects/RiBo-Core/env/lib/python3.5/site-packages/rest_framework/views.py", line 463, in dispatch
    response = handler(request, *args, **kwargs)
  File "/media/thqbop/data/Hoctap/NNLaptrinh/Python/Projects/RiBo-Core/src/ribo_api/views/user.py", line 67, in create
    raise e
  File "/media/thqbop/data/Hoctap/NNLaptrinh/Python/Projects/RiBo-Core/src/ribo_api/views/user.py", line 63, in create
    serializer.save()
  File "/media/thqbop/data/Hoctap/NNLaptrinh/Python/Projects/RiBo-Core/env/lib/python3.5/site-packages/rest_framework/serializers.py", line 191, in save
    self.instance = self.create(validated_data)
  File "/media/thqbop/data/Hoctap/NNLaptrinh/Python/Projects/RiBo-Core/src/ribo_api/serializers/user.py", line 12, in create
    obj = User.objects.create(**validated_data)
  File "/media/thqbop/data/Hoctap/NNLaptrinh/Python/Projects/RiBo-Core/env/lib/python3.5/site-packages/mongoengine/queryset/base.py", line 293, in create
    return self._document(**kwargs).save(force_insert=True)
  File "/media/thqbop/data/Hoctap/NNLaptrinh/Python/Projects/RiBo-Core/env/lib/python3.5/site-packages/mongoengine/document.py", line 360, in save
    doc = self.to_mongo()
  File "/media/thqbop/data/Hoctap/NNLaptrinh/Python/Projects/RiBo-Core/env/lib/python3.5/site-packages/mongoengine/document.py", line 242, in to_mongo
    data = super(Document, self).to_mongo(*args, **kwargs)
  File "/media/thqbop/data/Hoctap/NNLaptrinh/Python/Projects/RiBo-Core/env/lib/python3.5/site-packages/mongoengine/base/document.py", line 333, in to_mongo
    value = field.to_mongo(value, **ex_vars)
  File "/media/thqbop/data/Hoctap/NNLaptrinh/Python/Projects/RiBo-Core/env/lib/python3.5/site-packages/mongoengine/fields.py", line 1403, in to_mongo
    return Binary(value)
  File "/media/thqbop/data/Hoctap/NNLaptrinh/Python/Projects/RiBo-Core/env/lib/python3.5/site-packages/bson/binary.py", line 147, in __new__
    raise TypeError("data must be an instance of bytes")
TypeError: data must be an instance of bytes
[13/Mar/2018 17:30:57] ERROR [/media/thqbop/data/Hoctap/NNLaptrinh/Python/Projects/RiBo-Core/env/lib/python3.5/site-packages/django/core/handlers/base.py:284] Internal Server Error: /api/v1/user
Traceback (most recent call last):
  File "/media/thqbop/data/Hoctap/NNLaptrinh/Python/Projects/RiBo-Core/env/lib/python3.5/site-packages/django/core/handlers/base.py", line 149, in get_response
    response = self.process_exception_by_middleware(e, request)
  File "/media/thqbop/data/Hoctap/NNLaptrinh/Python/Projects/RiBo-Core/env/lib/python3.5/site-packages/django/core/handlers/base.py", line 147, in get_response
    response = wrapped_callback(request, *callback_args, **callback_kwargs)
  File "/media/thqbop/data/Hoctap/NNLaptrinh/Python/Projects/RiBo-Core/env/lib/python3.5/site-packages/django/views/decorators/csrf.py", line 58, in wrapped_view
    return view_func(*args, **kwargs)
  File "/media/thqbop/data/Hoctap/NNLaptrinh/Python/Projects/RiBo-Core/env/lib/python3.5/site-packages/rest_framework/viewsets.py", line 87, in view
    return self.dispatch(request, *args, **kwargs)
  File "/media/thqbop/data/Hoctap/NNLaptrinh/Python/Projects/RiBo-Core/env/lib/python3.5/site-packages/rest_framework/views.py", line 466, in dispatch
    response = self.handle_exception(exc)
  File "/media/thqbop/data/Hoctap/NNLaptrinh/Python/Projects/RiBo-Core/env/lib/python3.5/site-packages/rest_framework/views.py", line 463, in dispatch
    response = handler(request, *args, **kwargs)
  File "/media/thqbop/data/Hoctap/NNLaptrinh/Python/Projects/RiBo-Core/src/ribo_api/views/user.py", line 67, in create
    raise e
  File "/media/thqbop/data/Hoctap/NNLaptrinh/Python/Projects/RiBo-Core/src/ribo_api/views/user.py", line 63, in create
    serializer.save()
  File "/media/thqbop/data/Hoctap/NNLaptrinh/Python/Projects/RiBo-Core/env/lib/python3.5/site-packages/rest_framework/serializers.py", line 191, in save
    self.instance = self.create(validated_data)
  File "/media/thqbop/data/Hoctap/NNLaptrinh/Python/Projects/RiBo-Core/src/ribo_api/serializers/user.py", line 12, in create
    obj = User.objects.create(**validated_data)
  File "/media/thqbop/data/Hoctap/NNLaptrinh/Python/Projects/RiBo-Core/env/lib/python3.5/site-packages/mongoengine/queryset/base.py", line 293, in create
    return self._document(**kwargs).save(force_insert=True)
  File "/media/thqbop/data/Hoctap/NNLaptrinh/Python/Projects/RiBo-Core/env/lib/python3.5/site-packages/mongoengine/document.py", line 360, in save
    doc = self.to_mongo()
  File "/media/thqbop/data/Hoctap/NNLaptrinh/Python/Projects/RiBo-Core/env/lib/python3.5/site-packages/mongoengine/document.py", line 242, in to_mongo
    data = super(Document, self).to_mongo(*args, **kwargs)
  File "/media/thqbop/data/Hoctap/NNLaptrinh/Python/Projects/RiBo-Core/env/lib/python3.5/site-packages/mongoengine/base/document.py", line 333, in to_mongo
    value = field.to_mongo(value, **ex_vars)
  File "/media/thqbop/data/Hoctap/NNLaptrinh/Python/Projects/RiBo-Core/env/lib/python3.5/site-packages/mongoengine/fields.py", line 1403, in to_mongo
    return Binary(value)
  File "/media/thqbop/data/Hoctap/NNLaptrinh/Python/Projects/RiBo-Core/env/lib/python3.5/site-packages/bson/binary.py", line 147, in __new__
    raise TypeError("data must be an instance of bytes")
TypeError: data must be an instance of bytes
[13/Mar/2018 17:31:30] ERROR [/media/thqbop/data/Hoctap/NNLaptrinh/Python/Projects/RiBo-Core/env/lib/python3.5/site-packages/django/core/handlers/base.py:284] Internal Server Error: /api/v1/user
Traceback (most recent call last):
  File "/media/thqbop/data/Hoctap/NNLaptrinh/Python/Projects/RiBo-Core/env/lib/python3.5/site-packages/django/core/handlers/base.py", line 149, in get_response
    response = self.process_exception_by_middleware(e, request)
  File "/media/thqbop/data/Hoctap/NNLaptrinh/Python/Projects/RiBo-Core/env/lib/python3.5/site-packages/django/core/handlers/base.py", line 147, in get_response
    response = wrapped_callback(request, *callback_args, **callback_kwargs)
  File "/media/thqbop/data/Hoctap/NNLaptrinh/Python/Projects/RiBo-Core/env/lib/python3.5/site-packages/django/views/decorators/csrf.py", line 58, in wrapped_view
    return view_func(*args, **kwargs)
  File "/media/thqbop/data/Hoctap/NNLaptrinh/Python/Projects/RiBo-Core/env/lib/python3.5/site-packages/rest_framework/viewsets.py", line 87, in view
    return self.dispatch(request, *args, **kwargs)
  File "/media/thqbop/data/Hoctap/NNLaptrinh/Python/Projects/RiBo-Core/env/lib/python3.5/site-packages/rest_framework/views.py", line 466, in dispatch
    response = self.handle_exception(exc)
  File "/media/thqbop/data/Hoctap/NNLaptrinh/Python/Projects/RiBo-Core/env/lib/python3.5/site-packages/rest_framework/views.py", line 463, in dispatch
    response = handler(request, *args, **kwargs)
  File "/media/thqbop/data/Hoctap/NNLaptrinh/Python/Projects/RiBo-Core/src/ribo_api/views/user.py", line 67, in create
    raise e
  File "/media/thqbop/data/Hoctap/NNLaptrinh/Python/Projects/RiBo-Core/src/ribo_api/views/user.py", line 63, in create
    serializer.save()
  File "/media/thqbop/data/Hoctap/NNLaptrinh/Python/Projects/RiBo-Core/env/lib/python3.5/site-packages/rest_framework/serializers.py", line 191, in save
    self.instance = self.create(validated_data)
  File "/media/thqbop/data/Hoctap/NNLaptrinh/Python/Projects/RiBo-Core/src/ribo_api/serializers/user.py", line 12, in create
    obj = User.objects.create(**validated_data)
  File "/media/thqbop/data/Hoctap/NNLaptrinh/Python/Projects/RiBo-Core/env/lib/python3.5/site-packages/mongoengine/queryset/base.py", line 293, in create
    return self._document(**kwargs).save(force_insert=True)
  File "/media/thqbop/data/Hoctap/NNLaptrinh/Python/Projects/RiBo-Core/env/lib/python3.5/site-packages/mongoengine/document.py", line 360, in save
    doc = self.to_mongo()
  File "/media/thqbop/data/Hoctap/NNLaptrinh/Python/Projects/RiBo-Core/env/lib/python3.5/site-packages/mongoengine/document.py", line 242, in to_mongo
    data = super(Document, self).to_mongo(*args, **kwargs)
  File "/media/thqbop/data/Hoctap/NNLaptrinh/Python/Projects/RiBo-Core/env/lib/python3.5/site-packages/mongoengine/base/document.py", line 333, in to_mongo
    value = field.to_mongo(value, **ex_vars)
  File "/media/thqbop/data/Hoctap/NNLaptrinh/Python/Projects/RiBo-Core/env/lib/python3.5/site-packages/mongoengine/fields.py", line 1403, in to_mongo
    return Binary(value)
  File "/media/thqbop/data/Hoctap/NNLaptrinh/Python/Projects/RiBo-Core/env/lib/python3.5/site-packages/bson/binary.py", line 147, in __new__
    raise TypeError("data must be an instance of bytes")
TypeError: data must be an instance of bytes
[13/Mar/2018 17:37:06] ERROR [/media/thqbop/data/Hoctap/NNLaptrinh/Python/Projects/RiBo-Core/env/lib/python3.5/site-packages/django/core/handlers/base.py:284] Internal Server Error: /api/v1/user
Traceback (most recent call last):
  File "/media/thqbop/data/Hoctap/NNLaptrinh/Python/Projects/RiBo-Core/env/lib/python3.5/site-packages/django/core/handlers/base.py", line 149, in get_response
    response = self.process_exception_by_middleware(e, request)
  File "/media/thqbop/data/Hoctap/NNLaptrinh/Python/Projects/RiBo-Core/env/lib/python3.5/site-packages/django/core/handlers/base.py", line 147, in get_response
    response = wrapped_callback(request, *callback_args, **callback_kwargs)
  File "/media/thqbop/data/Hoctap/NNLaptrinh/Python/Projects/RiBo-Core/env/lib/python3.5/site-packages/django/views/decorators/csrf.py", line 58, in wrapped_view
    return view_func(*args, **kwargs)
  File "/media/thqbop/data/Hoctap/NNLaptrinh/Python/Projects/RiBo-Core/env/lib/python3.5/site-packages/rest_framework/viewsets.py", line 87, in view
    return self.dispatch(request, *args, **kwargs)
  File "/media/thqbop/data/Hoctap/NNLaptrinh/Python/Projects/RiBo-Core/env/lib/python3.5/site-packages/rest_framework/views.py", line 466, in dispatch
    response = self.handle_exception(exc)
  File "/media/thqbop/data/Hoctap/NNLaptrinh/Python/Projects/RiBo-Core/env/lib/python3.5/site-packages/rest_framework/views.py", line 463, in dispatch
    response = handler(request, *args, **kwargs)
  File "/media/thqbop/data/Hoctap/NNLaptrinh/Python/Projects/RiBo-Core/src/ribo_api/views/user.py", line 67, in create
    raise e
  File "/media/thqbop/data/Hoctap/NNLaptrinh/Python/Projects/RiBo-Core/src/ribo_api/views/user.py", line 63, in create
    serializer.save()
  File "/media/thqbop/data/Hoctap/NNLaptrinh/Python/Projects/RiBo-Core/env/lib/python3.5/site-packages/rest_framework/serializers.py", line 191, in save
    self.instance = self.create(validated_data)
  File "/media/thqbop/data/Hoctap/NNLaptrinh/Python/Projects/RiBo-Core/src/ribo_api/serializers/user.py", line 12, in create
    obj = User.objects.create(**validated_data)
  File "/media/thqbop/data/Hoctap/NNLaptrinh/Python/Projects/RiBo-Core/env/lib/python3.5/site-packages/mongoengine/queryset/base.py", line 293, in create
    return self._document(**kwargs).save(force_insert=True)
  File "/media/thqbop/data/Hoctap/NNLaptrinh/Python/Projects/RiBo-Core/env/lib/python3.5/site-packages/mongoengine/document.py", line 360, in save
    doc = self.to_mongo()
  File "/media/thqbop/data/Hoctap/NNLaptrinh/Python/Projects/RiBo-Core/env/lib/python3.5/site-packages/mongoengine/document.py", line 242, in to_mongo
    data = super(Document, self).to_mongo(*args, **kwargs)
  File "/media/thqbop/data/Hoctap/NNLaptrinh/Python/Projects/RiBo-Core/env/lib/python3.5/site-packages/mongoengine/base/document.py", line 333, in to_mongo
    value = field.to_mongo(value, **ex_vars)
  File "/media/thqbop/data/Hoctap/NNLaptrinh/Python/Projects/RiBo-Core/env/lib/python3.5/site-packages/mongoengine/fields.py", line 1403, in to_mongo
    return Binary(value)
  File "/media/thqbop/data/Hoctap/NNLaptrinh/Python/Projects/RiBo-Core/env/lib/python3.5/site-packages/bson/binary.py", line 147, in __new__
    raise TypeError("data must be an instance of bytes")
TypeError: data must be an instance of bytes
[13/Mar/2018 17:39:54] DEBUG [/media/thqbop/data/Hoctap/NNLaptrinh/Python/Projects/RiBo-Core/env/lib/python3.5/site-packages/django/db/backends/utils.py:89] (0.000) SET SQL_AUTO_IS_NULL = 0; args=None
[13/Mar/2018 17:39:58] DEBUG [/media/thqbop/data/Hoctap/NNLaptrinh/Python/Projects/RiBo-Core/env/lib/python3.5/site-packages/django/db/backends/utils.py:89] (0.012) SET SQL_AUTO_IS_NULL = 0; args=None
[13/Mar/2018 17:39:58] DEBUG [/media/thqbop/data/Hoctap/NNLaptrinh/Python/Projects/RiBo-Core/env/lib/python3.5/site-packages/django/db/backends/utils.py:89] (0.007) SHOW FULL TABLES; args=None
[13/Mar/2018 17:39:58] DEBUG [/media/thqbop/data/Hoctap/NNLaptrinh/Python/Projects/RiBo-Core/env/lib/python3.5/site-packages/django/db/backends/utils.py:89] (0.010) SELECT `django_migrations`.`app`, `django_migrations`.`name` FROM `django_migrations`; args=()
[13/Mar/2018 17:41:25] DEBUG [/media/thqbop/data/Hoctap/NNLaptrinh/Python/Projects/RiBo-Core/env/lib/python3.5/site-packages/django/db/backends/utils.py:89] (0.000) SET SQL_AUTO_IS_NULL = 0; args=None
[13/Mar/2018 17:41:28] DEBUG [/media/thqbop/data/Hoctap/NNLaptrinh/Python/Projects/RiBo-Core/env/lib/python3.5/site-packages/django/db/backends/utils.py:89] (0.000) SET SQL_AUTO_IS_NULL = 0; args=None
[13/Mar/2018 17:41:28] DEBUG [/media/thqbop/data/Hoctap/NNLaptrinh/Python/Projects/RiBo-Core/env/lib/python3.5/site-packages/django/db/backends/utils.py:89] (0.010) SHOW FULL TABLES; args=None
[13/Mar/2018 17:41:28] DEBUG [/media/thqbop/data/Hoctap/NNLaptrinh/Python/Projects/RiBo-Core/env/lib/python3.5/site-packages/django/db/backends/utils.py:89] (0.009) SELECT `django_migrations`.`app`, `django_migrations`.`name` FROM `django_migrations`; args=()
[13/Mar/2018 17:42:06] ERROR [/media/thqbop/data/Hoctap/NNLaptrinh/Python/Projects/RiBo-Core/env/lib/python3.5/site-packages/django/core/handlers/base.py:284] Internal Server Error: /api/v1/user
Traceback (most recent call last):
  File "/media/thqbop/data/Hoctap/NNLaptrinh/Python/Projects/RiBo-Core/env/lib/python3.5/site-packages/django/core/handlers/base.py", line 149, in get_response
    response = self.process_exception_by_middleware(e, request)
  File "/media/thqbop/data/Hoctap/NNLaptrinh/Python/Projects/RiBo-Core/env/lib/python3.5/site-packages/django/core/handlers/base.py", line 147, in get_response
    response = wrapped_callback(request, *callback_args, **callback_kwargs)
  File "/media/thqbop/data/Hoctap/NNLaptrinh/Python/Projects/RiBo-Core/env/lib/python3.5/site-packages/django/views/decorators/csrf.py", line 58, in wrapped_view
    return view_func(*args, **kwargs)
  File "/media/thqbop/data/Hoctap/NNLaptrinh/Python/Projects/RiBo-Core/env/lib/python3.5/site-packages/rest_framework/viewsets.py", line 87, in view
    return self.dispatch(request, *args, **kwargs)
  File "/media/thqbop/data/Hoctap/NNLaptrinh/Python/Projects/RiBo-Core/env/lib/python3.5/site-packages/rest_framework/views.py", line 466, in dispatch
    response = self.handle_exception(exc)
  File "/media/thqbop/data/Hoctap/NNLaptrinh/Python/Projects/RiBo-Core/env/lib/python3.5/site-packages/rest_framework/views.py", line 463, in dispatch
    response = handler(request, *args, **kwargs)
  File "/media/thqbop/data/Hoctap/NNLaptrinh/Python/Projects/RiBo-Core/src/ribo_api/views/user.py", line 67, in create
    raise e
  File "/media/thqbop/data/Hoctap/NNLaptrinh/Python/Projects/RiBo-Core/src/ribo_api/views/user.py", line 63, in create
    serializer.save()
  File "/media/thqbop/data/Hoctap/NNLaptrinh/Python/Projects/RiBo-Core/env/lib/python3.5/site-packages/rest_framework/serializers.py", line 191, in save
    self.instance = self.create(validated_data)
  File "/media/thqbop/data/Hoctap/NNLaptrinh/Python/Projects/RiBo-Core/src/ribo_api/serializers/user.py", line 12, in create
    obj = User.objects.create(**validated_data)
  File "/media/thqbop/data/Hoctap/NNLaptrinh/Python/Projects/RiBo-Core/env/lib/python3.5/site-packages/mongoengine/queryset/base.py", line 293, in create
    return self._document(**kwargs).save(force_insert=True)
  File "/media/thqbop/data/Hoctap/NNLaptrinh/Python/Projects/RiBo-Core/env/lib/python3.5/site-packages/mongoengine/document.py", line 355, in save
    self.validate(clean=clean)
  File "/media/thqbop/data/Hoctap/NNLaptrinh/Python/Projects/RiBo-Core/env/lib/python3.5/site-packages/mongoengine/base/document.py", line 395, in validate
    raise ValidationError(message, errors=errors)
mongoengine.errors.ValidationError: ValidationError (User:None) (Field is required: ['email_address'])
[13/Mar/2018 17:42:20] DEBUG [/media/thqbop/data/Hoctap/NNLaptrinh/Python/Projects/RiBo-Core/env/lib/python3.5/site-packages/django/db/backends/utils.py:89] (0.000) SET SQL_AUTO_IS_NULL = 0; args=None
[13/Mar/2018 17:42:23] DEBUG [/media/thqbop/data/Hoctap/NNLaptrinh/Python/Projects/RiBo-Core/env/lib/python3.5/site-packages/django/db/backends/utils.py:89] (0.001) SET SQL_AUTO_IS_NULL = 0; args=None
[13/Mar/2018 17:42:23] DEBUG [/media/thqbop/data/Hoctap/NNLaptrinh/Python/Projects/RiBo-Core/env/lib/python3.5/site-packages/django/db/backends/utils.py:89] (0.004) SHOW FULL TABLES; args=None
[13/Mar/2018 17:42:23] DEBUG [/media/thqbop/data/Hoctap/NNLaptrinh/Python/Projects/RiBo-Core/env/lib/python3.5/site-packages/django/db/backends/utils.py:89] (0.002) SELECT `django_migrations`.`app`, `django_migrations`.`name` FROM `django_migrations`; args=()
[13/Mar/2018 17:42:27] ERROR [/media/thqbop/data/Hoctap/NNLaptrinh/Python/Projects/RiBo-Core/env/lib/python3.5/site-packages/django/core/handlers/base.py:284] Internal Server Error: /api/v1/user
Traceback (most recent call last):
  File "/media/thqbop/data/Hoctap/NNLaptrinh/Python/Projects/RiBo-Core/env/lib/python3.5/site-packages/django/core/handlers/base.py", line 149, in get_response
    response = self.process_exception_by_middleware(e, request)
  File "/media/thqbop/data/Hoctap/NNLaptrinh/Python/Projects/RiBo-Core/env/lib/python3.5/site-packages/django/core/handlers/base.py", line 147, in get_response
    response = wrapped_callback(request, *callback_args, **callback_kwargs)
  File "/media/thqbop/data/Hoctap/NNLaptrinh/Python/Projects/RiBo-Core/env/lib/python3.5/site-packages/django/views/decorators/csrf.py", line 58, in wrapped_view
    return view_func(*args, **kwargs)
  File "/media/thqbop/data/Hoctap/NNLaptrinh/Python/Projects/RiBo-Core/env/lib/python3.5/site-packages/rest_framework/viewsets.py", line 87, in view
    return self.dispatch(request, *args, **kwargs)
  File "/media/thqbop/data/Hoctap/NNLaptrinh/Python/Projects/RiBo-Core/env/lib/python3.5/site-packages/rest_framework/views.py", line 466, in dispatch
    response = self.handle_exception(exc)
  File "/media/thqbop/data/Hoctap/NNLaptrinh/Python/Projects/RiBo-Core/env/lib/python3.5/site-packages/rest_framework/views.py", line 463, in dispatch
    response = handler(request, *args, **kwargs)
  File "/media/thqbop/data/Hoctap/NNLaptrinh/Python/Projects/RiBo-Core/src/ribo_api/views/user.py", line 67, in create
    raise e
  File "/media/thqbop/data/Hoctap/NNLaptrinh/Python/Projects/RiBo-Core/src/ribo_api/views/user.py", line 63, in create
    serializer.save()
  File "/media/thqbop/data/Hoctap/NNLaptrinh/Python/Projects/RiBo-Core/env/lib/python3.5/site-packages/rest_framework/serializers.py", line 191, in save
    self.instance = self.create(validated_data)
  File "/media/thqbop/data/Hoctap/NNLaptrinh/Python/Projects/RiBo-Core/src/ribo_api/serializers/user.py", line 12, in create
    obj = User.objects.create(**validated_data)
  File "/media/thqbop/data/Hoctap/NNLaptrinh/Python/Projects/RiBo-Core/env/lib/python3.5/site-packages/mongoengine/queryset/base.py", line 293, in create
    return self._document(**kwargs).save(force_insert=True)
  File "/media/thqbop/data/Hoctap/NNLaptrinh/Python/Projects/RiBo-Core/env/lib/python3.5/site-packages/mongoengine/document.py", line 355, in save
    self.validate(clean=clean)
  File "/media/thqbop/data/Hoctap/NNLaptrinh/Python/Projects/RiBo-Core/env/lib/python3.5/site-packages/mongoengine/base/document.py", line 395, in validate
    raise ValidationError(message, errors=errors)
mongoengine.errors.ValidationError: ValidationError (User:None) (Field is required: ['email'])
[13/Mar/2018 17:43:37] ERROR [/media/thqbop/data/Hoctap/NNLaptrinh/Python/Projects/RiBo-Core/env/lib/python3.5/site-packages/django/core/handlers/base.py:284] Internal Server Error: /api/v1/user
Traceback (most recent call last):
  File "/media/thqbop/data/Hoctap/NNLaptrinh/Python/Projects/RiBo-Core/env/lib/python3.5/site-packages/django/core/handlers/base.py", line 149, in get_response
    response = self.process_exception_by_middleware(e, request)
  File "/media/thqbop/data/Hoctap/NNLaptrinh/Python/Projects/RiBo-Core/env/lib/python3.5/site-packages/django/core/handlers/base.py", line 147, in get_response
    response = wrapped_callback(request, *callback_args, **callback_kwargs)
  File "/media/thqbop/data/Hoctap/NNLaptrinh/Python/Projects/RiBo-Core/env/lib/python3.5/site-packages/django/views/decorators/csrf.py", line 58, in wrapped_view
    return view_func(*args, **kwargs)
  File "/media/thqbop/data/Hoctap/NNLaptrinh/Python/Projects/RiBo-Core/env/lib/python3.5/site-packages/rest_framework/viewsets.py", line 87, in view
    return self.dispatch(request, *args, **kwargs)
  File "/media/thqbop/data/Hoctap/NNLaptrinh/Python/Projects/RiBo-Core/env/lib/python3.5/site-packages/rest_framework/views.py", line 466, in dispatch
    response = self.handle_exception(exc)
  File "/media/thqbop/data/Hoctap/NNLaptrinh/Python/Projects/RiBo-Core/env/lib/python3.5/site-packages/rest_framework/views.py", line 463, in dispatch
    response = handler(request, *args, **kwargs)
  File "/media/thqbop/data/Hoctap/NNLaptrinh/Python/Projects/RiBo-Core/src/ribo_api/views/user.py", line 67, in create
    raise e
  File "/media/thqbop/data/Hoctap/NNLaptrinh/Python/Projects/RiBo-Core/src/ribo_api/views/user.py", line 63, in create
    serializer.save()
  File "/media/thqbop/data/Hoctap/NNLaptrinh/Python/Projects/RiBo-Core/env/lib/python3.5/site-packages/rest_framework/serializers.py", line 175, in save
    "You cannot call `.save()` after accessing `serializer.data`."
AssertionError: You cannot call `.save()` after accessing `serializer.data`.If you need to access data before committing to the database then inspect 'serializer.validated_data' instead. 
[13/Mar/2018 17:43:45] DEBUG [/media/thqbop/data/Hoctap/NNLaptrinh/Python/Projects/RiBo-Core/env/lib/python3.5/site-packages/django/db/backends/utils.py:89] (0.000) SET SQL_AUTO_IS_NULL = 0; args=None
[13/Mar/2018 17:43:46] DEBUG [/media/thqbop/data/Hoctap/NNLaptrinh/Python/Projects/RiBo-Core/env/lib/python3.5/site-packages/django/db/backends/utils.py:89] (0.000) SET SQL_AUTO_IS_NULL = 0; args=None
[13/Mar/2018 17:43:46] DEBUG [/media/thqbop/data/Hoctap/NNLaptrinh/Python/Projects/RiBo-Core/env/lib/python3.5/site-packages/django/db/backends/utils.py:89] (0.001) SHOW FULL TABLES; args=None
[13/Mar/2018 17:43:46] DEBUG [/media/thqbop/data/Hoctap/NNLaptrinh/Python/Projects/RiBo-Core/env/lib/python3.5/site-packages/django/db/backends/utils.py:89] (0.001) SELECT `django_migrations`.`app`, `django_migrations`.`name` FROM `django_migrations`; args=()
[13/Mar/2018 17:44:09] ERROR [/media/thqbop/data/Hoctap/NNLaptrinh/Python/Projects/RiBo-Core/env/lib/python3.5/site-packages/django/core/handlers/base.py:284] Internal Server Error: /api/v1/user
Traceback (most recent call last):
  File "/media/thqbop/data/Hoctap/NNLaptrinh/Python/Projects/RiBo-Core/env/lib/python3.5/site-packages/django/core/handlers/base.py", line 149, in get_response
    response = self.process_exception_by_middleware(e, request)
  File "/media/thqbop/data/Hoctap/NNLaptrinh/Python/Projects/RiBo-Core/env/lib/python3.5/site-packages/django/core/handlers/base.py", line 147, in get_response
    response = wrapped_callback(request, *callback_args, **callback_kwargs)
  File "/media/thqbop/data/Hoctap/NNLaptrinh/Python/Projects/RiBo-Core/env/lib/python3.5/site-packages/django/views/decorators/csrf.py", line 58, in wrapped_view
    return view_func(*args, **kwargs)
  File "/media/thqbop/data/Hoctap/NNLaptrinh/Python/Projects/RiBo-Core/env/lib/python3.5/site-packages/rest_framework/viewsets.py", line 87, in view
    return self.dispatch(request, *args, **kwargs)
  File "/media/thqbop/data/Hoctap/NNLaptrinh/Python/Projects/RiBo-Core/env/lib/python3.5/site-packages/rest_framework/views.py", line 466, in dispatch
    response = self.handle_exception(exc)
  File "/media/thqbop/data/Hoctap/NNLaptrinh/Python/Projects/RiBo-Core/env/lib/python3.5/site-packages/rest_framework/views.py", line 463, in dispatch
    response = handler(request, *args, **kwargs)
  File "/media/thqbop/data/Hoctap/NNLaptrinh/Python/Projects/RiBo-Core/src/ribo_api/views/user.py", line 67, in create
    raise e
  File "/media/thqbop/data/Hoctap/NNLaptrinh/Python/Projects/RiBo-Core/src/ribo_api/views/user.py", line 63, in create
    serializer.save()
  File "/media/thqbop/data/Hoctap/NNLaptrinh/Python/Projects/RiBo-Core/env/lib/python3.5/site-packages/rest_framework/serializers.py", line 175, in save
    "You cannot call `.save()` after accessing `serializer.data`."
AssertionError: You cannot call `.save()` after accessing `serializer.data`.If you need to access data before committing to the database then inspect 'serializer.validated_data' instead. 
[13/Mar/2018 17:44:34] ERROR [/media/thqbop/data/Hoctap/NNLaptrinh/Python/Projects/RiBo-Core/env/lib/python3.5/site-packages/django/core/handlers/base.py:284] Internal Server Error: /api/v1/user
Traceback (most recent call last):
  File "/media/thqbop/data/Hoctap/NNLaptrinh/Python/Projects/RiBo-Core/env/lib/python3.5/site-packages/django/core/handlers/base.py", line 149, in get_response
    response = self.process_exception_by_middleware(e, request)
  File "/media/thqbop/data/Hoctap/NNLaptrinh/Python/Projects/RiBo-Core/env/lib/python3.5/site-packages/django/core/handlers/base.py", line 147, in get_response
    response = wrapped_callback(request, *callback_args, **callback_kwargs)
  File "/media/thqbop/data/Hoctap/NNLaptrinh/Python/Projects/RiBo-Core/env/lib/python3.5/site-packages/django/views/decorators/csrf.py", line 58, in wrapped_view
    return view_func(*args, **kwargs)
  File "/media/thqbop/data/Hoctap/NNLaptrinh/Python/Projects/RiBo-Core/env/lib/python3.5/site-packages/rest_framework/viewsets.py", line 87, in view
    return self.dispatch(request, *args, **kwargs)
  File "/media/thqbop/data/Hoctap/NNLaptrinh/Python/Projects/RiBo-Core/env/lib/python3.5/site-packages/rest_framework/views.py", line 466, in dispatch
    response = self.handle_exception(exc)
  File "/media/thqbop/data/Hoctap/NNLaptrinh/Python/Projects/RiBo-Core/env/lib/python3.5/site-packages/rest_framework/views.py", line 463, in dispatch
    response = handler(request, *args, **kwargs)
  File "/media/thqbop/data/Hoctap/NNLaptrinh/Python/Projects/RiBo-Core/src/ribo_api/views/user.py", line 67, in create
    raise e
  File "/media/thqbop/data/Hoctap/NNLaptrinh/Python/Projects/RiBo-Core/src/ribo_api/views/user.py", line 63, in create
    serializer.save()
  File "/media/thqbop/data/Hoctap/NNLaptrinh/Python/Projects/RiBo-Core/env/lib/python3.5/site-packages/rest_framework/serializers.py", line 191, in save
    self.instance = self.create(validated_data)
  File "/media/thqbop/data/Hoctap/NNLaptrinh/Python/Projects/RiBo-Core/src/ribo_api/serializers/user.py", line 12, in create
    obj = User.objects.create(**validated_data)
  File "/media/thqbop/data/Hoctap/NNLaptrinh/Python/Projects/RiBo-Core/env/lib/python3.5/site-packages/mongoengine/queryset/base.py", line 293, in create
    return self._document(**kwargs).save(force_insert=True)
  File "/media/thqbop/data/Hoctap/NNLaptrinh/Python/Projects/RiBo-Core/env/lib/python3.5/site-packages/mongoengine/document.py", line 355, in save
    self.validate(clean=clean)
  File "/media/thqbop/data/Hoctap/NNLaptrinh/Python/Projects/RiBo-Core/env/lib/python3.5/site-packages/mongoengine/base/document.py", line 395, in validate
    raise ValidationError(message, errors=errors)
mongoengine.errors.ValidationError: ValidationError (User:None) (Field is required: ['email'])
[13/Mar/2018 17:44:52] ERROR [/media/thqbop/data/Hoctap/NNLaptrinh/Python/Projects/RiBo-Core/env/lib/python3.5/site-packages/django/core/handlers/base.py:284] Internal Server Error: /api/v1/user
Traceback (most recent call last):
  File "/media/thqbop/data/Hoctap/NNLaptrinh/Python/Projects/RiBo-Core/env/lib/python3.5/site-packages/django/core/handlers/base.py", line 149, in get_response
    response = self.process_exception_by_middleware(e, request)
  File "/media/thqbop/data/Hoctap/NNLaptrinh/Python/Projects/RiBo-Core/env/lib/python3.5/site-packages/django/core/handlers/base.py", line 147, in get_response
    response = wrapped_callback(request, *callback_args, **callback_kwargs)
  File "/media/thqbop/data/Hoctap/NNLaptrinh/Python/Projects/RiBo-Core/env/lib/python3.5/site-packages/django/views/decorators/csrf.py", line 58, in wrapped_view
    return view_func(*args, **kwargs)
  File "/media/thqbop/data/Hoctap/NNLaptrinh/Python/Projects/RiBo-Core/env/lib/python3.5/site-packages/rest_framework/viewsets.py", line 87, in view
    return self.dispatch(request, *args, **kwargs)
  File "/media/thqbop/data/Hoctap/NNLaptrinh/Python/Projects/RiBo-Core/env/lib/python3.5/site-packages/rest_framework/views.py", line 466, in dispatch
    response = self.handle_exception(exc)
  File "/media/thqbop/data/Hoctap/NNLaptrinh/Python/Projects/RiBo-Core/env/lib/python3.5/site-packages/rest_framework/views.py", line 463, in dispatch
    response = handler(request, *args, **kwargs)
  File "/media/thqbop/data/Hoctap/NNLaptrinh/Python/Projects/RiBo-Core/src/ribo_api/views/user.py", line 67, in create
    raise e
  File "/media/thqbop/data/Hoctap/NNLaptrinh/Python/Projects/RiBo-Core/src/ribo_api/views/user.py", line 63, in create
    serializer.save()
  File "/media/thqbop/data/Hoctap/NNLaptrinh/Python/Projects/RiBo-Core/env/lib/python3.5/site-packages/rest_framework/serializers.py", line 191, in save
    self.instance = self.create(validated_data)
  File "/media/thqbop/data/Hoctap/NNLaptrinh/Python/Projects/RiBo-Core/src/ribo_api/serializers/user.py", line 12, in create
    obj = User.objects.create(**validated_data)
  File "/media/thqbop/data/Hoctap/NNLaptrinh/Python/Projects/RiBo-Core/env/lib/python3.5/site-packages/mongoengine/queryset/base.py", line 293, in create
    return self._document(**kwargs).save(force_insert=True)
  File "/media/thqbop/data/Hoctap/NNLaptrinh/Python/Projects/RiBo-Core/env/lib/python3.5/site-packages/mongoengine/document.py", line 355, in save
    self.validate(clean=clean)
  File "/media/thqbop/data/Hoctap/NNLaptrinh/Python/Projects/RiBo-Core/env/lib/python3.5/site-packages/mongoengine/base/document.py", line 395, in validate
    raise ValidationError(message, errors=errors)
mongoengine.errors.ValidationError: ValidationError (User:None) (Field is required: ['email'])
[13/Mar/2018 17:45:08] ERROR [/media/thqbop/data/Hoctap/NNLaptrinh/Python/Projects/RiBo-Core/env/lib/python3.5/site-packages/django/core/handlers/base.py:284] Internal Server Error: /api/v1/user
Traceback (most recent call last):
  File "/media/thqbop/data/Hoctap/NNLaptrinh/Python/Projects/RiBo-Core/env/lib/python3.5/site-packages/django/core/handlers/base.py", line 149, in get_response
    response = self.process_exception_by_middleware(e, request)
  File "/media/thqbop/data/Hoctap/NNLaptrinh/Python/Projects/RiBo-Core/env/lib/python3.5/site-packages/django/core/handlers/base.py", line 147, in get_response
    response = wrapped_callback(request, *callback_args, **callback_kwargs)
  File "/media/thqbop/data/Hoctap/NNLaptrinh/Python/Projects/RiBo-Core/env/lib/python3.5/site-packages/django/views/decorators/csrf.py", line 58, in wrapped_view
    return view_func(*args, **kwargs)
  File "/media/thqbop/data/Hoctap/NNLaptrinh/Python/Projects/RiBo-Core/env/lib/python3.5/site-packages/rest_framework/viewsets.py", line 87, in view
    return self.dispatch(request, *args, **kwargs)
  File "/media/thqbop/data/Hoctap/NNLaptrinh/Python/Projects/RiBo-Core/env/lib/python3.5/site-packages/rest_framework/views.py", line 466, in dispatch
    response = self.handle_exception(exc)
  File "/media/thqbop/data/Hoctap/NNLaptrinh/Python/Projects/RiBo-Core/env/lib/python3.5/site-packages/rest_framework/views.py", line 463, in dispatch
    response = handler(request, *args, **kwargs)
  File "/media/thqbop/data/Hoctap/NNLaptrinh/Python/Projects/RiBo-Core/src/ribo_api/views/user.py", line 67, in create
    raise e
  File "/media/thqbop/data/Hoctap/NNLaptrinh/Python/Projects/RiBo-Core/src/ribo_api/views/user.py", line 63, in create
    serializer.save()
  File "/media/thqbop/data/Hoctap/NNLaptrinh/Python/Projects/RiBo-Core/env/lib/python3.5/site-packages/rest_framework/serializers.py", line 191, in save
    self.instance = self.create(validated_data)
  File "/media/thqbop/data/Hoctap/NNLaptrinh/Python/Projects/RiBo-Core/src/ribo_api/serializers/user.py", line 12, in create
    obj = User.objects.create(**validated_data)
  File "/media/thqbop/data/Hoctap/NNLaptrinh/Python/Projects/RiBo-Core/env/lib/python3.5/site-packages/mongoengine/queryset/base.py", line 293, in create
    return self._document(**kwargs).save(force_insert=True)
  File "/media/thqbop/data/Hoctap/NNLaptrinh/Python/Projects/RiBo-Core/env/lib/python3.5/site-packages/mongoengine/document.py", line 355, in save
    self.validate(clean=clean)
  File "/media/thqbop/data/Hoctap/NNLaptrinh/Python/Projects/RiBo-Core/env/lib/python3.5/site-packages/mongoengine/base/document.py", line 395, in validate
    raise ValidationError(message, errors=errors)
mongoengine.errors.ValidationError: ValidationError (User:None) (Field is required: ['email'])
[13/Mar/2018 17:45:39] DEBUG [/media/thqbop/data/Hoctap/NNLaptrinh/Python/Projects/RiBo-Core/env/lib/python3.5/site-packages/django/db/backends/utils.py:89] (0.000) SET SQL_AUTO_IS_NULL = 0; args=None
[13/Mar/2018 17:45:40] DEBUG [/media/thqbop/data/Hoctap/NNLaptrinh/Python/Projects/RiBo-Core/env/lib/python3.5/site-packages/django/db/backends/utils.py:89] (0.000) SET SQL_AUTO_IS_NULL = 0; args=None
[13/Mar/2018 17:45:40] DEBUG [/media/thqbop/data/Hoctap/NNLaptrinh/Python/Projects/RiBo-Core/env/lib/python3.5/site-packages/django/db/backends/utils.py:89] (0.001) SHOW FULL TABLES; args=None
[13/Mar/2018 17:45:40] DEBUG [/media/thqbop/data/Hoctap/NNLaptrinh/Python/Projects/RiBo-Core/env/lib/python3.5/site-packages/django/db/backends/utils.py:89] (0.001) SELECT `django_migrations`.`app`, `django_migrations`.`name` FROM `django_migrations`; args=()
[13/Mar/2018 17:45:57] ERROR [/media/thqbop/data/Hoctap/NNLaptrinh/Python/Projects/RiBo-Core/env/lib/python3.5/site-packages/django/core/handlers/base.py:284] Internal Server Error: /api/v1/user
Traceback (most recent call last):
  File "/media/thqbop/data/Hoctap/NNLaptrinh/Python/Projects/RiBo-Core/env/lib/python3.5/site-packages/django/core/handlers/base.py", line 149, in get_response
    response = self.process_exception_by_middleware(e, request)
  File "/media/thqbop/data/Hoctap/NNLaptrinh/Python/Projects/RiBo-Core/env/lib/python3.5/site-packages/django/core/handlers/base.py", line 147, in get_response
    response = wrapped_callback(request, *callback_args, **callback_kwargs)
  File "/media/thqbop/data/Hoctap/NNLaptrinh/Python/Projects/RiBo-Core/env/lib/python3.5/site-packages/django/views/decorators/csrf.py", line 58, in wrapped_view
    return view_func(*args, **kwargs)
  File "/media/thqbop/data/Hoctap/NNLaptrinh/Python/Projects/RiBo-Core/env/lib/python3.5/site-packages/rest_framework/viewsets.py", line 87, in view
    return self.dispatch(request, *args, **kwargs)
  File "/media/thqbop/data/Hoctap/NNLaptrinh/Python/Projects/RiBo-Core/env/lib/python3.5/site-packages/rest_framework/views.py", line 466, in dispatch
    response = self.handle_exception(exc)
  File "/media/thqbop/data/Hoctap/NNLaptrinh/Python/Projects/RiBo-Core/env/lib/python3.5/site-packages/rest_framework/views.py", line 463, in dispatch
    response = handler(request, *args, **kwargs)
  File "/media/thqbop/data/Hoctap/NNLaptrinh/Python/Projects/RiBo-Core/src/ribo_api/views/user.py", line 67, in create
    raise e
  File "/media/thqbop/data/Hoctap/NNLaptrinh/Python/Projects/RiBo-Core/src/ribo_api/views/user.py", line 63, in create
    serializer.save()
  File "/media/thqbop/data/Hoctap/NNLaptrinh/Python/Projects/RiBo-Core/env/lib/python3.5/site-packages/rest_framework/serializers.py", line 191, in save
    self.instance = self.create(validated_data)
  File "/media/thqbop/data/Hoctap/NNLaptrinh/Python/Projects/RiBo-Core/src/ribo_api/serializers/user.py", line 12, in create
    obj = User.objects.create(**validated_data)
  File "/media/thqbop/data/Hoctap/NNLaptrinh/Python/Projects/RiBo-Core/env/lib/python3.5/site-packages/mongoengine/queryset/base.py", line 293, in create
    return self._document(**kwargs).save(force_insert=True)
  File "/media/thqbop/data/Hoctap/NNLaptrinh/Python/Projects/RiBo-Core/env/lib/python3.5/site-packages/mongoengine/document.py", line 355, in save
    self.validate(clean=clean)
  File "/media/thqbop/data/Hoctap/NNLaptrinh/Python/Projects/RiBo-Core/env/lib/python3.5/site-packages/mongoengine/base/document.py", line 395, in validate
    raise ValidationError(message, errors=errors)
mongoengine.errors.ValidationError: ValidationError (User:None) (Field is required: ['email'])
[13/Mar/2018 17:46:47] DEBUG [/media/thqbop/data/Hoctap/NNLaptrinh/Python/Projects/RiBo-Core/env/lib/python3.5/site-packages/django/db/backends/utils.py:89] (0.000) SET SQL_AUTO_IS_NULL = 0; args=None
[13/Mar/2018 17:46:48] DEBUG [/media/thqbop/data/Hoctap/NNLaptrinh/Python/Projects/RiBo-Core/env/lib/python3.5/site-packages/django/db/backends/utils.py:89] (0.000) SET SQL_AUTO_IS_NULL = 0; args=None
[13/Mar/2018 17:46:48] DEBUG [/media/thqbop/data/Hoctap/NNLaptrinh/Python/Projects/RiBo-Core/env/lib/python3.5/site-packages/django/db/backends/utils.py:89] (0.001) SHOW FULL TABLES; args=None
[13/Mar/2018 17:46:48] DEBUG [/media/thqbop/data/Hoctap/NNLaptrinh/Python/Projects/RiBo-Core/env/lib/python3.5/site-packages/django/db/backends/utils.py:89] (0.001) SELECT `django_migrations`.`app`, `django_migrations`.`name` FROM `django_migrations`; args=()
[13/Mar/2018 17:46:57] ERROR [/media/thqbop/data/Hoctap/NNLaptrinh/Python/Projects/RiBo-Core/env/lib/python3.5/site-packages/django/core/handlers/base.py:284] Internal Server Error: /api/v1/user
Traceback (most recent call last):
  File "/media/thqbop/data/Hoctap/NNLaptrinh/Python/Projects/RiBo-Core/env/lib/python3.5/site-packages/django/core/handlers/base.py", line 149, in get_response
    response = self.process_exception_by_middleware(e, request)
  File "/media/thqbop/data/Hoctap/NNLaptrinh/Python/Projects/RiBo-Core/env/lib/python3.5/site-packages/django/core/handlers/base.py", line 147, in get_response
    response = wrapped_callback(request, *callback_args, **callback_kwargs)
  File "/media/thqbop/data/Hoctap/NNLaptrinh/Python/Projects/RiBo-Core/env/lib/python3.5/site-packages/django/views/decorators/csrf.py", line 58, in wrapped_view
    return view_func(*args, **kwargs)
  File "/media/thqbop/data/Hoctap/NNLaptrinh/Python/Projects/RiBo-Core/env/lib/python3.5/site-packages/rest_framework/viewsets.py", line 87, in view
    return self.dispatch(request, *args, **kwargs)
  File "/media/thqbop/data/Hoctap/NNLaptrinh/Python/Projects/RiBo-Core/env/lib/python3.5/site-packages/rest_framework/views.py", line 466, in dispatch
    response = self.handle_exception(exc)
  File "/media/thqbop/data/Hoctap/NNLaptrinh/Python/Projects/RiBo-Core/env/lib/python3.5/site-packages/rest_framework/views.py", line 463, in dispatch
    response = handler(request, *args, **kwargs)
  File "/media/thqbop/data/Hoctap/NNLaptrinh/Python/Projects/RiBo-Core/src/ribo_api/views/user.py", line 67, in create
    raise e
  File "/media/thqbop/data/Hoctap/NNLaptrinh/Python/Projects/RiBo-Core/src/ribo_api/views/user.py", line 63, in create
    serializer.save()
  File "/media/thqbop/data/Hoctap/NNLaptrinh/Python/Projects/RiBo-Core/env/lib/python3.5/site-packages/rest_framework/serializers.py", line 191, in save
    self.instance = self.create(validated_data)
  File "/media/thqbop/data/Hoctap/NNLaptrinh/Python/Projects/RiBo-Core/src/ribo_api/serializers/user.py", line 12, in create
    obj = User.objects.create(**validated_data)
  File "/media/thqbop/data/Hoctap/NNLaptrinh/Python/Projects/RiBo-Core/env/lib/python3.5/site-packages/mongoengine/queryset/base.py", line 293, in create
    return self._document(**kwargs).save(force_insert=True)
  File "/media/thqbop/data/Hoctap/NNLaptrinh/Python/Projects/RiBo-Core/env/lib/python3.5/site-packages/mongoengine/document.py", line 355, in save
    self.validate(clean=clean)
  File "/media/thqbop/data/Hoctap/NNLaptrinh/Python/Projects/RiBo-Core/env/lib/python3.5/site-packages/mongoengine/base/document.py", line 395, in validate
    raise ValidationError(message, errors=errors)
mongoengine.errors.ValidationError: ValidationError (User:None) (Field is required: ['username'])
[13/Mar/2018 17:47:57] DEBUG [/media/thqbop/data/Hoctap/NNLaptrinh/Python/Projects/RiBo-Core/env/lib/python3.5/site-packages/django/db/backends/utils.py:89] (0.000) SET SQL_AUTO_IS_NULL = 0; args=None
[13/Mar/2018 17:48:00] DEBUG [/media/thqbop/data/Hoctap/NNLaptrinh/Python/Projects/RiBo-Core/env/lib/python3.5/site-packages/django/db/backends/utils.py:89] (0.000) SET SQL_AUTO_IS_NULL = 0; args=None
[13/Mar/2018 17:48:00] DEBUG [/media/thqbop/data/Hoctap/NNLaptrinh/Python/Projects/RiBo-Core/env/lib/python3.5/site-packages/django/db/backends/utils.py:89] (0.004) SHOW FULL TABLES; args=None
[13/Mar/2018 17:48:00] DEBUG [/media/thqbop/data/Hoctap/NNLaptrinh/Python/Projects/RiBo-Core/env/lib/python3.5/site-packages/django/db/backends/utils.py:89] (0.002) SELECT `django_migrations`.`app`, `django_migrations`.`name` FROM `django_migrations`; args=()
[13/Mar/2018 17:48:08] DEBUG [/media/thqbop/data/Hoctap/NNLaptrinh/Python/Projects/RiBo-Core/env/lib/python3.5/site-packages/django/db/backends/utils.py:89] (0.000) SET SQL_AUTO_IS_NULL = 0; args=None
[13/Mar/2018 17:48:09] DEBUG [/media/thqbop/data/Hoctap/NNLaptrinh/Python/Projects/RiBo-Core/env/lib/python3.5/site-packages/django/db/backends/utils.py:89] (0.000) SET SQL_AUTO_IS_NULL = 0; args=None
[13/Mar/2018 17:48:09] DEBUG [/media/thqbop/data/Hoctap/NNLaptrinh/Python/Projects/RiBo-Core/env/lib/python3.5/site-packages/django/db/backends/utils.py:89] (0.001) SHOW FULL TABLES; args=None
[13/Mar/2018 17:48:09] DEBUG [/media/thqbop/data/Hoctap/NNLaptrinh/Python/Projects/RiBo-Core/env/lib/python3.5/site-packages/django/db/backends/utils.py:89] (0.001) SELECT `django_migrations`.`app`, `django_migrations`.`name` FROM `django_migrations`; args=()
[13/Mar/2018 17:48:29] ERROR [/media/thqbop/data/Hoctap/NNLaptrinh/Python/Projects/RiBo-Core/env/lib/python3.5/site-packages/django/core/handlers/base.py:284] Internal Server Error: /api/v1/user
Traceback (most recent call last):
  File "/media/thqbop/data/Hoctap/NNLaptrinh/Python/Projects/RiBo-Core/env/lib/python3.5/site-packages/django/core/handlers/base.py", line 149, in get_response
    response = self.process_exception_by_middleware(e, request)
  File "/media/thqbop/data/Hoctap/NNLaptrinh/Python/Projects/RiBo-Core/env/lib/python3.5/site-packages/django/core/handlers/base.py", line 147, in get_response
    response = wrapped_callback(request, *callback_args, **callback_kwargs)
  File "/media/thqbop/data/Hoctap/NNLaptrinh/Python/Projects/RiBo-Core/env/lib/python3.5/site-packages/django/views/decorators/csrf.py", line 58, in wrapped_view
    return view_func(*args, **kwargs)
  File "/media/thqbop/data/Hoctap/NNLaptrinh/Python/Projects/RiBo-Core/env/lib/python3.5/site-packages/rest_framework/viewsets.py", line 87, in view
    return self.dispatch(request, *args, **kwargs)
  File "/media/thqbop/data/Hoctap/NNLaptrinh/Python/Projects/RiBo-Core/env/lib/python3.5/site-packages/rest_framework/views.py", line 466, in dispatch
    response = self.handle_exception(exc)
  File "/media/thqbop/data/Hoctap/NNLaptrinh/Python/Projects/RiBo-Core/env/lib/python3.5/site-packages/rest_framework/views.py", line 463, in dispatch
    response = handler(request, *args, **kwargs)
  File "/media/thqbop/data/Hoctap/NNLaptrinh/Python/Projects/RiBo-Core/src/ribo_api/views/user.py", line 67, in create
    raise e
  File "/media/thqbop/data/Hoctap/NNLaptrinh/Python/Projects/RiBo-Core/src/ribo_api/views/user.py", line 63, in create
    serializer.save()
  File "/media/thqbop/data/Hoctap/NNLaptrinh/Python/Projects/RiBo-Core/env/lib/python3.5/site-packages/rest_framework/serializers.py", line 191, in save
    self.instance = self.create(validated_data)
  File "/media/thqbop/data/Hoctap/NNLaptrinh/Python/Projects/RiBo-Core/src/ribo_api/serializers/user.py", line 12, in create
    obj = User.objects.create(**validated_data)
  File "/media/thqbop/data/Hoctap/NNLaptrinh/Python/Projects/RiBo-Core/env/lib/python3.5/site-packages/mongoengine/queryset/base.py", line 293, in create
    return self._document(**kwargs).save(force_insert=True)
  File "/media/thqbop/data/Hoctap/NNLaptrinh/Python/Projects/RiBo-Core/env/lib/python3.5/site-packages/mongoengine/document.py", line 355, in save
    self.validate(clean=clean)
  File "/media/thqbop/data/Hoctap/NNLaptrinh/Python/Projects/RiBo-Core/env/lib/python3.5/site-packages/mongoengine/base/document.py", line 395, in validate
    raise ValidationError(message, errors=errors)
mongoengine.errors.ValidationError: ValidationError (User:None) (Field is required: ['email'])
[13/Mar/2018 17:48:55] DEBUG [/media/thqbop/data/Hoctap/NNLaptrinh/Python/Projects/RiBo-Core/env/lib/python3.5/site-packages/django/db/backends/utils.py:89] (0.000) SET SQL_AUTO_IS_NULL = 0; args=None
[13/Mar/2018 17:48:56] DEBUG [/media/thqbop/data/Hoctap/NNLaptrinh/Python/Projects/RiBo-Core/env/lib/python3.5/site-packages/django/db/backends/utils.py:89] (0.000) SET SQL_AUTO_IS_NULL = 0; args=None
[13/Mar/2018 17:48:56] DEBUG [/media/thqbop/data/Hoctap/NNLaptrinh/Python/Projects/RiBo-Core/env/lib/python3.5/site-packages/django/db/backends/utils.py:89] (0.001) SHOW FULL TABLES; args=None
[13/Mar/2018 17:48:56] DEBUG [/media/thqbop/data/Hoctap/NNLaptrinh/Python/Projects/RiBo-Core/env/lib/python3.5/site-packages/django/db/backends/utils.py:89] (0.000) SELECT `django_migrations`.`app`, `django_migrations`.`name` FROM `django_migrations`; args=()
[13/Mar/2018 17:49:04] ERROR [/media/thqbop/data/Hoctap/NNLaptrinh/Python/Projects/RiBo-Core/env/lib/python3.5/site-packages/django/core/handlers/base.py:284] Internal Server Error: /api/v1/user
Traceback (most recent call last):
  File "/media/thqbop/data/Hoctap/NNLaptrinh/Python/Projects/RiBo-Core/env/lib/python3.5/site-packages/django/core/handlers/base.py", line 149, in get_response
    response = self.process_exception_by_middleware(e, request)
  File "/media/thqbop/data/Hoctap/NNLaptrinh/Python/Projects/RiBo-Core/env/lib/python3.5/site-packages/django/core/handlers/base.py", line 147, in get_response
    response = wrapped_callback(request, *callback_args, **callback_kwargs)
  File "/media/thqbop/data/Hoctap/NNLaptrinh/Python/Projects/RiBo-Core/env/lib/python3.5/site-packages/django/views/decorators/csrf.py", line 58, in wrapped_view
    return view_func(*args, **kwargs)
  File "/media/thqbop/data/Hoctap/NNLaptrinh/Python/Projects/RiBo-Core/env/lib/python3.5/site-packages/rest_framework/viewsets.py", line 87, in view
    return self.dispatch(request, *args, **kwargs)
  File "/media/thqbop/data/Hoctap/NNLaptrinh/Python/Projects/RiBo-Core/env/lib/python3.5/site-packages/rest_framework/views.py", line 466, in dispatch
    response = self.handle_exception(exc)
  File "/media/thqbop/data/Hoctap/NNLaptrinh/Python/Projects/RiBo-Core/env/lib/python3.5/site-packages/rest_framework/views.py", line 463, in dispatch
    response = handler(request, *args, **kwargs)
  File "/media/thqbop/data/Hoctap/NNLaptrinh/Python/Projects/RiBo-Core/src/ribo_api/views/user.py", line 67, in create
    raise e
  File "/media/thqbop/data/Hoctap/NNLaptrinh/Python/Projects/RiBo-Core/src/ribo_api/views/user.py", line 63, in create
    serializer.save()
  File "/media/thqbop/data/Hoctap/NNLaptrinh/Python/Projects/RiBo-Core/env/lib/python3.5/site-packages/rest_framework/serializers.py", line 191, in save
    self.instance = self.create(validated_data)
  File "/media/thqbop/data/Hoctap/NNLaptrinh/Python/Projects/RiBo-Core/src/ribo_api/serializers/user.py", line 12, in create
    obj = User.objects.create(**validated_data)
  File "/media/thqbop/data/Hoctap/NNLaptrinh/Python/Projects/RiBo-Core/env/lib/python3.5/site-packages/mongoengine/queryset/base.py", line 293, in create
    return self._document(**kwargs).save(force_insert=True)
  File "/media/thqbop/data/Hoctap/NNLaptrinh/Python/Projects/RiBo-Core/env/lib/python3.5/site-packages/mongoengine/document.py", line 355, in save
    self.validate(clean=clean)
  File "/media/thqbop/data/Hoctap/NNLaptrinh/Python/Projects/RiBo-Core/env/lib/python3.5/site-packages/mongoengine/base/document.py", line 395, in validate
    raise ValidationError(message, errors=errors)
mongoengine.errors.ValidationError: ValidationError (User:None) (Field is required: ['email'])
[13/Mar/2018 17:49:20] ERROR [/media/thqbop/data/Hoctap/NNLaptrinh/Python/Projects/RiBo-Core/env/lib/python3.5/site-packages/django/core/handlers/base.py:284] Internal Server Error: /api/v1/user
Traceback (most recent call last):
  File "/media/thqbop/data/Hoctap/NNLaptrinh/Python/Projects/RiBo-Core/env/lib/python3.5/site-packages/django/core/handlers/base.py", line 149, in get_response
    response = self.process_exception_by_middleware(e, request)
  File "/media/thqbop/data/Hoctap/NNLaptrinh/Python/Projects/RiBo-Core/env/lib/python3.5/site-packages/django/core/handlers/base.py", line 147, in get_response
    response = wrapped_callback(request, *callback_args, **callback_kwargs)
  File "/media/thqbop/data/Hoctap/NNLaptrinh/Python/Projects/RiBo-Core/env/lib/python3.5/site-packages/django/views/decorators/csrf.py", line 58, in wrapped_view
    return view_func(*args, **kwargs)
  File "/media/thqbop/data/Hoctap/NNLaptrinh/Python/Projects/RiBo-Core/env/lib/python3.5/site-packages/rest_framework/viewsets.py", line 87, in view
    return self.dispatch(request, *args, **kwargs)
  File "/media/thqbop/data/Hoctap/NNLaptrinh/Python/Projects/RiBo-Core/env/lib/python3.5/site-packages/rest_framework/views.py", line 466, in dispatch
    response = self.handle_exception(exc)
  File "/media/thqbop/data/Hoctap/NNLaptrinh/Python/Projects/RiBo-Core/env/lib/python3.5/site-packages/rest_framework/views.py", line 463, in dispatch
    response = handler(request, *args, **kwargs)
  File "/media/thqbop/data/Hoctap/NNLaptrinh/Python/Projects/RiBo-Core/src/ribo_api/views/user.py", line 67, in create
    raise e
  File "/media/thqbop/data/Hoctap/NNLaptrinh/Python/Projects/RiBo-Core/src/ribo_api/views/user.py", line 63, in create
    serializer.save()
  File "/media/thqbop/data/Hoctap/NNLaptrinh/Python/Projects/RiBo-Core/env/lib/python3.5/site-packages/rest_framework/serializers.py", line 191, in save
    self.instance = self.create(validated_data)
  File "/media/thqbop/data/Hoctap/NNLaptrinh/Python/Projects/RiBo-Core/src/ribo_api/serializers/user.py", line 12, in create
    obj = User.objects.create(**validated_data)
  File "/media/thqbop/data/Hoctap/NNLaptrinh/Python/Projects/RiBo-Core/env/lib/python3.5/site-packages/mongoengine/queryset/base.py", line 293, in create
    return self._document(**kwargs).save(force_insert=True)
  File "/media/thqbop/data/Hoctap/NNLaptrinh/Python/Projects/RiBo-Core/env/lib/python3.5/site-packages/mongoengine/document.py", line 355, in save
    self.validate(clean=clean)
  File "/media/thqbop/data/Hoctap/NNLaptrinh/Python/Projects/RiBo-Core/env/lib/python3.5/site-packages/mongoengine/base/document.py", line 395, in validate
    raise ValidationError(message, errors=errors)
mongoengine.errors.ValidationError: ValidationError (User:None) (Field is required: ['email'])
[13/Mar/2018 17:49:53] DEBUG [/media/thqbop/data/Hoctap/NNLaptrinh/Python/Projects/RiBo-Core/env/lib/python3.5/site-packages/django/db/backends/utils.py:89] (0.000) SET SQL_AUTO_IS_NULL = 0; args=None
[13/Mar/2018 17:49:54] DEBUG [/media/thqbop/data/Hoctap/NNLaptrinh/Python/Projects/RiBo-Core/env/lib/python3.5/site-packages/django/db/backends/utils.py:89] (0.000) SET SQL_AUTO_IS_NULL = 0; args=None
[13/Mar/2018 17:49:54] DEBUG [/media/thqbop/data/Hoctap/NNLaptrinh/Python/Projects/RiBo-Core/env/lib/python3.5/site-packages/django/db/backends/utils.py:89] (0.001) SHOW FULL TABLES; args=None
[13/Mar/2018 17:49:54] DEBUG [/media/thqbop/data/Hoctap/NNLaptrinh/Python/Projects/RiBo-Core/env/lib/python3.5/site-packages/django/db/backends/utils.py:89] (0.001) SELECT `django_migrations`.`app`, `django_migrations`.`name` FROM `django_migrations`; args=()
[13/Mar/2018 17:49:59] ERROR [/media/thqbop/data/Hoctap/NNLaptrinh/Python/Projects/RiBo-Core/env/lib/python3.5/site-packages/django/core/handlers/base.py:284] Internal Server Error: /api/v1/user
Traceback (most recent call last):
  File "/media/thqbop/data/Hoctap/NNLaptrinh/Python/Projects/RiBo-Core/env/lib/python3.5/site-packages/django/core/handlers/base.py", line 149, in get_response
    response = self.process_exception_by_middleware(e, request)
  File "/media/thqbop/data/Hoctap/NNLaptrinh/Python/Projects/RiBo-Core/env/lib/python3.5/site-packages/django/core/handlers/base.py", line 147, in get_response
    response = wrapped_callback(request, *callback_args, **callback_kwargs)
  File "/media/thqbop/data/Hoctap/NNLaptrinh/Python/Projects/RiBo-Core/env/lib/python3.5/site-packages/django/views/decorators/csrf.py", line 58, in wrapped_view
    return view_func(*args, **kwargs)
  File "/media/thqbop/data/Hoctap/NNLaptrinh/Python/Projects/RiBo-Core/env/lib/python3.5/site-packages/rest_framework/viewsets.py", line 87, in view
    return self.dispatch(request, *args, **kwargs)
  File "/media/thqbop/data/Hoctap/NNLaptrinh/Python/Projects/RiBo-Core/env/lib/python3.5/site-packages/rest_framework/views.py", line 466, in dispatch
    response = self.handle_exception(exc)
  File "/media/thqbop/data/Hoctap/NNLaptrinh/Python/Projects/RiBo-Core/env/lib/python3.5/site-packages/rest_framework/views.py", line 463, in dispatch
    response = handler(request, *args, **kwargs)
  File "/media/thqbop/data/Hoctap/NNLaptrinh/Python/Projects/RiBo-Core/src/ribo_api/views/user.py", line 67, in create
    raise e
  File "/media/thqbop/data/Hoctap/NNLaptrinh/Python/Projects/RiBo-Core/src/ribo_api/views/user.py", line 63, in create
    serializer.save()
  File "/media/thqbop/data/Hoctap/NNLaptrinh/Python/Projects/RiBo-Core/env/lib/python3.5/site-packages/rest_framework/serializers.py", line 191, in save
    self.instance = self.create(validated_data)
  File "/media/thqbop/data/Hoctap/NNLaptrinh/Python/Projects/RiBo-Core/src/ribo_api/serializers/user.py", line 12, in create
    obj = User.objects.create(**validated_data)
  File "/media/thqbop/data/Hoctap/NNLaptrinh/Python/Projects/RiBo-Core/env/lib/python3.5/site-packages/mongoengine/queryset/base.py", line 293, in create
    return self._document(**kwargs).save(force_insert=True)
  File "/media/thqbop/data/Hoctap/NNLaptrinh/Python/Projects/RiBo-Core/env/lib/python3.5/site-packages/mongoengine/document.py", line 355, in save
    self.validate(clean=clean)
  File "/media/thqbop/data/Hoctap/NNLaptrinh/Python/Projects/RiBo-Core/env/lib/python3.5/site-packages/mongoengine/base/document.py", line 395, in validate
    raise ValidationError(message, errors=errors)
mongoengine.errors.ValidationError: ValidationError (User:None) (Field is required: ['username'])
[13/Mar/2018 17:50:54] ERROR [/media/thqbop/data/Hoctap/NNLaptrinh/Python/Projects/RiBo-Core/env/lib/python3.5/site-packages/django/core/handlers/base.py:284] Internal Server Error: /api/v1/user
Traceback (most recent call last):
  File "/media/thqbop/data/Hoctap/NNLaptrinh/Python/Projects/RiBo-Core/env/lib/python3.5/site-packages/django/core/handlers/base.py", line 149, in get_response
    response = self.process_exception_by_middleware(e, request)
  File "/media/thqbop/data/Hoctap/NNLaptrinh/Python/Projects/RiBo-Core/env/lib/python3.5/site-packages/django/core/handlers/base.py", line 147, in get_response
    response = wrapped_callback(request, *callback_args, **callback_kwargs)
  File "/media/thqbop/data/Hoctap/NNLaptrinh/Python/Projects/RiBo-Core/env/lib/python3.5/site-packages/django/views/decorators/csrf.py", line 58, in wrapped_view
    return view_func(*args, **kwargs)
  File "/media/thqbop/data/Hoctap/NNLaptrinh/Python/Projects/RiBo-Core/env/lib/python3.5/site-packages/rest_framework/viewsets.py", line 87, in view
    return self.dispatch(request, *args, **kwargs)
  File "/media/thqbop/data/Hoctap/NNLaptrinh/Python/Projects/RiBo-Core/env/lib/python3.5/site-packages/rest_framework/views.py", line 466, in dispatch
    response = self.handle_exception(exc)
  File "/media/thqbop/data/Hoctap/NNLaptrinh/Python/Projects/RiBo-Core/env/lib/python3.5/site-packages/rest_framework/views.py", line 463, in dispatch
    response = handler(request, *args, **kwargs)
  File "/media/thqbop/data/Hoctap/NNLaptrinh/Python/Projects/RiBo-Core/src/ribo_api/views/user.py", line 67, in create
    raise e
  File "/media/thqbop/data/Hoctap/NNLaptrinh/Python/Projects/RiBo-Core/src/ribo_api/views/user.py", line 63, in create
    serializer.save()
  File "/media/thqbop/data/Hoctap/NNLaptrinh/Python/Projects/RiBo-Core/env/lib/python3.5/site-packages/rest_framework/serializers.py", line 175, in save
    "You cannot call `.save()` after accessing `serializer.data`."
AssertionError: You cannot call `.save()` after accessing `serializer.data`.If you need to access data before committing to the database then inspect 'serializer.validated_data' instead. 
[13/Mar/2018 17:51:38] DEBUG [/media/thqbop/data/Hoctap/NNLaptrinh/Python/Projects/RiBo-Core/env/lib/python3.5/site-packages/django/db/backends/utils.py:89] (0.000) SET SQL_AUTO_IS_NULL = 0; args=None
[13/Mar/2018 17:53:26] DEBUG [/media/thqbop/data/Hoctap/NNLaptrinh/Python/Projects/RiBo-Core/env/lib/python3.5/site-packages/django/db/backends/utils.py:89] (0.005) SET SQL_AUTO_IS_NULL = 0; args=None
[13/Mar/2018 17:53:29] DEBUG [/media/thqbop/data/Hoctap/NNLaptrinh/Python/Projects/RiBo-Core/env/lib/python3.5/site-packages/django/db/backends/utils.py:89] (0.000) SET SQL_AUTO_IS_NULL = 0; args=None
[13/Mar/2018 17:53:29] DEBUG [/media/thqbop/data/Hoctap/NNLaptrinh/Python/Projects/RiBo-Core/env/lib/python3.5/site-packages/django/db/backends/utils.py:89] (0.046) SHOW FULL TABLES; args=None
[13/Mar/2018 17:53:29] DEBUG [/media/thqbop/data/Hoctap/NNLaptrinh/Python/Projects/RiBo-Core/env/lib/python3.5/site-packages/django/db/backends/utils.py:89] (0.042) SELECT `django_migrations`.`app`, `django_migrations`.`name` FROM `django_migrations`; args=()
[13/Mar/2018 17:53:33] DEBUG [/media/thqbop/data/Hoctap/NNLaptrinh/Python/Projects/RiBo-Core/env/lib/python3.5/site-packages/django/db/backends/utils.py:89] (0.000) SET SQL_AUTO_IS_NULL = 0; args=None
[13/Mar/2018 17:53:34] DEBUG [/media/thqbop/data/Hoctap/NNLaptrinh/Python/Projects/RiBo-Core/env/lib/python3.5/site-packages/django/db/backends/utils.py:89] (0.000) SET SQL_AUTO_IS_NULL = 0; args=None
[13/Mar/2018 17:53:34] DEBUG [/media/thqbop/data/Hoctap/NNLaptrinh/Python/Projects/RiBo-Core/env/lib/python3.5/site-packages/django/db/backends/utils.py:89] (0.001) SHOW FULL TABLES; args=None
[13/Mar/2018 17:53:34] DEBUG [/media/thqbop/data/Hoctap/NNLaptrinh/Python/Projects/RiBo-Core/env/lib/python3.5/site-packages/django/db/backends/utils.py:89] (0.003) SELECT `django_migrations`.`app`, `django_migrations`.`name` FROM `django_migrations`; args=()
[13/Mar/2018 17:54:11] ERROR [/media/thqbop/data/Hoctap/NNLaptrinh/Python/Projects/RiBo-Core/env/lib/python3.5/site-packages/django/core/handlers/base.py:284] Internal Server Error: /api/v1/user
Traceback (most recent call last):
  File "/media/thqbop/data/Hoctap/NNLaptrinh/Python/Projects/RiBo-Core/env/lib/python3.5/site-packages/django/core/handlers/base.py", line 149, in get_response
    response = self.process_exception_by_middleware(e, request)
  File "/media/thqbop/data/Hoctap/NNLaptrinh/Python/Projects/RiBo-Core/env/lib/python3.5/site-packages/django/core/handlers/base.py", line 147, in get_response
    response = wrapped_callback(request, *callback_args, **callback_kwargs)
  File "/media/thqbop/data/Hoctap/NNLaptrinh/Python/Projects/RiBo-Core/env/lib/python3.5/site-packages/django/views/decorators/csrf.py", line 58, in wrapped_view
    return view_func(*args, **kwargs)
  File "/media/thqbop/data/Hoctap/NNLaptrinh/Python/Projects/RiBo-Core/env/lib/python3.5/site-packages/rest_framework/viewsets.py", line 87, in view
    return self.dispatch(request, *args, **kwargs)
  File "/media/thqbop/data/Hoctap/NNLaptrinh/Python/Projects/RiBo-Core/env/lib/python3.5/site-packages/rest_framework/views.py", line 466, in dispatch
    response = self.handle_exception(exc)
  File "/media/thqbop/data/Hoctap/NNLaptrinh/Python/Projects/RiBo-Core/env/lib/python3.5/site-packages/rest_framework/views.py", line 463, in dispatch
    response = handler(request, *args, **kwargs)
  File "/media/thqbop/data/Hoctap/NNLaptrinh/Python/Projects/RiBo-Core/src/ribo_api/views/user.py", line 67, in create
    raise e
  File "/media/thqbop/data/Hoctap/NNLaptrinh/Python/Projects/RiBo-Core/src/ribo_api/views/user.py", line 63, in create
    serializer.save()
  File "/media/thqbop/data/Hoctap/NNLaptrinh/Python/Projects/RiBo-Core/env/lib/python3.5/site-packages/rest_framework/serializers.py", line 175, in save
    "You cannot call `.save()` after accessing `serializer.data`."
AssertionError: You cannot call `.save()` after accessing `serializer.data`.If you need to access data before committing to the database then inspect 'serializer.validated_data' instead. 
[13/Mar/2018 17:54:15] ERROR [/media/thqbop/data/Hoctap/NNLaptrinh/Python/Projects/RiBo-Core/env/lib/python3.5/site-packages/django/core/handlers/base.py:284] Internal Server Error: /api/v1/user
Traceback (most recent call last):
  File "/media/thqbop/data/Hoctap/NNLaptrinh/Python/Projects/RiBo-Core/env/lib/python3.5/site-packages/django/core/handlers/base.py", line 149, in get_response
    response = self.process_exception_by_middleware(e, request)
  File "/media/thqbop/data/Hoctap/NNLaptrinh/Python/Projects/RiBo-Core/env/lib/python3.5/site-packages/django/core/handlers/base.py", line 147, in get_response
    response = wrapped_callback(request, *callback_args, **callback_kwargs)
  File "/media/thqbop/data/Hoctap/NNLaptrinh/Python/Projects/RiBo-Core/env/lib/python3.5/site-packages/django/views/decorators/csrf.py", line 58, in wrapped_view
    return view_func(*args, **kwargs)
  File "/media/thqbop/data/Hoctap/NNLaptrinh/Python/Projects/RiBo-Core/env/lib/python3.5/site-packages/rest_framework/viewsets.py", line 87, in view
    return self.dispatch(request, *args, **kwargs)
  File "/media/thqbop/data/Hoctap/NNLaptrinh/Python/Projects/RiBo-Core/env/lib/python3.5/site-packages/rest_framework/views.py", line 466, in dispatch
    response = self.handle_exception(exc)
  File "/media/thqbop/data/Hoctap/NNLaptrinh/Python/Projects/RiBo-Core/env/lib/python3.5/site-packages/rest_framework/views.py", line 463, in dispatch
    response = handler(request, *args, **kwargs)
  File "/media/thqbop/data/Hoctap/NNLaptrinh/Python/Projects/RiBo-Core/src/ribo_api/views/user.py", line 67, in create
    raise e
  File "/media/thqbop/data/Hoctap/NNLaptrinh/Python/Projects/RiBo-Core/src/ribo_api/views/user.py", line 63, in create
    serializer.save()
  File "/media/thqbop/data/Hoctap/NNLaptrinh/Python/Projects/RiBo-Core/env/lib/python3.5/site-packages/rest_framework/serializers.py", line 191, in save
    self.instance = self.create(validated_data)
  File "/media/thqbop/data/Hoctap/NNLaptrinh/Python/Projects/RiBo-Core/src/ribo_api/serializers/user.py", line 13, in create
    obj = User.objects.create(**validated_data)
  File "/media/thqbop/data/Hoctap/NNLaptrinh/Python/Projects/RiBo-Core/env/lib/python3.5/site-packages/mongoengine/queryset/base.py", line 293, in create
    return self._document(**kwargs).save(force_insert=True)
  File "/media/thqbop/data/Hoctap/NNLaptrinh/Python/Projects/RiBo-Core/env/lib/python3.5/site-packages/mongoengine/document.py", line 355, in save
    self.validate(clean=clean)
  File "/media/thqbop/data/Hoctap/NNLaptrinh/Python/Projects/RiBo-Core/env/lib/python3.5/site-packages/mongoengine/base/document.py", line 395, in validate
    raise ValidationError(message, errors=errors)
mongoengine.errors.ValidationError: ValidationError (User:None) (Field is required: ['email'])
[13/Mar/2018 17:55:04] DEBUG [/media/thqbop/data/Hoctap/NNLaptrinh/Python/Projects/RiBo-Core/env/lib/python3.5/site-packages/django/db/backends/utils.py:89] (0.001) SET SQL_AUTO_IS_NULL = 0; args=None
[13/Mar/2018 17:55:07] DEBUG [/media/thqbop/data/Hoctap/NNLaptrinh/Python/Projects/RiBo-Core/env/lib/python3.5/site-packages/django/db/backends/utils.py:89] (0.000) SET SQL_AUTO_IS_NULL = 0; args=None
[13/Mar/2018 17:55:07] DEBUG [/media/thqbop/data/Hoctap/NNLaptrinh/Python/Projects/RiBo-Core/env/lib/python3.5/site-packages/django/db/backends/utils.py:89] (0.009) SHOW FULL TABLES; args=None
[13/Mar/2018 17:55:07] DEBUG [/media/thqbop/data/Hoctap/NNLaptrinh/Python/Projects/RiBo-Core/env/lib/python3.5/site-packages/django/db/backends/utils.py:89] (0.010) SELECT `django_migrations`.`app`, `django_migrations`.`name` FROM `django_migrations`; args=()
[13/Mar/2018 17:55:21] ERROR [/media/thqbop/data/Hoctap/NNLaptrinh/Python/Projects/RiBo-Core/env/lib/python3.5/site-packages/django/core/handlers/base.py:284] Internal Server Error: /api/v1/user
Traceback (most recent call last):
  File "/media/thqbop/data/Hoctap/NNLaptrinh/Python/Projects/RiBo-Core/env/lib/python3.5/site-packages/django/core/handlers/base.py", line 149, in get_response
    response = self.process_exception_by_middleware(e, request)
  File "/media/thqbop/data/Hoctap/NNLaptrinh/Python/Projects/RiBo-Core/env/lib/python3.5/site-packages/django/core/handlers/base.py", line 147, in get_response
    response = wrapped_callback(request, *callback_args, **callback_kwargs)
  File "/media/thqbop/data/Hoctap/NNLaptrinh/Python/Projects/RiBo-Core/env/lib/python3.5/site-packages/django/views/decorators/csrf.py", line 58, in wrapped_view
    return view_func(*args, **kwargs)
  File "/media/thqbop/data/Hoctap/NNLaptrinh/Python/Projects/RiBo-Core/env/lib/python3.5/site-packages/rest_framework/viewsets.py", line 87, in view
    return self.dispatch(request, *args, **kwargs)
  File "/media/thqbop/data/Hoctap/NNLaptrinh/Python/Projects/RiBo-Core/env/lib/python3.5/site-packages/rest_framework/views.py", line 466, in dispatch
    response = self.handle_exception(exc)
  File "/media/thqbop/data/Hoctap/NNLaptrinh/Python/Projects/RiBo-Core/env/lib/python3.5/site-packages/rest_framework/views.py", line 463, in dispatch
    response = handler(request, *args, **kwargs)
  File "/media/thqbop/data/Hoctap/NNLaptrinh/Python/Projects/RiBo-Core/src/ribo_api/views/user.py", line 67, in create
    raise e
  File "/media/thqbop/data/Hoctap/NNLaptrinh/Python/Projects/RiBo-Core/src/ribo_api/views/user.py", line 63, in create
    serializer.save()
  File "/media/thqbop/data/Hoctap/NNLaptrinh/Python/Projects/RiBo-Core/env/lib/python3.5/site-packages/rest_framework/serializers.py", line 191, in save
    self.instance = self.create(validated_data)
  File "/media/thqbop/data/Hoctap/NNLaptrinh/Python/Projects/RiBo-Core/src/ribo_api/serializers/user.py", line 13, in create
    obj = User.objects.create(**validated_data)
  File "/media/thqbop/data/Hoctap/NNLaptrinh/Python/Projects/RiBo-Core/env/lib/python3.5/site-packages/mongoengine/queryset/base.py", line 293, in create
    return self._document(**kwargs).save(force_insert=True)
  File "/media/thqbop/data/Hoctap/NNLaptrinh/Python/Projects/RiBo-Core/env/lib/python3.5/site-packages/mongoengine/document.py", line 355, in save
    self.validate(clean=clean)
  File "/media/thqbop/data/Hoctap/NNLaptrinh/Python/Projects/RiBo-Core/env/lib/python3.5/site-packages/mongoengine/base/document.py", line 395, in validate
    raise ValidationError(message, errors=errors)
mongoengine.errors.ValidationError: ValidationError (User:None) (Field is required: ['email_address'])
[13/Mar/2018 17:55:42] ERROR [/media/thqbop/data/Hoctap/NNLaptrinh/Python/Projects/RiBo-Core/env/lib/python3.5/site-packages/django/core/handlers/base.py:284] Internal Server Error: /api/v1/user
Traceback (most recent call last):
  File "/media/thqbop/data/Hoctap/NNLaptrinh/Python/Projects/RiBo-Core/env/lib/python3.5/site-packages/django/core/handlers/base.py", line 149, in get_response
    response = self.process_exception_by_middleware(e, request)
  File "/media/thqbop/data/Hoctap/NNLaptrinh/Python/Projects/RiBo-Core/env/lib/python3.5/site-packages/django/core/handlers/base.py", line 147, in get_response
    response = wrapped_callback(request, *callback_args, **callback_kwargs)
  File "/media/thqbop/data/Hoctap/NNLaptrinh/Python/Projects/RiBo-Core/env/lib/python3.5/site-packages/django/views/decorators/csrf.py", line 58, in wrapped_view
    return view_func(*args, **kwargs)
  File "/media/thqbop/data/Hoctap/NNLaptrinh/Python/Projects/RiBo-Core/env/lib/python3.5/site-packages/rest_framework/viewsets.py", line 87, in view
    return self.dispatch(request, *args, **kwargs)
  File "/media/thqbop/data/Hoctap/NNLaptrinh/Python/Projects/RiBo-Core/env/lib/python3.5/site-packages/rest_framework/views.py", line 466, in dispatch
    response = self.handle_exception(exc)
  File "/media/thqbop/data/Hoctap/NNLaptrinh/Python/Projects/RiBo-Core/env/lib/python3.5/site-packages/rest_framework/views.py", line 463, in dispatch
    response = handler(request, *args, **kwargs)
  File "/media/thqbop/data/Hoctap/NNLaptrinh/Python/Projects/RiBo-Core/src/ribo_api/views/user.py", line 67, in create
    raise e
  File "/media/thqbop/data/Hoctap/NNLaptrinh/Python/Projects/RiBo-Core/src/ribo_api/views/user.py", line 63, in create
    serializer.save()
  File "/media/thqbop/data/Hoctap/NNLaptrinh/Python/Projects/RiBo-Core/env/lib/python3.5/site-packages/rest_framework/serializers.py", line 191, in save
    self.instance = self.create(validated_data)
  File "/media/thqbop/data/Hoctap/NNLaptrinh/Python/Projects/RiBo-Core/src/ribo_api/serializers/user.py", line 13, in create
    obj = User.objects.create(**validated_data)
  File "/media/thqbop/data/Hoctap/NNLaptrinh/Python/Projects/RiBo-Core/env/lib/python3.5/site-packages/mongoengine/queryset/base.py", line 293, in create
    return self._document(**kwargs).save(force_insert=True)
  File "/media/thqbop/data/Hoctap/NNLaptrinh/Python/Projects/RiBo-Core/env/lib/python3.5/site-packages/mongoengine/document.py", line 355, in save
    self.validate(clean=clean)
  File "/media/thqbop/data/Hoctap/NNLaptrinh/Python/Projects/RiBo-Core/env/lib/python3.5/site-packages/mongoengine/base/document.py", line 395, in validate
    raise ValidationError(message, errors=errors)
mongoengine.errors.ValidationError: ValidationError (User:None) (Field is required: ['email_address'])
[13/Mar/2018 17:56:06] DEBUG [/media/thqbop/data/Hoctap/NNLaptrinh/Python/Projects/RiBo-Core/env/lib/python3.5/site-packages/django/db/backends/utils.py:89] (0.000) SET SQL_AUTO_IS_NULL = 0; args=None
[13/Mar/2018 17:56:09] DEBUG [/media/thqbop/data/Hoctap/NNLaptrinh/Python/Projects/RiBo-Core/env/lib/python3.5/site-packages/django/db/backends/utils.py:89] (0.000) SET SQL_AUTO_IS_NULL = 0; args=None
[13/Mar/2018 17:56:09] DEBUG [/media/thqbop/data/Hoctap/NNLaptrinh/Python/Projects/RiBo-Core/env/lib/python3.5/site-packages/django/db/backends/utils.py:89] (0.004) SHOW FULL TABLES; args=None
[13/Mar/2018 17:56:09] DEBUG [/media/thqbop/data/Hoctap/NNLaptrinh/Python/Projects/RiBo-Core/env/lib/python3.5/site-packages/django/db/backends/utils.py:89] (0.001) SELECT `django_migrations`.`app`, `django_migrations`.`name` FROM `django_migrations`; args=()
[13/Mar/2018 17:56:29] DEBUG [/media/thqbop/data/Hoctap/NNLaptrinh/Python/Projects/RiBo-Core/env/lib/python3.5/site-packages/django/db/backends/utils.py:89] (0.000) SET SQL_AUTO_IS_NULL = 0; args=None
[13/Mar/2018 17:56:30] DEBUG [/media/thqbop/data/Hoctap/NNLaptrinh/Python/Projects/RiBo-Core/env/lib/python3.5/site-packages/django/db/backends/utils.py:89] (0.000) SET SQL_AUTO_IS_NULL = 0; args=None
[13/Mar/2018 17:56:30] DEBUG [/media/thqbop/data/Hoctap/NNLaptrinh/Python/Projects/RiBo-Core/env/lib/python3.5/site-packages/django/db/backends/utils.py:89] (0.001) SHOW FULL TABLES; args=None
[13/Mar/2018 17:56:30] DEBUG [/media/thqbop/data/Hoctap/NNLaptrinh/Python/Projects/RiBo-Core/env/lib/python3.5/site-packages/django/db/backends/utils.py:89] (0.001) SELECT `django_migrations`.`app`, `django_migrations`.`name` FROM `django_migrations`; args=()
[13/Mar/2018 17:56:34] DEBUG [/media/thqbop/data/Hoctap/NNLaptrinh/Python/Projects/RiBo-Core/env/lib/python3.5/site-packages/django/db/backends/utils.py:89] (0.000) SET SQL_AUTO_IS_NULL = 0; args=None
[13/Mar/2018 17:56:35] DEBUG [/media/thqbop/data/Hoctap/NNLaptrinh/Python/Projects/RiBo-Core/env/lib/python3.5/site-packages/django/db/backends/utils.py:89] (0.000) SET SQL_AUTO_IS_NULL = 0; args=None
[13/Mar/2018 17:56:35] DEBUG [/media/thqbop/data/Hoctap/NNLaptrinh/Python/Projects/RiBo-Core/env/lib/python3.5/site-packages/django/db/backends/utils.py:89] (0.001) SHOW FULL TABLES; args=None
[13/Mar/2018 17:56:35] DEBUG [/media/thqbop/data/Hoctap/NNLaptrinh/Python/Projects/RiBo-Core/env/lib/python3.5/site-packages/django/db/backends/utils.py:89] (0.001) SELECT `django_migrations`.`app`, `django_migrations`.`name` FROM `django_migrations`; args=()
[13/Mar/2018 17:57:47] DEBUG [/media/thqbop/data/Hoctap/NNLaptrinh/Python/Projects/RiBo-Core/env/lib/python3.5/site-packages/django/db/backends/utils.py:89] (0.000) SET SQL_AUTO_IS_NULL = 0; args=None
[13/Mar/2018 17:57:48] DEBUG [/media/thqbop/data/Hoctap/NNLaptrinh/Python/Projects/RiBo-Core/env/lib/python3.5/site-packages/django/db/backends/utils.py:89] (0.000) SET SQL_AUTO_IS_NULL = 0; args=None
[13/Mar/2018 17:57:48] DEBUG [/media/thqbop/data/Hoctap/NNLaptrinh/Python/Projects/RiBo-Core/env/lib/python3.5/site-packages/django/db/backends/utils.py:89] (0.001) SHOW FULL TABLES; args=None
[13/Mar/2018 17:57:48] DEBUG [/media/thqbop/data/Hoctap/NNLaptrinh/Python/Projects/RiBo-Core/env/lib/python3.5/site-packages/django/db/backends/utils.py:89] (0.001) SELECT `django_migrations`.`app`, `django_migrations`.`name` FROM `django_migrations`; args=()
[13/Mar/2018 17:58:47] DEBUG [/media/thqbop/data/Hoctap/NNLaptrinh/Python/Projects/RiBo-Core/env/lib/python3.5/site-packages/django/db/backends/utils.py:89] (0.000) SET SQL_AUTO_IS_NULL = 0; args=None
[13/Mar/2018 17:58:47] DEBUG [/media/thqbop/data/Hoctap/NNLaptrinh/Python/Projects/RiBo-Core/env/lib/python3.5/site-packages/django/db/backends/utils.py:89] (0.000) SET SQL_AUTO_IS_NULL = 0; args=None
[13/Mar/2018 17:58:47] DEBUG [/media/thqbop/data/Hoctap/NNLaptrinh/Python/Projects/RiBo-Core/env/lib/python3.5/site-packages/django/db/backends/utils.py:89] (0.001) SHOW FULL TABLES; args=None
[13/Mar/2018 17:58:47] DEBUG [/media/thqbop/data/Hoctap/NNLaptrinh/Python/Projects/RiBo-Core/env/lib/python3.5/site-packages/django/db/backends/utils.py:89] (0.001) SELECT `django_migrations`.`app`, `django_migrations`.`name` FROM `django_migrations`; args=()
[13/Mar/2018 17:58:53] DEBUG [/media/thqbop/data/Hoctap/NNLaptrinh/Python/Projects/RiBo-Core/env/lib/python3.5/site-packages/django/db/backends/utils.py:89] (0.000) SET SQL_AUTO_IS_NULL = 0; args=None
[13/Mar/2018 17:58:53] DEBUG [/media/thqbop/data/Hoctap/NNLaptrinh/Python/Projects/RiBo-Core/env/lib/python3.5/site-packages/django/db/backends/utils.py:89] (0.000) SET SQL_AUTO_IS_NULL = 0; args=None
[13/Mar/2018 17:58:53] DEBUG [/media/thqbop/data/Hoctap/NNLaptrinh/Python/Projects/RiBo-Core/env/lib/python3.5/site-packages/django/db/backends/utils.py:89] (0.001) SHOW FULL TABLES; args=None
[13/Mar/2018 17:58:53] DEBUG [/media/thqbop/data/Hoctap/NNLaptrinh/Python/Projects/RiBo-Core/env/lib/python3.5/site-packages/django/db/backends/utils.py:89] (0.001) SELECT `django_migrations`.`app`, `django_migrations`.`name` FROM `django_migrations`; args=()
[14/Mar/2018 13:35:34] DEBUG [/media/thqbop/data/Hoctap/NNLaptrinh/Python/Projects/RiBo-Core/env/lib/python3.5/site-packages/django/db/backends/utils.py:89] (0.000) SET SQL_AUTO_IS_NULL = 0; args=None
[14/Mar/2018 13:35:38] DEBUG [/media/thqbop/data/Hoctap/NNLaptrinh/Python/Projects/RiBo-Core/env/lib/python3.5/site-packages/django/db/backends/utils.py:89] (0.001) SET SQL_AUTO_IS_NULL = 0; args=None
[14/Mar/2018 13:35:38] DEBUG [/media/thqbop/data/Hoctap/NNLaptrinh/Python/Projects/RiBo-Core/env/lib/python3.5/site-packages/django/db/backends/utils.py:89] (0.009) SHOW FULL TABLES; args=None
[14/Mar/2018 13:35:38] DEBUG [/media/thqbop/data/Hoctap/NNLaptrinh/Python/Projects/RiBo-Core/env/lib/python3.5/site-packages/django/db/backends/utils.py:89] (0.014) SELECT `django_migrations`.`app`, `django_migrations`.`name` FROM `django_migrations`; args=()
[14/Mar/2018 14:26:20] DEBUG [/media/thqbop/data/Hoctap/NNLaptrinh/Python/Projects/RiBo-Core/env/lib/python3.5/site-packages/django/db/backends/utils.py:89] (0.000) SET SQL_AUTO_IS_NULL = 0; args=None
[14/Mar/2018 14:26:22] DEBUG [/media/thqbop/data/Hoctap/NNLaptrinh/Python/Projects/RiBo-Core/env/lib/python3.5/site-packages/django/db/backends/utils.py:89] (0.000) SET SQL_AUTO_IS_NULL = 0; args=None
[14/Mar/2018 14:26:22] DEBUG [/media/thqbop/data/Hoctap/NNLaptrinh/Python/Projects/RiBo-Core/env/lib/python3.5/site-packages/django/db/backends/utils.py:89] (0.011) SHOW FULL TABLES; args=None
[14/Mar/2018 14:26:22] DEBUG [/media/thqbop/data/Hoctap/NNLaptrinh/Python/Projects/RiBo-Core/env/lib/python3.5/site-packages/django/db/backends/utils.py:89] (0.012) SELECT `django_migrations`.`app`, `django_migrations`.`name` FROM `django_migrations`; args=()
[14/Mar/2018 14:26:45] DEBUG [/media/thqbop/data/Hoctap/NNLaptrinh/Python/Projects/RiBo-Core/env/lib/python3.5/site-packages/django/db/backends/utils.py:89] (0.000) SET SQL_AUTO_IS_NULL = 0; args=None
[14/Mar/2018 14:26:46] DEBUG [/media/thqbop/data/Hoctap/NNLaptrinh/Python/Projects/RiBo-Core/env/lib/python3.5/site-packages/django/db/backends/utils.py:89] (0.000) SET SQL_AUTO_IS_NULL = 0; args=None
[14/Mar/2018 14:26:46] DEBUG [/media/thqbop/data/Hoctap/NNLaptrinh/Python/Projects/RiBo-Core/env/lib/python3.5/site-packages/django/db/backends/utils.py:89] (0.001) SHOW FULL TABLES; args=None
[14/Mar/2018 14:26:46] DEBUG [/media/thqbop/data/Hoctap/NNLaptrinh/Python/Projects/RiBo-Core/env/lib/python3.5/site-packages/django/db/backends/utils.py:89] (0.002) SELECT `django_migrations`.`app`, `django_migrations`.`name` FROM `django_migrations`; args=()
[14/Mar/2018 14:27:09] DEBUG [/media/thqbop/data/Hoctap/NNLaptrinh/Python/Projects/RiBo-Core/env/lib/python3.5/site-packages/django/db/backends/utils.py:89] (0.000) SET SQL_AUTO_IS_NULL = 0; args=None
[14/Mar/2018 14:27:10] DEBUG [/media/thqbop/data/Hoctap/NNLaptrinh/Python/Projects/RiBo-Core/env/lib/python3.5/site-packages/django/db/backends/utils.py:89] (0.000) SET SQL_AUTO_IS_NULL = 0; args=None
[14/Mar/2018 14:27:10] DEBUG [/media/thqbop/data/Hoctap/NNLaptrinh/Python/Projects/RiBo-Core/env/lib/python3.5/site-packages/django/db/backends/utils.py:89] (0.002) SHOW FULL TABLES; args=None
[14/Mar/2018 14:27:10] DEBUG [/media/thqbop/data/Hoctap/NNLaptrinh/Python/Projects/RiBo-Core/env/lib/python3.5/site-packages/django/db/backends/utils.py:89] (0.002) SELECT `django_migrations`.`app`, `django_migrations`.`name` FROM `django_migrations`; args=()
[14/Mar/2018 14:27:59] DEBUG [/media/thqbop/data/Hoctap/NNLaptrinh/Python/Projects/RiBo-Core/env/lib/python3.5/site-packages/django/db/backends/utils.py:89] (0.001) SET SQL_AUTO_IS_NULL = 0; args=None
[14/Mar/2018 14:28:00] DEBUG [/media/thqbop/data/Hoctap/NNLaptrinh/Python/Projects/RiBo-Core/env/lib/python3.5/site-packages/django/db/backends/utils.py:89] (0.000) SET SQL_AUTO_IS_NULL = 0; args=None
[14/Mar/2018 14:28:00] DEBUG [/media/thqbop/data/Hoctap/NNLaptrinh/Python/Projects/RiBo-Core/env/lib/python3.5/site-packages/django/db/backends/utils.py:89] (0.001) SHOW FULL TABLES; args=None
[14/Mar/2018 14:28:00] DEBUG [/media/thqbop/data/Hoctap/NNLaptrinh/Python/Projects/RiBo-Core/env/lib/python3.5/site-packages/django/db/backends/utils.py:89] (0.002) SELECT `django_migrations`.`app`, `django_migrations`.`name` FROM `django_migrations`; args=()
[14/Mar/2018 14:28:26] DEBUG [/media/thqbop/data/Hoctap/NNLaptrinh/Python/Projects/RiBo-Core/env/lib/python3.5/site-packages/django/db/backends/utils.py:89] (0.000) SET SQL_AUTO_IS_NULL = 0; args=None
[14/Mar/2018 14:28:27] DEBUG [/media/thqbop/data/Hoctap/NNLaptrinh/Python/Projects/RiBo-Core/env/lib/python3.5/site-packages/django/db/backends/utils.py:89] (0.000) SET SQL_AUTO_IS_NULL = 0; args=None
[14/Mar/2018 14:28:27] DEBUG [/media/thqbop/data/Hoctap/NNLaptrinh/Python/Projects/RiBo-Core/env/lib/python3.5/site-packages/django/db/backends/utils.py:89] (0.000) SHOW FULL TABLES; args=None
[14/Mar/2018 14:28:27] DEBUG [/media/thqbop/data/Hoctap/NNLaptrinh/Python/Projects/RiBo-Core/env/lib/python3.5/site-packages/django/db/backends/utils.py:89] (0.001) SELECT `django_migrations`.`app`, `django_migrations`.`name` FROM `django_migrations`; args=()
[14/Mar/2018 14:38:22] DEBUG [/media/thqbop/data/Hoctap/NNLaptrinh/Python/Projects/RiBo-Core/env/lib/python3.5/site-packages/django/db/backends/utils.py:89] (0.000) SET SQL_AUTO_IS_NULL = 0; args=None
[14/Mar/2018 14:39:00] DEBUG [/media/thqbop/data/Hoctap/NNLaptrinh/Python/Projects/RiBo-Core/env/lib/python3.5/site-packages/django/db/backends/utils.py:89] (0.000) SET SQL_AUTO_IS_NULL = 0; args=None
[14/Mar/2018 14:39:26] DEBUG [/media/thqbop/data/Hoctap/NNLaptrinh/Python/Projects/RiBo-Core/env/lib/python3.5/site-packages/django/db/backends/utils.py:89] (0.000) SET SQL_AUTO_IS_NULL = 0; args=None
[14/Mar/2018 14:39:27] DEBUG [/media/thqbop/data/Hoctap/NNLaptrinh/Python/Projects/RiBo-Core/env/lib/python3.5/site-packages/django/db/backends/utils.py:89] (0.001) SET SQL_AUTO_IS_NULL = 0; args=None
[14/Mar/2018 14:39:27] DEBUG [/media/thqbop/data/Hoctap/NNLaptrinh/Python/Projects/RiBo-Core/env/lib/python3.5/site-packages/django/db/backends/utils.py:89] (0.008) SHOW FULL TABLES; args=None
[14/Mar/2018 14:39:27] DEBUG [/media/thqbop/data/Hoctap/NNLaptrinh/Python/Projects/RiBo-Core/env/lib/python3.5/site-packages/django/db/backends/utils.py:89] (0.009) SELECT `django_migrations`.`app`, `django_migrations`.`name` FROM `django_migrations`; args=()
[14/Mar/2018 14:42:04] DEBUG [/media/thqbop/data/Hoctap/NNLaptrinh/Python/Projects/RiBo-Core/env/lib/python3.5/site-packages/django/db/backends/utils.py:89] (0.000) SET SQL_AUTO_IS_NULL = 0; args=None
[14/Mar/2018 14:42:05] DEBUG [/media/thqbop/data/Hoctap/NNLaptrinh/Python/Projects/RiBo-Core/env/lib/python3.5/site-packages/django/db/backends/utils.py:89] (0.000) SET SQL_AUTO_IS_NULL = 0; args=None
[14/Mar/2018 14:42:05] DEBUG [/media/thqbop/data/Hoctap/NNLaptrinh/Python/Projects/RiBo-Core/env/lib/python3.5/site-packages/django/db/backends/utils.py:89] (0.004) SHOW FULL TABLES; args=None
[14/Mar/2018 14:42:05] DEBUG [/media/thqbop/data/Hoctap/NNLaptrinh/Python/Projects/RiBo-Core/env/lib/python3.5/site-packages/django/db/backends/utils.py:89] (0.002) SELECT `django_migrations`.`app`, `django_migrations`.`name` FROM `django_migrations`; args=()
[14/Mar/2018 14:43:48] DEBUG [/media/thqbop/data/Hoctap/NNLaptrinh/Python/Projects/RiBo-Core/env/lib/python3.5/site-packages/django/db/backends/utils.py:89] (0.000) SET SQL_AUTO_IS_NULL = 0; args=None
[14/Mar/2018 14:43:48] DEBUG [/media/thqbop/data/Hoctap/NNLaptrinh/Python/Projects/RiBo-Core/env/lib/python3.5/site-packages/django/db/backends/utils.py:89] (0.001) SET SQL_AUTO_IS_NULL = 0; args=None
[14/Mar/2018 14:43:48] DEBUG [/media/thqbop/data/Hoctap/NNLaptrinh/Python/Projects/RiBo-Core/env/lib/python3.5/site-packages/django/db/backends/utils.py:89] (0.001) SHOW FULL TABLES; args=None
[14/Mar/2018 14:43:48] DEBUG [/media/thqbop/data/Hoctap/NNLaptrinh/Python/Projects/RiBo-Core/env/lib/python3.5/site-packages/django/db/backends/utils.py:89] (0.000) SELECT `django_migrations`.`app`, `django_migrations`.`name` FROM `django_migrations`; args=()
[14/Mar/2018 14:44:19] DEBUG [/media/thqbop/data/Hoctap/NNLaptrinh/Python/Projects/RiBo-Core/env/lib/python3.5/site-packages/django/db/backends/utils.py:89] (0.000) SET SQL_AUTO_IS_NULL = 0; args=None
[14/Mar/2018 14:44:19] DEBUG [/media/thqbop/data/Hoctap/NNLaptrinh/Python/Projects/RiBo-Core/env/lib/python3.5/site-packages/django/db/backends/utils.py:89] (0.000) SET SQL_AUTO_IS_NULL = 0; args=None
[14/Mar/2018 14:44:19] DEBUG [/media/thqbop/data/Hoctap/NNLaptrinh/Python/Projects/RiBo-Core/env/lib/python3.5/site-packages/django/db/backends/utils.py:89] (0.001) SHOW FULL TABLES; args=None
[14/Mar/2018 14:44:19] DEBUG [/media/thqbop/data/Hoctap/NNLaptrinh/Python/Projects/RiBo-Core/env/lib/python3.5/site-packages/django/db/backends/utils.py:89] (0.001) SELECT `django_migrations`.`app`, `django_migrations`.`name` FROM `django_migrations`; args=()
[14/Mar/2018 14:47:42] ERROR [/media/thqbop/data/Hoctap/NNLaptrinh/Python/Projects/RiBo-Core/env/lib/python3.5/site-packages/django/core/handlers/base.py:284] Internal Server Error: /api/v1/task
Traceback (most recent call last):
  File "/media/thqbop/data/Hoctap/NNLaptrinh/Python/Projects/RiBo-Core/env/lib/python3.5/site-packages/mongoengine/base/fields.py", line 466, in to_mongo
    return ObjectId(six.text_type(value))
  File "/media/thqbop/data/Hoctap/NNLaptrinh/Python/Projects/RiBo-Core/env/lib/python3.5/site-packages/bson/objectid.py", line 110, in __init__
    self.__validate(oid)
  File "/media/thqbop/data/Hoctap/NNLaptrinh/Python/Projects/RiBo-Core/env/lib/python3.5/site-packages/bson/objectid.py", line 206, in __validate
    _raise_invalid_id(oid)
  File "/media/thqbop/data/Hoctap/NNLaptrinh/Python/Projects/RiBo-Core/env/lib/python3.5/site-packages/bson/objectid.py", line 52, in _raise_invalid_id
    " or a 24-character hex string" % oid)
bson.errors.InvalidId: '' is not a valid ObjectId, it must be a 12-byte input or a 24-character hex string

During handling of the above exception, another exception occurred:

Traceback (most recent call last):
  File "/media/thqbop/data/Hoctap/NNLaptrinh/Python/Projects/RiBo-Core/env/lib/python3.5/site-packages/django/core/handlers/base.py", line 149, in get_response
    response = self.process_exception_by_middleware(e, request)
  File "/media/thqbop/data/Hoctap/NNLaptrinh/Python/Projects/RiBo-Core/env/lib/python3.5/site-packages/django/core/handlers/base.py", line 147, in get_response
    response = wrapped_callback(request, *callback_args, **callback_kwargs)
  File "/media/thqbop/data/Hoctap/NNLaptrinh/Python/Projects/RiBo-Core/env/lib/python3.5/site-packages/django/views/decorators/csrf.py", line 58, in wrapped_view
    return view_func(*args, **kwargs)
  File "/media/thqbop/data/Hoctap/NNLaptrinh/Python/Projects/RiBo-Core/env/lib/python3.5/site-packages/rest_framework/viewsets.py", line 87, in view
    return self.dispatch(request, *args, **kwargs)
  File "/media/thqbop/data/Hoctap/NNLaptrinh/Python/Projects/RiBo-Core/env/lib/python3.5/site-packages/rest_framework/views.py", line 466, in dispatch
    response = self.handle_exception(exc)
  File "/media/thqbop/data/Hoctap/NNLaptrinh/Python/Projects/RiBo-Core/env/lib/python3.5/site-packages/rest_framework/views.py", line 463, in dispatch
    response = handler(request, *args, **kwargs)
  File "/media/thqbop/data/Hoctap/NNLaptrinh/Python/Projects/RiBo-Core/src/ribo_api/views/api/task.py", line 61, in list
    raise e
  File "/media/thqbop/data/Hoctap/NNLaptrinh/Python/Projects/RiBo-Core/src/ribo_api/views/api/task.py", line 58, in list
    return Response(serializer.data)
  File "/media/thqbop/data/Hoctap/NNLaptrinh/Python/Projects/RiBo-Core/env/lib/python3.5/site-packages/rest_framework/serializers.py", line 674, in data
    ret = super(ListSerializer, self).data
  File "/media/thqbop/data/Hoctap/NNLaptrinh/Python/Projects/RiBo-Core/env/lib/python3.5/site-packages/rest_framework/serializers.py", line 239, in data
    self._data = self.to_representation(self.instance)
  File "/media/thqbop/data/Hoctap/NNLaptrinh/Python/Projects/RiBo-Core/env/lib/python3.5/site-packages/rest_framework/serializers.py", line 614, in to_representation
    self.child.to_representation(item) for item in iterable
  File "/media/thqbop/data/Hoctap/NNLaptrinh/Python/Projects/RiBo-Core/env/lib/python3.5/site-packages/rest_framework/serializers.py", line 614, in <listcomp>
    self.child.to_representation(item) for item in iterable
  File "/media/thqbop/data/Hoctap/NNLaptrinh/Python/Projects/RiBo-Core/env/lib/python3.5/site-packages/mongoengine/queryset/queryset.py", line 99, in _iter_results
    self._populate_cache()
  File "/media/thqbop/data/Hoctap/NNLaptrinh/Python/Projects/RiBo-Core/env/lib/python3.5/site-packages/mongoengine/queryset/queryset.py", line 118, in _populate_cache
    self._result_cache.append(next(self))
  File "/media/thqbop/data/Hoctap/NNLaptrinh/Python/Projects/RiBo-Core/env/lib/python3.5/site-packages/mongoengine/queryset/base.py", line 1466, in __next__
    raw_doc = next(self._cursor)
  File "/media/thqbop/data/Hoctap/NNLaptrinh/Python/Projects/RiBo-Core/env/lib/python3.5/site-packages/mongoengine/queryset/base.py", line 1547, in _cursor
    self._cursor_obj = self._collection.find(self._query,
  File "/media/thqbop/data/Hoctap/NNLaptrinh/Python/Projects/RiBo-Core/env/lib/python3.5/site-packages/mongoengine/queryset/base.py", line 1590, in _query
    self._mongo_query = self._query_obj.to_query(self._document)
  File "/media/thqbop/data/Hoctap/NNLaptrinh/Python/Projects/RiBo-Core/env/lib/python3.5/site-packages/mongoengine/queryset/visitor.py", line 89, in to_query
    query = query.accept(QueryCompilerVisitor(document))
  File "/media/thqbop/data/Hoctap/NNLaptrinh/Python/Projects/RiBo-Core/env/lib/python3.5/site-packages/mongoengine/queryset/visitor.py", line 155, in accept
    return visitor.visit_query(self)
  File "/media/thqbop/data/Hoctap/NNLaptrinh/Python/Projects/RiBo-Core/env/lib/python3.5/site-packages/mongoengine/queryset/visitor.py", line 78, in visit_query
    return transform.query(self.document, **query.query)
  File "/media/thqbop/data/Hoctap/NNLaptrinh/Python/Projects/RiBo-Core/env/lib/python3.5/site-packages/mongoengine/queryset/transform.py", line 98, in query
    value = field.prepare_query_value(op, value)
  File "/media/thqbop/data/Hoctap/NNLaptrinh/Python/Projects/RiBo-Core/env/lib/python3.5/site-packages/mongoengine/base/fields.py", line 473, in prepare_query_value
    return self.to_mongo(value)
  File "/media/thqbop/data/Hoctap/NNLaptrinh/Python/Projects/RiBo-Core/env/lib/python3.5/site-packages/mongoengine/base/fields.py", line 469, in to_mongo
    self.error(six.text_type(e))
  File "/media/thqbop/data/Hoctap/NNLaptrinh/Python/Projects/RiBo-Core/env/lib/python3.5/site-packages/mongoengine/base/fields.py", line 167, in error
    raise ValidationError(message, errors=errors, field_name=field_name)
mongoengine.errors.ValidationError: '' is not a valid ObjectId, it must be a 12-byte input or a 24-character hex string
[14/Mar/2018 14:48:11] ERROR [/media/thqbop/data/Hoctap/NNLaptrinh/Python/Projects/RiBo-Core/env/lib/python3.5/site-packages/django/core/handlers/base.py:284] Internal Server Error: /api/v1/task
Traceback (most recent call last):
  File "/media/thqbop/data/Hoctap/NNLaptrinh/Python/Projects/RiBo-Core/env/lib/python3.5/site-packages/mongoengine/base/fields.py", line 466, in to_mongo
    return ObjectId(six.text_type(value))
  File "/media/thqbop/data/Hoctap/NNLaptrinh/Python/Projects/RiBo-Core/env/lib/python3.5/site-packages/bson/objectid.py", line 110, in __init__
    self.__validate(oid)
  File "/media/thqbop/data/Hoctap/NNLaptrinh/Python/Projects/RiBo-Core/env/lib/python3.5/site-packages/bson/objectid.py", line 206, in __validate
    _raise_invalid_id(oid)
  File "/media/thqbop/data/Hoctap/NNLaptrinh/Python/Projects/RiBo-Core/env/lib/python3.5/site-packages/bson/objectid.py", line 52, in _raise_invalid_id
    " or a 24-character hex string" % oid)
bson.errors.InvalidId: '' is not a valid ObjectId, it must be a 12-byte input or a 24-character hex string

During handling of the above exception, another exception occurred:

Traceback (most recent call last):
  File "/media/thqbop/data/Hoctap/NNLaptrinh/Python/Projects/RiBo-Core/env/lib/python3.5/site-packages/django/core/handlers/base.py", line 149, in get_response
    response = self.process_exception_by_middleware(e, request)
  File "/media/thqbop/data/Hoctap/NNLaptrinh/Python/Projects/RiBo-Core/env/lib/python3.5/site-packages/django/core/handlers/base.py", line 147, in get_response
    response = wrapped_callback(request, *callback_args, **callback_kwargs)
  File "/media/thqbop/data/Hoctap/NNLaptrinh/Python/Projects/RiBo-Core/env/lib/python3.5/site-packages/django/views/decorators/csrf.py", line 58, in wrapped_view
    return view_func(*args, **kwargs)
  File "/media/thqbop/data/Hoctap/NNLaptrinh/Python/Projects/RiBo-Core/env/lib/python3.5/site-packages/rest_framework/viewsets.py", line 87, in view
    return self.dispatch(request, *args, **kwargs)
  File "/media/thqbop/data/Hoctap/NNLaptrinh/Python/Projects/RiBo-Core/env/lib/python3.5/site-packages/rest_framework/views.py", line 466, in dispatch
    response = self.handle_exception(exc)
  File "/media/thqbop/data/Hoctap/NNLaptrinh/Python/Projects/RiBo-Core/env/lib/python3.5/site-packages/rest_framework/views.py", line 463, in dispatch
    response = handler(request, *args, **kwargs)
  File "/media/thqbop/data/Hoctap/NNLaptrinh/Python/Projects/RiBo-Core/src/ribo_api/views/api/task.py", line 61, in list
    raise e
  File "/media/thqbop/data/Hoctap/NNLaptrinh/Python/Projects/RiBo-Core/src/ribo_api/views/api/task.py", line 58, in list
    return Response(serializer.data)
  File "/media/thqbop/data/Hoctap/NNLaptrinh/Python/Projects/RiBo-Core/env/lib/python3.5/site-packages/rest_framework/serializers.py", line 674, in data
    ret = super(ListSerializer, self).data
  File "/media/thqbop/data/Hoctap/NNLaptrinh/Python/Projects/RiBo-Core/env/lib/python3.5/site-packages/rest_framework/serializers.py", line 239, in data
    self._data = self.to_representation(self.instance)
  File "/media/thqbop/data/Hoctap/NNLaptrinh/Python/Projects/RiBo-Core/env/lib/python3.5/site-packages/rest_framework/serializers.py", line 614, in to_representation
    self.child.to_representation(item) for item in iterable
  File "/media/thqbop/data/Hoctap/NNLaptrinh/Python/Projects/RiBo-Core/env/lib/python3.5/site-packages/rest_framework/serializers.py", line 614, in <listcomp>
    self.child.to_representation(item) for item in iterable
  File "/media/thqbop/data/Hoctap/NNLaptrinh/Python/Projects/RiBo-Core/env/lib/python3.5/site-packages/mongoengine/queryset/queryset.py", line 99, in _iter_results
    self._populate_cache()
  File "/media/thqbop/data/Hoctap/NNLaptrinh/Python/Projects/RiBo-Core/env/lib/python3.5/site-packages/mongoengine/queryset/queryset.py", line 118, in _populate_cache
    self._result_cache.append(next(self))
  File "/media/thqbop/data/Hoctap/NNLaptrinh/Python/Projects/RiBo-Core/env/lib/python3.5/site-packages/mongoengine/queryset/base.py", line 1466, in __next__
    raw_doc = next(self._cursor)
  File "/media/thqbop/data/Hoctap/NNLaptrinh/Python/Projects/RiBo-Core/env/lib/python3.5/site-packages/mongoengine/queryset/base.py", line 1547, in _cursor
    self._cursor_obj = self._collection.find(self._query,
  File "/media/thqbop/data/Hoctap/NNLaptrinh/Python/Projects/RiBo-Core/env/lib/python3.5/site-packages/mongoengine/queryset/base.py", line 1590, in _query
    self._mongo_query = self._query_obj.to_query(self._document)
  File "/media/thqbop/data/Hoctap/NNLaptrinh/Python/Projects/RiBo-Core/env/lib/python3.5/site-packages/mongoengine/queryset/visitor.py", line 89, in to_query
    query = query.accept(QueryCompilerVisitor(document))
  File "/media/thqbop/data/Hoctap/NNLaptrinh/Python/Projects/RiBo-Core/env/lib/python3.5/site-packages/mongoengine/queryset/visitor.py", line 155, in accept
    return visitor.visit_query(self)
  File "/media/thqbop/data/Hoctap/NNLaptrinh/Python/Projects/RiBo-Core/env/lib/python3.5/site-packages/mongoengine/queryset/visitor.py", line 78, in visit_query
    return transform.query(self.document, **query.query)
  File "/media/thqbop/data/Hoctap/NNLaptrinh/Python/Projects/RiBo-Core/env/lib/python3.5/site-packages/mongoengine/queryset/transform.py", line 98, in query
    value = field.prepare_query_value(op, value)
  File "/media/thqbop/data/Hoctap/NNLaptrinh/Python/Projects/RiBo-Core/env/lib/python3.5/site-packages/mongoengine/base/fields.py", line 473, in prepare_query_value
    return self.to_mongo(value)
  File "/media/thqbop/data/Hoctap/NNLaptrinh/Python/Projects/RiBo-Core/env/lib/python3.5/site-packages/mongoengine/base/fields.py", line 469, in to_mongo
    self.error(six.text_type(e))
  File "/media/thqbop/data/Hoctap/NNLaptrinh/Python/Projects/RiBo-Core/env/lib/python3.5/site-packages/mongoengine/base/fields.py", line 167, in error
    raise ValidationError(message, errors=errors, field_name=field_name)
mongoengine.errors.ValidationError: '' is not a valid ObjectId, it must be a 12-byte input or a 24-character hex string
[14/Mar/2018 14:48:41] DEBUG [/media/thqbop/data/Hoctap/NNLaptrinh/Python/Projects/RiBo-Core/env/lib/python3.5/site-packages/django/db/backends/utils.py:89] (0.000) SET SQL_AUTO_IS_NULL = 0; args=None
[14/Mar/2018 14:48:43] DEBUG [/media/thqbop/data/Hoctap/NNLaptrinh/Python/Projects/RiBo-Core/env/lib/python3.5/site-packages/django/db/backends/utils.py:89] (0.000) SET SQL_AUTO_IS_NULL = 0; args=None
[14/Mar/2018 14:48:43] DEBUG [/media/thqbop/data/Hoctap/NNLaptrinh/Python/Projects/RiBo-Core/env/lib/python3.5/site-packages/django/db/backends/utils.py:89] (0.006) SHOW FULL TABLES; args=None
[14/Mar/2018 14:48:43] DEBUG [/media/thqbop/data/Hoctap/NNLaptrinh/Python/Projects/RiBo-Core/env/lib/python3.5/site-packages/django/db/backends/utils.py:89] (0.007) SELECT `django_migrations`.`app`, `django_migrations`.`name` FROM `django_migrations`; args=()
[14/Mar/2018 14:54:38] ERROR [/media/thqbop/data/Hoctap/NNLaptrinh/Python/Projects/RiBo-Core/env/lib/python3.5/site-packages/django/core/handlers/base.py:284] Internal Server Error: /api/v1/task
Traceback (most recent call last):
  File "/media/thqbop/data/Hoctap/NNLaptrinh/Python/Projects/RiBo-Core/env/lib/python3.5/site-packages/mongoengine/base/fields.py", line 466, in to_mongo
    return ObjectId(six.text_type(value))
  File "/media/thqbop/data/Hoctap/NNLaptrinh/Python/Projects/RiBo-Core/env/lib/python3.5/site-packages/bson/objectid.py", line 110, in __init__
    self.__validate(oid)
  File "/media/thqbop/data/Hoctap/NNLaptrinh/Python/Projects/RiBo-Core/env/lib/python3.5/site-packages/bson/objectid.py", line 206, in __validate
    _raise_invalid_id(oid)
  File "/media/thqbop/data/Hoctap/NNLaptrinh/Python/Projects/RiBo-Core/env/lib/python3.5/site-packages/bson/objectid.py", line 52, in _raise_invalid_id
    " or a 24-character hex string" % oid)
bson.errors.InvalidId: '' is not a valid ObjectId, it must be a 12-byte input or a 24-character hex string

During handling of the above exception, another exception occurred:

Traceback (most recent call last):
  File "/media/thqbop/data/Hoctap/NNLaptrinh/Python/Projects/RiBo-Core/env/lib/python3.5/site-packages/django/core/handlers/base.py", line 149, in get_response
    response = self.process_exception_by_middleware(e, request)
  File "/media/thqbop/data/Hoctap/NNLaptrinh/Python/Projects/RiBo-Core/env/lib/python3.5/site-packages/django/core/handlers/base.py", line 147, in get_response
    response = wrapped_callback(request, *callback_args, **callback_kwargs)
  File "/media/thqbop/data/Hoctap/NNLaptrinh/Python/Projects/RiBo-Core/env/lib/python3.5/site-packages/django/views/decorators/csrf.py", line 58, in wrapped_view
    return view_func(*args, **kwargs)
  File "/media/thqbop/data/Hoctap/NNLaptrinh/Python/Projects/RiBo-Core/env/lib/python3.5/site-packages/rest_framework/viewsets.py", line 87, in view
    return self.dispatch(request, *args, **kwargs)
  File "/media/thqbop/data/Hoctap/NNLaptrinh/Python/Projects/RiBo-Core/env/lib/python3.5/site-packages/rest_framework/views.py", line 466, in dispatch
    response = self.handle_exception(exc)
  File "/media/thqbop/data/Hoctap/NNLaptrinh/Python/Projects/RiBo-Core/env/lib/python3.5/site-packages/rest_framework/views.py", line 463, in dispatch
    response = handler(request, *args, **kwargs)
  File "/media/thqbop/data/Hoctap/NNLaptrinh/Python/Projects/RiBo-Core/src/ribo_api/views/api/task.py", line 60, in list
    raise e
  File "/media/thqbop/data/Hoctap/NNLaptrinh/Python/Projects/RiBo-Core/src/ribo_api/views/api/task.py", line 57, in list
    return Response(serializer.data)
  File "/media/thqbop/data/Hoctap/NNLaptrinh/Python/Projects/RiBo-Core/env/lib/python3.5/site-packages/rest_framework/serializers.py", line 674, in data
    ret = super(ListSerializer, self).data
  File "/media/thqbop/data/Hoctap/NNLaptrinh/Python/Projects/RiBo-Core/env/lib/python3.5/site-packages/rest_framework/serializers.py", line 239, in data
    self._data = self.to_representation(self.instance)
  File "/media/thqbop/data/Hoctap/NNLaptrinh/Python/Projects/RiBo-Core/env/lib/python3.5/site-packages/rest_framework/serializers.py", line 614, in to_representation
    self.child.to_representation(item) for item in iterable
  File "/media/thqbop/data/Hoctap/NNLaptrinh/Python/Projects/RiBo-Core/env/lib/python3.5/site-packages/rest_framework/serializers.py", line 614, in <listcomp>
    self.child.to_representation(item) for item in iterable
  File "/media/thqbop/data/Hoctap/NNLaptrinh/Python/Projects/RiBo-Core/env/lib/python3.5/site-packages/mongoengine/queryset/queryset.py", line 99, in _iter_results
    self._populate_cache()
  File "/media/thqbop/data/Hoctap/NNLaptrinh/Python/Projects/RiBo-Core/env/lib/python3.5/site-packages/mongoengine/queryset/queryset.py", line 118, in _populate_cache
    self._result_cache.append(next(self))
  File "/media/thqbop/data/Hoctap/NNLaptrinh/Python/Projects/RiBo-Core/env/lib/python3.5/site-packages/mongoengine/queryset/base.py", line 1466, in __next__
    raw_doc = next(self._cursor)
  File "/media/thqbop/data/Hoctap/NNLaptrinh/Python/Projects/RiBo-Core/env/lib/python3.5/site-packages/mongoengine/queryset/base.py", line 1547, in _cursor
    self._cursor_obj = self._collection.find(self._query,
  File "/media/thqbop/data/Hoctap/NNLaptrinh/Python/Projects/RiBo-Core/env/lib/python3.5/site-packages/mongoengine/queryset/base.py", line 1590, in _query
    self._mongo_query = self._query_obj.to_query(self._document)
  File "/media/thqbop/data/Hoctap/NNLaptrinh/Python/Projects/RiBo-Core/env/lib/python3.5/site-packages/mongoengine/queryset/visitor.py", line 89, in to_query
    query = query.accept(QueryCompilerVisitor(document))
  File "/media/thqbop/data/Hoctap/NNLaptrinh/Python/Projects/RiBo-Core/env/lib/python3.5/site-packages/mongoengine/queryset/visitor.py", line 155, in accept
    return visitor.visit_query(self)
  File "/media/thqbop/data/Hoctap/NNLaptrinh/Python/Projects/RiBo-Core/env/lib/python3.5/site-packages/mongoengine/queryset/visitor.py", line 78, in visit_query
    return transform.query(self.document, **query.query)
  File "/media/thqbop/data/Hoctap/NNLaptrinh/Python/Projects/RiBo-Core/env/lib/python3.5/site-packages/mongoengine/queryset/transform.py", line 98, in query
    value = field.prepare_query_value(op, value)
  File "/media/thqbop/data/Hoctap/NNLaptrinh/Python/Projects/RiBo-Core/env/lib/python3.5/site-packages/mongoengine/base/fields.py", line 473, in prepare_query_value
    return self.to_mongo(value)
  File "/media/thqbop/data/Hoctap/NNLaptrinh/Python/Projects/RiBo-Core/env/lib/python3.5/site-packages/mongoengine/base/fields.py", line 469, in to_mongo
    self.error(six.text_type(e))
  File "/media/thqbop/data/Hoctap/NNLaptrinh/Python/Projects/RiBo-Core/env/lib/python3.5/site-packages/mongoengine/base/fields.py", line 167, in error
    raise ValidationError(message, errors=errors, field_name=field_name)
mongoengine.errors.ValidationError: '' is not a valid ObjectId, it must be a 12-byte input or a 24-character hex string
[14/Mar/2018 14:56:20] ERROR [/media/thqbop/data/Hoctap/NNLaptrinh/Python/Projects/RiBo-Core/env/lib/python3.5/site-packages/django/core/handlers/base.py:284] Internal Server Error: /api/v1/task
Traceback (most recent call last):
  File "/media/thqbop/data/Hoctap/NNLaptrinh/Python/Projects/RiBo-Core/env/lib/python3.5/site-packages/django/core/handlers/base.py", line 149, in get_response
    response = self.process_exception_by_middleware(e, request)
  File "/media/thqbop/data/Hoctap/NNLaptrinh/Python/Projects/RiBo-Core/env/lib/python3.5/site-packages/django/core/handlers/base.py", line 147, in get_response
    response = wrapped_callback(request, *callback_args, **callback_kwargs)
  File "/media/thqbop/data/Hoctap/NNLaptrinh/Python/Projects/RiBo-Core/env/lib/python3.5/site-packages/django/views/decorators/csrf.py", line 58, in wrapped_view
    return view_func(*args, **kwargs)
  File "/media/thqbop/data/Hoctap/NNLaptrinh/Python/Projects/RiBo-Core/env/lib/python3.5/site-packages/rest_framework/viewsets.py", line 87, in view
    return self.dispatch(request, *args, **kwargs)
  File "/media/thqbop/data/Hoctap/NNLaptrinh/Python/Projects/RiBo-Core/env/lib/python3.5/site-packages/rest_framework/views.py", line 466, in dispatch
    response = self.handle_exception(exc)
  File "/media/thqbop/data/Hoctap/NNLaptrinh/Python/Projects/RiBo-Core/env/lib/python3.5/site-packages/rest_framework/views.py", line 463, in dispatch
    response = handler(request, *args, **kwargs)
  File "/media/thqbop/data/Hoctap/NNLaptrinh/Python/Projects/RiBo-Core/src/ribo_api/views/api/task.py", line 208, in delete
    raise e
  File "/media/thqbop/data/Hoctap/NNLaptrinh/Python/Projects/RiBo-Core/src/ribo_api/views/api/task.py", line 203, in delete
    task = Task.objects(id = data.get('id', None))[0]
  File "/media/thqbop/data/Hoctap/NNLaptrinh/Python/Projects/RiBo-Core/env/lib/python3.5/site-packages/mongoengine/queryset/base.py", line 197, in __getitem__
    queryset._cursor[key],
  File "/media/thqbop/data/Hoctap/NNLaptrinh/Python/Projects/RiBo-Core/env/lib/python3.5/site-packages/pymongo/cursor.py", line 613, in __getitem__
    raise IndexError("no such item for Cursor instance")
IndexError: no such item for Cursor instance
[14/Mar/2018 14:57:17] DEBUG [/media/thqbop/data/Hoctap/NNLaptrinh/Python/Projects/RiBo-Core/env/lib/python3.5/site-packages/django/db/backends/utils.py:89] (0.000) SET SQL_AUTO_IS_NULL = 0; args=None
[14/Mar/2018 14:57:19] DEBUG [/media/thqbop/data/Hoctap/NNLaptrinh/Python/Projects/RiBo-Core/env/lib/python3.5/site-packages/django/db/backends/utils.py:89] (0.000) SET SQL_AUTO_IS_NULL = 0; args=None
[14/Mar/2018 14:57:19] DEBUG [/media/thqbop/data/Hoctap/NNLaptrinh/Python/Projects/RiBo-Core/env/lib/python3.5/site-packages/django/db/backends/utils.py:89] (0.006) SHOW FULL TABLES; args=None
[14/Mar/2018 14:57:19] DEBUG [/media/thqbop/data/Hoctap/NNLaptrinh/Python/Projects/RiBo-Core/env/lib/python3.5/site-packages/django/db/backends/utils.py:89] (0.006) SELECT `django_migrations`.`app`, `django_migrations`.`name` FROM `django_migrations`; args=()
[14/Mar/2018 14:57:35] ERROR [/media/thqbop/data/Hoctap/NNLaptrinh/Python/Projects/RiBo-Core/env/lib/python3.5/site-packages/django/core/handlers/base.py:284] Internal Server Error: /api/v1/task
Traceback (most recent call last):
  File "/media/thqbop/data/Hoctap/NNLaptrinh/Python/Projects/RiBo-Core/env/lib/python3.5/site-packages/django/core/handlers/base.py", line 149, in get_response
    response = self.process_exception_by_middleware(e, request)
  File "/media/thqbop/data/Hoctap/NNLaptrinh/Python/Projects/RiBo-Core/env/lib/python3.5/site-packages/django/core/handlers/base.py", line 147, in get_response
    response = wrapped_callback(request, *callback_args, **callback_kwargs)
  File "/media/thqbop/data/Hoctap/NNLaptrinh/Python/Projects/RiBo-Core/env/lib/python3.5/site-packages/django/views/decorators/csrf.py", line 58, in wrapped_view
    return view_func(*args, **kwargs)
  File "/media/thqbop/data/Hoctap/NNLaptrinh/Python/Projects/RiBo-Core/env/lib/python3.5/site-packages/rest_framework/viewsets.py", line 87, in view
    return self.dispatch(request, *args, **kwargs)
  File "/media/thqbop/data/Hoctap/NNLaptrinh/Python/Projects/RiBo-Core/env/lib/python3.5/site-packages/rest_framework/views.py", line 466, in dispatch
    response = self.handle_exception(exc)
  File "/media/thqbop/data/Hoctap/NNLaptrinh/Python/Projects/RiBo-Core/env/lib/python3.5/site-packages/rest_framework/views.py", line 463, in dispatch
    response = handler(request, *args, **kwargs)
  File "/media/thqbop/data/Hoctap/NNLaptrinh/Python/Projects/RiBo-Core/src/ribo_api/views/api/task.py", line 209, in delete
    raise e
  File "/media/thqbop/data/Hoctap/NNLaptrinh/Python/Projects/RiBo-Core/src/ribo_api/views/api/task.py", line 204, in delete
    task = Task.objects(id = pk)[0]
  File "/media/thqbop/data/Hoctap/NNLaptrinh/Python/Projects/RiBo-Core/env/lib/python3.5/site-packages/mongoengine/queryset/base.py", line 197, in __getitem__
    queryset._cursor[key],
  File "/media/thqbop/data/Hoctap/NNLaptrinh/Python/Projects/RiBo-Core/env/lib/python3.5/site-packages/pymongo/cursor.py", line 613, in __getitem__
    raise IndexError("no such item for Cursor instance")
IndexError: no such item for Cursor instance
[14/Mar/2018 14:59:20] DEBUG [/media/thqbop/data/Hoctap/NNLaptrinh/Python/Projects/RiBo-Core/env/lib/python3.5/site-packages/django/db/backends/utils.py:89] (0.000) SET SQL_AUTO_IS_NULL = 0; args=None
[14/Mar/2018 14:59:22] DEBUG [/media/thqbop/data/Hoctap/NNLaptrinh/Python/Projects/RiBo-Core/env/lib/python3.5/site-packages/django/db/backends/utils.py:89] (0.000) SET SQL_AUTO_IS_NULL = 0; args=None
[14/Mar/2018 14:59:22] DEBUG [/media/thqbop/data/Hoctap/NNLaptrinh/Python/Projects/RiBo-Core/env/lib/python3.5/site-packages/django/db/backends/utils.py:89] (0.003) SHOW FULL TABLES; args=None
[14/Mar/2018 14:59:22] DEBUG [/media/thqbop/data/Hoctap/NNLaptrinh/Python/Projects/RiBo-Core/env/lib/python3.5/site-packages/django/db/backends/utils.py:89] (0.001) SELECT `django_migrations`.`app`, `django_migrations`.`name` FROM `django_migrations`; args=()
[14/Mar/2018 14:59:36] DEBUG [/media/thqbop/data/Hoctap/NNLaptrinh/Python/Projects/RiBo-Core/env/lib/python3.5/site-packages/django/db/backends/utils.py:89] (0.000) SET SQL_AUTO_IS_NULL = 0; args=None
[14/Mar/2018 15:01:59] DEBUG [/media/thqbop/data/Hoctap/NNLaptrinh/Python/Projects/RiBo-Core/env/lib/python3.5/site-packages/django/db/backends/utils.py:89] (0.000) SET SQL_AUTO_IS_NULL = 0; args=None
[14/Mar/2018 15:02:09] DEBUG [/media/thqbop/data/Hoctap/NNLaptrinh/Python/Projects/RiBo-Core/env/lib/python3.5/site-packages/django/db/backends/utils.py:89] (0.000) SET SQL_AUTO_IS_NULL = 0; args=None
[14/Mar/2018 15:02:09] DEBUG [/media/thqbop/data/Hoctap/NNLaptrinh/Python/Projects/RiBo-Core/env/lib/python3.5/site-packages/django/db/backends/utils.py:89] (0.000) SET SQL_AUTO_IS_NULL = 0; args=None
[14/Mar/2018 15:02:09] DEBUG [/media/thqbop/data/Hoctap/NNLaptrinh/Python/Projects/RiBo-Core/env/lib/python3.5/site-packages/django/db/backends/utils.py:89] (0.001) SHOW FULL TABLES; args=None
[14/Mar/2018 15:02:09] DEBUG [/media/thqbop/data/Hoctap/NNLaptrinh/Python/Projects/RiBo-Core/env/lib/python3.5/site-packages/django/db/backends/utils.py:89] (0.000) SELECT `django_migrations`.`app`, `django_migrations`.`name` FROM `django_migrations`; args=()
[14/Mar/2018 15:02:42] ERROR [/media/thqbop/data/Hoctap/NNLaptrinh/Python/Projects/RiBo-Core/env/lib/python3.5/site-packages/django/core/handlers/base.py:284] Internal Server Error: /api/v1/task
Traceback (most recent call last):
  File "/media/thqbop/data/Hoctap/NNLaptrinh/Python/Projects/RiBo-Core/env/lib/python3.5/site-packages/django/core/handlers/base.py", line 149, in get_response
    response = self.process_exception_by_middleware(e, request)
  File "/media/thqbop/data/Hoctap/NNLaptrinh/Python/Projects/RiBo-Core/env/lib/python3.5/site-packages/django/core/handlers/base.py", line 147, in get_response
    response = wrapped_callback(request, *callback_args, **callback_kwargs)
  File "/media/thqbop/data/Hoctap/NNLaptrinh/Python/Projects/RiBo-Core/env/lib/python3.5/site-packages/django/views/decorators/csrf.py", line 58, in wrapped_view
    return view_func(*args, **kwargs)
  File "/media/thqbop/data/Hoctap/NNLaptrinh/Python/Projects/RiBo-Core/env/lib/python3.5/site-packages/rest_framework/viewsets.py", line 87, in view
    return self.dispatch(request, *args, **kwargs)
  File "/media/thqbop/data/Hoctap/NNLaptrinh/Python/Projects/RiBo-Core/env/lib/python3.5/site-packages/rest_framework/views.py", line 466, in dispatch
    response = self.handle_exception(exc)
  File "/media/thqbop/data/Hoctap/NNLaptrinh/Python/Projects/RiBo-Core/env/lib/python3.5/site-packages/rest_framework/views.py", line 463, in dispatch
    response = handler(request, *args, **kwargs)
  File "/media/thqbop/data/Hoctap/NNLaptrinh/Python/Projects/RiBo-Core/src/ribo_api/views/api/task.py", line 209, in delete
    raise e
  File "/media/thqbop/data/Hoctap/NNLaptrinh/Python/Projects/RiBo-Core/src/ribo_api/views/api/task.py", line 204, in delete
    task = Task.objects(id = pk)[0]
  File "/media/thqbop/data/Hoctap/NNLaptrinh/Python/Projects/RiBo-Core/env/lib/python3.5/site-packages/mongoengine/queryset/base.py", line 197, in __getitem__
    queryset._cursor[key],
  File "/media/thqbop/data/Hoctap/NNLaptrinh/Python/Projects/RiBo-Core/env/lib/python3.5/site-packages/pymongo/cursor.py", line 613, in __getitem__
    raise IndexError("no such item for Cursor instance")
IndexError: no such item for Cursor instance
[14/Mar/2018 15:02:49] DEBUG [/media/thqbop/data/Hoctap/NNLaptrinh/Python/Projects/RiBo-Core/env/lib/python3.5/site-packages/django/db/backends/utils.py:89] (0.000) SET SQL_AUTO_IS_NULL = 0; args=None
[14/Mar/2018 15:02:49] DEBUG [/media/thqbop/data/Hoctap/NNLaptrinh/Python/Projects/RiBo-Core/env/lib/python3.5/site-packages/django/db/backends/utils.py:89] (0.000) SET SQL_AUTO_IS_NULL = 0; args=None
[14/Mar/2018 15:02:49] DEBUG [/media/thqbop/data/Hoctap/NNLaptrinh/Python/Projects/RiBo-Core/env/lib/python3.5/site-packages/django/db/backends/utils.py:89] (0.001) SHOW FULL TABLES; args=None
[14/Mar/2018 15:02:49] DEBUG [/media/thqbop/data/Hoctap/NNLaptrinh/Python/Projects/RiBo-Core/env/lib/python3.5/site-packages/django/db/backends/utils.py:89] (0.001) SELECT `django_migrations`.`app`, `django_migrations`.`name` FROM `django_migrations`; args=()
[14/Mar/2018 15:03:34] DEBUG [/media/thqbop/data/Hoctap/NNLaptrinh/Python/Projects/RiBo-Core/env/lib/python3.5/site-packages/django/db/backends/utils.py:89] (0.000) SET SQL_AUTO_IS_NULL = 0; args=None
[14/Mar/2018 15:04:56] DEBUG [/media/thqbop/data/Hoctap/NNLaptrinh/Python/Projects/RiBo-Core/env/lib/python3.5/site-packages/django/db/backends/utils.py:89] (0.000) SET SQL_AUTO_IS_NULL = 0; args=None
[14/Mar/2018 15:04:57] DEBUG [/media/thqbop/data/Hoctap/NNLaptrinh/Python/Projects/RiBo-Core/env/lib/python3.5/site-packages/django/db/backends/utils.py:89] (0.000) SET SQL_AUTO_IS_NULL = 0; args=None
[14/Mar/2018 15:04:57] DEBUG [/media/thqbop/data/Hoctap/NNLaptrinh/Python/Projects/RiBo-Core/env/lib/python3.5/site-packages/django/db/backends/utils.py:89] (0.005) SHOW FULL TABLES; args=None
[14/Mar/2018 15:04:57] DEBUG [/media/thqbop/data/Hoctap/NNLaptrinh/Python/Projects/RiBo-Core/env/lib/python3.5/site-packages/django/db/backends/utils.py:89] (0.008) SELECT `django_migrations`.`app`, `django_migrations`.`name` FROM `django_migrations`; args=()
[14/Mar/2018 15:05:09] DEBUG [/media/thqbop/data/Hoctap/NNLaptrinh/Python/Projects/RiBo-Core/env/lib/python3.5/site-packages/django/db/backends/utils.py:89] (0.000) SET SQL_AUTO_IS_NULL = 0; args=None
[14/Mar/2018 15:05:10] DEBUG [/media/thqbop/data/Hoctap/NNLaptrinh/Python/Projects/RiBo-Core/env/lib/python3.5/site-packages/django/db/backends/utils.py:89] (0.000) SET SQL_AUTO_IS_NULL = 0; args=None
[14/Mar/2018 15:05:10] DEBUG [/media/thqbop/data/Hoctap/NNLaptrinh/Python/Projects/RiBo-Core/env/lib/python3.5/site-packages/django/db/backends/utils.py:89] (0.001) SHOW FULL TABLES; args=None
[14/Mar/2018 15:05:10] DEBUG [/media/thqbop/data/Hoctap/NNLaptrinh/Python/Projects/RiBo-Core/env/lib/python3.5/site-packages/django/db/backends/utils.py:89] (0.001) SELECT `django_migrations`.`app`, `django_migrations`.`name` FROM `django_migrations`; args=()
[14/Mar/2018 15:05:37] DEBUG [/media/thqbop/data/Hoctap/NNLaptrinh/Python/Projects/RiBo-Core/env/lib/python3.5/site-packages/django/db/backends/utils.py:89] (0.000) SET SQL_AUTO_IS_NULL = 0; args=None
[14/Mar/2018 15:05:38] DEBUG [/media/thqbop/data/Hoctap/NNLaptrinh/Python/Projects/RiBo-Core/env/lib/python3.5/site-packages/django/db/backends/utils.py:89] (0.000) SET SQL_AUTO_IS_NULL = 0; args=None
[14/Mar/2018 15:05:38] DEBUG [/media/thqbop/data/Hoctap/NNLaptrinh/Python/Projects/RiBo-Core/env/lib/python3.5/site-packages/django/db/backends/utils.py:89] (0.001) SHOW FULL TABLES; args=None
[14/Mar/2018 15:05:38] DEBUG [/media/thqbop/data/Hoctap/NNLaptrinh/Python/Projects/RiBo-Core/env/lib/python3.5/site-packages/django/db/backends/utils.py:89] (0.002) SELECT `django_migrations`.`app`, `django_migrations`.`name` FROM `django_migrations`; args=()
[15/Mar/2018 03:00:51] DEBUG [/home/thqbop/workspace/Ribo/RiBo-Core/env/lib/python3.5/site-packages/django/db/backends/utils.py:89] (0.000) SET SQL_AUTO_IS_NULL = 0; args=None
[15/Mar/2018 03:00:52] DEBUG [/home/thqbop/workspace/Ribo/RiBo-Core/env/lib/python3.5/site-packages/django/db/backends/utils.py:89] (0.000) SET SQL_AUTO_IS_NULL = 0; args=None
[15/Mar/2018 03:00:52] DEBUG [/home/thqbop/workspace/Ribo/RiBo-Core/env/lib/python3.5/site-packages/django/db/backends/utils.py:89] (0.002) SHOW FULL TABLES; args=None
[15/Mar/2018 03:00:52] DEBUG [/home/thqbop/workspace/Ribo/RiBo-Core/env/lib/python3.5/site-packages/django/db/backends/utils.py:89] (0.002) SELECT `django_migrations`.`app`, `django_migrations`.`name` FROM `django_migrations`; args=()
[15/Mar/2018 04:38:25] DEBUG [/home/thqbop/workspace/Ribo/RiBo-Core/env/lib/python3.5/site-packages/django/db/backends/utils.py:89] (0.000) SET SQL_AUTO_IS_NULL = 0; args=None
[15/Mar/2018 04:38:26] DEBUG [/home/thqbop/workspace/Ribo/RiBo-Core/env/lib/python3.5/site-packages/django/db/backends/utils.py:89] (0.000) SET SQL_AUTO_IS_NULL = 0; args=None
[15/Mar/2018 04:38:26] DEBUG [/home/thqbop/workspace/Ribo/RiBo-Core/env/lib/python3.5/site-packages/django/db/backends/utils.py:89] (0.001) SHOW FULL TABLES; args=None
[15/Mar/2018 04:38:26] DEBUG [/home/thqbop/workspace/Ribo/RiBo-Core/env/lib/python3.5/site-packages/django/db/backends/utils.py:89] (0.000) SELECT `django_migrations`.`app`, `django_migrations`.`name` FROM `django_migrations`; args=()
[15/Mar/2018 05:04:16] DEBUG [/home/thqbop/workspace/Ribo/RiBo-Core/env/lib/python3.5/site-packages/django/db/backends/utils.py:89] (0.000) SET SQL_AUTO_IS_NULL = 0; args=None
[15/Mar/2018 05:04:16] DEBUG [/home/thqbop/workspace/Ribo/RiBo-Core/env/lib/python3.5/site-packages/django/db/backends/utils.py:89] (0.000) SET SQL_AUTO_IS_NULL = 0; args=None
[15/Mar/2018 05:04:16] DEBUG [/home/thqbop/workspace/Ribo/RiBo-Core/env/lib/python3.5/site-packages/django/db/backends/utils.py:89] (0.000) SHOW FULL TABLES; args=None
[15/Mar/2018 05:04:16] DEBUG [/home/thqbop/workspace/Ribo/RiBo-Core/env/lib/python3.5/site-packages/django/db/backends/utils.py:89] (0.000) SELECT `django_migrations`.`app`, `django_migrations`.`name` FROM `django_migrations`; args=()
[15/Mar/2018 05:04:25] DEBUG [/home/thqbop/workspace/Ribo/RiBo-Core/env/lib/python3.5/site-packages/django/db/backends/utils.py:89] (0.000) SET SQL_AUTO_IS_NULL = 0; args=None
[15/Mar/2018 05:04:25] DEBUG [/home/thqbop/workspace/Ribo/RiBo-Core/env/lib/python3.5/site-packages/django/db/backends/utils.py:89] (0.000) SET SQL_AUTO_IS_NULL = 0; args=None
[15/Mar/2018 05:04:25] DEBUG [/home/thqbop/workspace/Ribo/RiBo-Core/env/lib/python3.5/site-packages/django/db/backends/utils.py:89] (0.000) SHOW FULL TABLES; args=None
[15/Mar/2018 05:04:25] DEBUG [/home/thqbop/workspace/Ribo/RiBo-Core/env/lib/python3.5/site-packages/django/db/backends/utils.py:89] (0.000) SELECT `django_migrations`.`app`, `django_migrations`.`name` FROM `django_migrations`; args=()
