[13/Mar/2018 16:26:22] ERROR [/media/thqbop/data/Hoctap/NNLaptrinh/Python/Projects/RiBo-Core/src/ribo_api/services/utils.py:189] {'birthday': ['Datetime has wrong format. Use one of these formats instead: YYYY-MM-DDThh:mm[:ss[.uuuuuu]][+HH:MM|-HH:MM|Z].'], 'expire_time': ['Datetime has wrong format. Use one of these formats instead: YYYY-MM-DDThh:mm[:ss[.uuuuuu]][+HH:MM|-HH:MM|Z].']}
Traceback (most recent call last):
  File "/media/thqbop/data/Hoctap/NNLaptrinh/Python/Projects/RiBo-Core/src/ribo_api/views/user.py", line 62, in create
    serializer.is_valid(raise_exception=True)
  File "/media/thqbop/data/Hoctap/NNLaptrinh/Python/Projects/RiBo-Core/env/lib/python3.5/site-packages/rest_framework/serializers.py", line 221, in is_valid
    raise ValidationError(self.errors)
rest_framework.exceptions.ValidationError: {'birthday': ['Datetime has wrong format. Use one of these formats instead: YYYY-MM-DDThh:mm[:ss[.uuuuuu]][+HH:MM|-HH:MM|Z].'], 'expire_time': ['Datetime has wrong format. Use one of these formats instead: YYYY-MM-DDThh:mm[:ss[.uuuuuu]][+HH:MM|-HH:MM|Z].']}
[13/Mar/2018 16:28:11] ERROR [/media/thqbop/data/Hoctap/NNLaptrinh/Python/Projects/RiBo-Core/src/ribo_api/services/utils.py:189] {'birthday': ['Datetime has wrong format. Use one of these formats instead: YYYY-MM-DDThh:mm[:ss[.uuuuuu]][+HH:MM|-HH:MM|Z].'], 'expire_time': ['Datetime has wrong format. Use one of these formats instead: YYYY-MM-DDThh:mm[:ss[.uuuuuu]][+HH:MM|-HH:MM|Z].']}
Traceback (most recent call last):
  File "/media/thqbop/data/Hoctap/NNLaptrinh/Python/Projects/RiBo-Core/src/ribo_api/views/user.py", line 62, in create
    serializer.is_valid(raise_exception=True)
  File "/media/thqbop/data/Hoctap/NNLaptrinh/Python/Projects/RiBo-Core/env/lib/python3.5/site-packages/rest_framework/serializers.py", line 221, in is_valid
    raise ValidationError(self.errors)
rest_framework.exceptions.ValidationError: {'birthday': ['Datetime has wrong format. Use one of these formats instead: YYYY-MM-DDThh:mm[:ss[.uuuuuu]][+HH:MM|-HH:MM|Z].'], 'expire_time': ['Datetime has wrong format. Use one of these formats instead: YYYY-MM-DDThh:mm[:ss[.uuuuuu]][+HH:MM|-HH:MM|Z].']}
[13/Mar/2018 16:28:37] ERROR [/media/thqbop/data/Hoctap/NNLaptrinh/Python/Projects/RiBo-Core/src/ribo_api/services/utils.py:189] {'birthday': ['Datetime has wrong format. Use one of these formats instead: YYYY-MM-DDThh:mm[:ss[.uuuuuu]][+HH:MM|-HH:MM|Z].'], 'expire_time': ['Datetime has wrong format. Use one of these formats instead: YYYY-MM-DDThh:mm[:ss[.uuuuuu]][+HH:MM|-HH:MM|Z].']}
Traceback (most recent call last):
  File "/media/thqbop/data/Hoctap/NNLaptrinh/Python/Projects/RiBo-Core/src/ribo_api/views/user.py", line 62, in create
    serializer.is_valid(raise_exception=True)
  File "/media/thqbop/data/Hoctap/NNLaptrinh/Python/Projects/RiBo-Core/env/lib/python3.5/site-packages/rest_framework/serializers.py", line 221, in is_valid
    raise ValidationError(self.errors)
rest_framework.exceptions.ValidationError: {'birthday': ['Datetime has wrong format. Use one of these formats instead: YYYY-MM-DDThh:mm[:ss[.uuuuuu]][+HH:MM|-HH:MM|Z].'], 'expire_time': ['Datetime has wrong format. Use one of these formats instead: YYYY-MM-DDThh:mm[:ss[.uuuuuu]][+HH:MM|-HH:MM|Z].']}
[13/Mar/2018 16:28:44] ERROR [/media/thqbop/data/Hoctap/NNLaptrinh/Python/Projects/RiBo-Core/src/ribo_api/services/utils.py:189] {'birthday': ['Datetime has wrong format. Use one of these formats instead: YYYY-MM-DDThh:mm[:ss[.uuuuuu]][+HH:MM|-HH:MM|Z].'], 'expire_time': ['Datetime has wrong format. Use one of these formats instead: YYYY-MM-DDThh:mm[:ss[.uuuuuu]][+HH:MM|-HH:MM|Z].']}
Traceback (most recent call last):
  File "/media/thqbop/data/Hoctap/NNLaptrinh/Python/Projects/RiBo-Core/src/ribo_api/views/user.py", line 62, in create
    serializer.is_valid(raise_exception=True)
  File "/media/thqbop/data/Hoctap/NNLaptrinh/Python/Projects/RiBo-Core/env/lib/python3.5/site-packages/rest_framework/serializers.py", line 221, in is_valid
    raise ValidationError(self.errors)
rest_framework.exceptions.ValidationError: {'birthday': ['Datetime has wrong format. Use one of these formats instead: YYYY-MM-DDThh:mm[:ss[.uuuuuu]][+HH:MM|-HH:MM|Z].'], 'expire_time': ['Datetime has wrong format. Use one of these formats instead: YYYY-MM-DDThh:mm[:ss[.uuuuuu]][+HH:MM|-HH:MM|Z].']}
[13/Mar/2018 16:35:20] ERROR [/media/thqbop/data/Hoctap/NNLaptrinh/Python/Projects/RiBo-Core/src/ribo_api/services/utils.py:189] Got a `ValidationError` when calling `User.objects.create()`. This may be because request data satisfies serializer validations but not Mongoengine`s. You may need to check consistency between User and UserSerializer.
If that is not the case, please open a ticket regarding this issue on https://github.com/umutbozkurt/django-rest-framework-mongoengine/issues
Original exception was: ValidationError (User:None) (Field is required: ['email'])
Traceback (most recent call last):
  File "/media/thqbop/data/Hoctap/NNLaptrinh/Python/Projects/RiBo-Core/env/lib/python3.5/site-packages/rest_framework_mongoengine/serializers.py", line 151, in create
    instance = self.recursive_save(validated_data)
  File "/media/thqbop/data/Hoctap/NNLaptrinh/Python/Projects/RiBo-Core/env/lib/python3.5/site-packages/rest_framework_mongoengine/serializers.py", line 262, in recursive_save
    instance.save()
  File "/media/thqbop/data/Hoctap/NNLaptrinh/Python/Projects/RiBo-Core/env/lib/python3.5/site-packages/mongoengine/document.py", line 355, in save
    self.validate(clean=clean)
  File "/media/thqbop/data/Hoctap/NNLaptrinh/Python/Projects/RiBo-Core/env/lib/python3.5/site-packages/mongoengine/base/document.py", line 395, in validate
    raise ValidationError(message, errors=errors)
mongoengine.errors.ValidationError: ValidationError (User:None) (Field is required: ['email'])

During handling of the above exception, another exception occurred:

Traceback (most recent call last):
  File "/media/thqbop/data/Hoctap/NNLaptrinh/Python/Projects/RiBo-Core/src/ribo_api/views/user.py", line 63, in create
    serializer.save()
  File "/media/thqbop/data/Hoctap/NNLaptrinh/Python/Projects/RiBo-Core/env/lib/python3.5/site-packages/rest_framework/serializers.py", line 191, in save
    self.instance = self.create(validated_data)
  File "/media/thqbop/data/Hoctap/NNLaptrinh/Python/Projects/RiBo-Core/env/lib/python3.5/site-packages/rest_framework_mongoengine/serializers.py", line 183, in create
    raise me_ValidationError(msg)
mongoengine.errors.ValidationError: Got a `ValidationError` when calling `User.objects.create()`. This may be because request data satisfies serializer validations but not Mongoengine`s. You may need to check consistency between User and UserSerializer.
If that is not the case, please open a ticket regarding this issue on https://github.com/umutbozkurt/django-rest-framework-mongoengine/issues
Original exception was: ValidationError (User:None) (Field is required: ['email'])
[13/Mar/2018 16:35:54] ERROR [/media/thqbop/data/Hoctap/NNLaptrinh/Python/Projects/RiBo-Core/src/ribo_api/services/utils.py:189] Got a `ValidationError` when calling `User.objects.create()`. This may be because request data satisfies serializer validations but not Mongoengine`s. You may need to check consistency between User and UserSerializer.
If that is not the case, please open a ticket regarding this issue on https://github.com/umutbozkurt/django-rest-framework-mongoengine/issues
Original exception was: ValidationError (User:None) (Field is required: ['email'])
Traceback (most recent call last):
  File "/media/thqbop/data/Hoctap/NNLaptrinh/Python/Projects/RiBo-Core/env/lib/python3.5/site-packages/rest_framework_mongoengine/serializers.py", line 151, in create
    instance = self.recursive_save(validated_data)
  File "/media/thqbop/data/Hoctap/NNLaptrinh/Python/Projects/RiBo-Core/env/lib/python3.5/site-packages/rest_framework_mongoengine/serializers.py", line 262, in recursive_save
    instance.save()
  File "/media/thqbop/data/Hoctap/NNLaptrinh/Python/Projects/RiBo-Core/env/lib/python3.5/site-packages/mongoengine/document.py", line 355, in save
    self.validate(clean=clean)
  File "/media/thqbop/data/Hoctap/NNLaptrinh/Python/Projects/RiBo-Core/env/lib/python3.5/site-packages/mongoengine/base/document.py", line 395, in validate
    raise ValidationError(message, errors=errors)
mongoengine.errors.ValidationError: ValidationError (User:None) (Field is required: ['email'])

During handling of the above exception, another exception occurred:

Traceback (most recent call last):
  File "/media/thqbop/data/Hoctap/NNLaptrinh/Python/Projects/RiBo-Core/src/ribo_api/views/user.py", line 63, in create
    serializer.save()
  File "/media/thqbop/data/Hoctap/NNLaptrinh/Python/Projects/RiBo-Core/env/lib/python3.5/site-packages/rest_framework/serializers.py", line 191, in save
    self.instance = self.create(validated_data)
  File "/media/thqbop/data/Hoctap/NNLaptrinh/Python/Projects/RiBo-Core/env/lib/python3.5/site-packages/rest_framework_mongoengine/serializers.py", line 183, in create
    raise me_ValidationError(msg)
mongoengine.errors.ValidationError: Got a `ValidationError` when calling `User.objects.create()`. This may be because request data satisfies serializer validations but not Mongoengine`s. You may need to check consistency between User and UserSerializer.
If that is not the case, please open a ticket regarding this issue on https://github.com/umutbozkurt/django-rest-framework-mongoengine/issues
Original exception was: ValidationError (User:None) (Field is required: ['email'])
[13/Mar/2018 16:37:01] ERROR [/media/thqbop/data/Hoctap/NNLaptrinh/Python/Projects/RiBo-Core/src/ribo_api/services/utils.py:189] Got a `ValidationError` when calling `User.objects.create()`. This may be because request data satisfies serializer validations but not Mongoengine`s. You may need to check consistency between User and UserSerializer.
If that is not the case, please open a ticket regarding this issue on https://github.com/umutbozkurt/django-rest-framework-mongoengine/issues
Original exception was: ValidationError (User:None) (Field is required: ['email'])
Traceback (most recent call last):
  File "/media/thqbop/data/Hoctap/NNLaptrinh/Python/Projects/RiBo-Core/env/lib/python3.5/site-packages/rest_framework_mongoengine/serializers.py", line 151, in create
    instance = self.recursive_save(validated_data)
  File "/media/thqbop/data/Hoctap/NNLaptrinh/Python/Projects/RiBo-Core/env/lib/python3.5/site-packages/rest_framework_mongoengine/serializers.py", line 262, in recursive_save
    instance.save()
  File "/media/thqbop/data/Hoctap/NNLaptrinh/Python/Projects/RiBo-Core/env/lib/python3.5/site-packages/mongoengine/document.py", line 355, in save
    self.validate(clean=clean)
  File "/media/thqbop/data/Hoctap/NNLaptrinh/Python/Projects/RiBo-Core/env/lib/python3.5/site-packages/mongoengine/base/document.py", line 395, in validate
    raise ValidationError(message, errors=errors)
mongoengine.errors.ValidationError: ValidationError (User:None) (Field is required: ['email'])

During handling of the above exception, another exception occurred:

Traceback (most recent call last):
  File "/media/thqbop/data/Hoctap/NNLaptrinh/Python/Projects/RiBo-Core/src/ribo_api/views/user.py", line 63, in create
    serializer.save()
  File "/media/thqbop/data/Hoctap/NNLaptrinh/Python/Projects/RiBo-Core/env/lib/python3.5/site-packages/rest_framework/serializers.py", line 191, in save
    self.instance = self.create(validated_data)
  File "/media/thqbop/data/Hoctap/NNLaptrinh/Python/Projects/RiBo-Core/env/lib/python3.5/site-packages/rest_framework_mongoengine/serializers.py", line 183, in create
    raise me_ValidationError(msg)
mongoengine.errors.ValidationError: Got a `ValidationError` when calling `User.objects.create()`. This may be because request data satisfies serializer validations but not Mongoengine`s. You may need to check consistency between User and UserSerializer.
If that is not the case, please open a ticket regarding this issue on https://github.com/umutbozkurt/django-rest-framework-mongoengine/issues
Original exception was: ValidationError (User:None) (Field is required: ['email'])
[13/Mar/2018 16:38:07] ERROR [/media/thqbop/data/Hoctap/NNLaptrinh/Python/Projects/RiBo-Core/src/ribo_api/services/utils.py:189] Got a `ValidationError` when calling `User.objects.create()`. This may be because request data satisfies serializer validations but not Mongoengine`s. You may need to check consistency between User and UserSerializer.
If that is not the case, please open a ticket regarding this issue on https://github.com/umutbozkurt/django-rest-framework-mongoengine/issues
Original exception was: ValidationError (User:None) (Field is required: ['email'])
Traceback (most recent call last):
  File "/media/thqbop/data/Hoctap/NNLaptrinh/Python/Projects/RiBo-Core/env/lib/python3.5/site-packages/rest_framework_mongoengine/serializers.py", line 151, in create
    instance = self.recursive_save(validated_data)
  File "/media/thqbop/data/Hoctap/NNLaptrinh/Python/Projects/RiBo-Core/env/lib/python3.5/site-packages/rest_framework_mongoengine/serializers.py", line 262, in recursive_save
    instance.save()
  File "/media/thqbop/data/Hoctap/NNLaptrinh/Python/Projects/RiBo-Core/env/lib/python3.5/site-packages/mongoengine/document.py", line 355, in save
    self.validate(clean=clean)
  File "/media/thqbop/data/Hoctap/NNLaptrinh/Python/Projects/RiBo-Core/env/lib/python3.5/site-packages/mongoengine/base/document.py", line 395, in validate
    raise ValidationError(message, errors=errors)
mongoengine.errors.ValidationError: ValidationError (User:None) (Field is required: ['email'])

During handling of the above exception, another exception occurred:

Traceback (most recent call last):
  File "/media/thqbop/data/Hoctap/NNLaptrinh/Python/Projects/RiBo-Core/src/ribo_api/views/user.py", line 63, in create
    serializer.save()
  File "/media/thqbop/data/Hoctap/NNLaptrinh/Python/Projects/RiBo-Core/env/lib/python3.5/site-packages/rest_framework/serializers.py", line 191, in save
    self.instance = self.create(validated_data)
  File "/media/thqbop/data/Hoctap/NNLaptrinh/Python/Projects/RiBo-Core/env/lib/python3.5/site-packages/rest_framework_mongoengine/serializers.py", line 183, in create
    raise me_ValidationError(msg)
mongoengine.errors.ValidationError: Got a `ValidationError` when calling `User.objects.create()`. This may be because request data satisfies serializer validations but not Mongoengine`s. You may need to check consistency between User and UserSerializer.
If that is not the case, please open a ticket regarding this issue on https://github.com/umutbozkurt/django-rest-framework-mongoengine/issues
Original exception was: ValidationError (User:None) (Field is required: ['email'])
[13/Mar/2018 16:38:51] ERROR [/media/thqbop/data/Hoctap/NNLaptrinh/Python/Projects/RiBo-Core/src/ribo_api/services/utils.py:189] Got a `ValidationError` when calling `User.objects.create()`. This may be because request data satisfies serializer validations but not Mongoengine`s. You may need to check consistency between User and UserSerializer.
If that is not the case, please open a ticket regarding this issue on https://github.com/umutbozkurt/django-rest-framework-mongoengine/issues
Original exception was: ValidationError (User:None) (Field is required: ['email_address'])
Traceback (most recent call last):
  File "/media/thqbop/data/Hoctap/NNLaptrinh/Python/Projects/RiBo-Core/env/lib/python3.5/site-packages/rest_framework_mongoengine/serializers.py", line 151, in create
    instance = self.recursive_save(validated_data)
  File "/media/thqbop/data/Hoctap/NNLaptrinh/Python/Projects/RiBo-Core/env/lib/python3.5/site-packages/rest_framework_mongoengine/serializers.py", line 262, in recursive_save
    instance.save()
  File "/media/thqbop/data/Hoctap/NNLaptrinh/Python/Projects/RiBo-Core/env/lib/python3.5/site-packages/mongoengine/document.py", line 355, in save
    self.validate(clean=clean)
  File "/media/thqbop/data/Hoctap/NNLaptrinh/Python/Projects/RiBo-Core/env/lib/python3.5/site-packages/mongoengine/base/document.py", line 395, in validate
    raise ValidationError(message, errors=errors)
mongoengine.errors.ValidationError: ValidationError (User:None) (Field is required: ['email_address'])

During handling of the above exception, another exception occurred:

Traceback (most recent call last):
  File "/media/thqbop/data/Hoctap/NNLaptrinh/Python/Projects/RiBo-Core/src/ribo_api/views/user.py", line 63, in create
    serializer.save()
  File "/media/thqbop/data/Hoctap/NNLaptrinh/Python/Projects/RiBo-Core/env/lib/python3.5/site-packages/rest_framework/serializers.py", line 191, in save
    self.instance = self.create(validated_data)
  File "/media/thqbop/data/Hoctap/NNLaptrinh/Python/Projects/RiBo-Core/env/lib/python3.5/site-packages/rest_framework_mongoengine/serializers.py", line 183, in create
    raise me_ValidationError(msg)
mongoengine.errors.ValidationError: Got a `ValidationError` when calling `User.objects.create()`. This may be because request data satisfies serializer validations but not Mongoengine`s. You may need to check consistency between User and UserSerializer.
If that is not the case, please open a ticket regarding this issue on https://github.com/umutbozkurt/django-rest-framework-mongoengine/issues
Original exception was: ValidationError (User:None) (Field is required: ['email_address'])
[13/Mar/2018 16:40:06] ERROR [/media/thqbop/data/Hoctap/NNLaptrinh/Python/Projects/RiBo-Core/src/ribo_api/services/utils.py:189] Got a `ValidationError` when calling `User.objects.create()`. This may be because request data satisfies serializer validations but not Mongoengine`s. You may need to check consistency between User and UserSerializer.
If that is not the case, please open a ticket regarding this issue on https://github.com/umutbozkurt/django-rest-framework-mongoengine/issues
Original exception was: ValidationError (User:None) (Field is required: ['email_address'])
Traceback (most recent call last):
  File "/media/thqbop/data/Hoctap/NNLaptrinh/Python/Projects/RiBo-Core/env/lib/python3.5/site-packages/rest_framework_mongoengine/serializers.py", line 151, in create
    instance = self.recursive_save(validated_data)
  File "/media/thqbop/data/Hoctap/NNLaptrinh/Python/Projects/RiBo-Core/env/lib/python3.5/site-packages/rest_framework_mongoengine/serializers.py", line 262, in recursive_save
    instance.save()
  File "/media/thqbop/data/Hoctap/NNLaptrinh/Python/Projects/RiBo-Core/env/lib/python3.5/site-packages/mongoengine/document.py", line 355, in save
    self.validate(clean=clean)
  File "/media/thqbop/data/Hoctap/NNLaptrinh/Python/Projects/RiBo-Core/env/lib/python3.5/site-packages/mongoengine/base/document.py", line 395, in validate
    raise ValidationError(message, errors=errors)
mongoengine.errors.ValidationError: ValidationError (User:None) (Field is required: ['email_address'])

During handling of the above exception, another exception occurred:

Traceback (most recent call last):
  File "/media/thqbop/data/Hoctap/NNLaptrinh/Python/Projects/RiBo-Core/src/ribo_api/views/user.py", line 63, in create
    serializer.save()
  File "/media/thqbop/data/Hoctap/NNLaptrinh/Python/Projects/RiBo-Core/env/lib/python3.5/site-packages/rest_framework/serializers.py", line 191, in save
    self.instance = self.create(validated_data)
  File "/media/thqbop/data/Hoctap/NNLaptrinh/Python/Projects/RiBo-Core/env/lib/python3.5/site-packages/rest_framework_mongoengine/serializers.py", line 183, in create
    raise me_ValidationError(msg)
mongoengine.errors.ValidationError: Got a `ValidationError` when calling `User.objects.create()`. This may be because request data satisfies serializer validations but not Mongoengine`s. You may need to check consistency between User and UserSerializer.
If that is not the case, please open a ticket regarding this issue on https://github.com/umutbozkurt/django-rest-framework-mongoengine/issues
Original exception was: ValidationError (User:None) (Field is required: ['email_address'])
[13/Mar/2018 16:40:40] ERROR [/media/thqbop/data/Hoctap/NNLaptrinh/Python/Projects/RiBo-Core/src/ribo_api/services/utils.py:189] Got a `ValidationError` when calling `User.objects.create()`. This may be because request data satisfies serializer validations but not Mongoengine`s. You may need to check consistency between User and UserSerializer.
If that is not the case, please open a ticket regarding this issue on https://github.com/umutbozkurt/django-rest-framework-mongoengine/issues
Original exception was: ValidationError (User:None) (Field is required: ['email_address'])
Traceback (most recent call last):
  File "/media/thqbop/data/Hoctap/NNLaptrinh/Python/Projects/RiBo-Core/env/lib/python3.5/site-packages/rest_framework_mongoengine/serializers.py", line 151, in create
    instance = self.recursive_save(validated_data)
  File "/media/thqbop/data/Hoctap/NNLaptrinh/Python/Projects/RiBo-Core/env/lib/python3.5/site-packages/rest_framework_mongoengine/serializers.py", line 262, in recursive_save
    instance.save()
  File "/media/thqbop/data/Hoctap/NNLaptrinh/Python/Projects/RiBo-Core/env/lib/python3.5/site-packages/mongoengine/document.py", line 355, in save
    self.validate(clean=clean)
  File "/media/thqbop/data/Hoctap/NNLaptrinh/Python/Projects/RiBo-Core/env/lib/python3.5/site-packages/mongoengine/base/document.py", line 395, in validate
    raise ValidationError(message, errors=errors)
mongoengine.errors.ValidationError: ValidationError (User:None) (Field is required: ['email_address'])

During handling of the above exception, another exception occurred:

Traceback (most recent call last):
  File "/media/thqbop/data/Hoctap/NNLaptrinh/Python/Projects/RiBo-Core/src/ribo_api/views/user.py", line 63, in create
    serializer.save()
  File "/media/thqbop/data/Hoctap/NNLaptrinh/Python/Projects/RiBo-Core/env/lib/python3.5/site-packages/rest_framework/serializers.py", line 191, in save
    self.instance = self.create(validated_data)
  File "/media/thqbop/data/Hoctap/NNLaptrinh/Python/Projects/RiBo-Core/env/lib/python3.5/site-packages/rest_framework_mongoengine/serializers.py", line 183, in create
    raise me_ValidationError(msg)
mongoengine.errors.ValidationError: Got a `ValidationError` when calling `User.objects.create()`. This may be because request data satisfies serializer validations but not Mongoengine`s. You may need to check consistency between User and UserSerializer.
If that is not the case, please open a ticket regarding this issue on https://github.com/umutbozkurt/django-rest-framework-mongoengine/issues
Original exception was: ValidationError (User:None) (Field is required: ['email_address'])
[13/Mar/2018 16:41:01] ERROR [/media/thqbop/data/Hoctap/NNLaptrinh/Python/Projects/RiBo-Core/src/ribo_api/services/utils.py:189] Got a `TypeError` when calling `User.objects.create()`. This may be because you have a writable field on the serializer class that is not a valid argument to `User.objects.create()`. You may need to make the field read-only, or override the UserSerializer.create() method to handle this correctly.
Original exception text was: data must be an instance of bytes.
Traceback (most recent call last):
  File "/media/thqbop/data/Hoctap/NNLaptrinh/Python/Projects/RiBo-Core/env/lib/python3.5/site-packages/rest_framework_mongoengine/serializers.py", line 151, in create
    instance = self.recursive_save(validated_data)
  File "/media/thqbop/data/Hoctap/NNLaptrinh/Python/Projects/RiBo-Core/env/lib/python3.5/site-packages/rest_framework_mongoengine/serializers.py", line 262, in recursive_save
    instance.save()
  File "/media/thqbop/data/Hoctap/NNLaptrinh/Python/Projects/RiBo-Core/env/lib/python3.5/site-packages/mongoengine/document.py", line 360, in save
    doc = self.to_mongo()
  File "/media/thqbop/data/Hoctap/NNLaptrinh/Python/Projects/RiBo-Core/env/lib/python3.5/site-packages/mongoengine/document.py", line 242, in to_mongo
    data = super(Document, self).to_mongo(*args, **kwargs)
  File "/media/thqbop/data/Hoctap/NNLaptrinh/Python/Projects/RiBo-Core/env/lib/python3.5/site-packages/mongoengine/base/document.py", line 333, in to_mongo
    value = field.to_mongo(value, **ex_vars)
  File "/media/thqbop/data/Hoctap/NNLaptrinh/Python/Projects/RiBo-Core/env/lib/python3.5/site-packages/mongoengine/fields.py", line 1403, in to_mongo
    return Binary(value)
  File "/media/thqbop/data/Hoctap/NNLaptrinh/Python/Projects/RiBo-Core/env/lib/python3.5/site-packages/bson/binary.py", line 147, in __new__
    raise TypeError("data must be an instance of bytes")
TypeError: data must be an instance of bytes

During handling of the above exception, another exception occurred:

Traceback (most recent call last):
  File "/media/thqbop/data/Hoctap/NNLaptrinh/Python/Projects/RiBo-Core/src/ribo_api/views/user.py", line 63, in create
    serializer.save()
  File "/media/thqbop/data/Hoctap/NNLaptrinh/Python/Projects/RiBo-Core/env/lib/python3.5/site-packages/rest_framework/serializers.py", line 191, in save
    self.instance = self.create(validated_data)
  File "/media/thqbop/data/Hoctap/NNLaptrinh/Python/Projects/RiBo-Core/env/lib/python3.5/site-packages/rest_framework_mongoengine/serializers.py", line 167, in create
    raise TypeError(msg)
TypeError: Got a `TypeError` when calling `User.objects.create()`. This may be because you have a writable field on the serializer class that is not a valid argument to `User.objects.create()`. You may need to make the field read-only, or override the UserSerializer.create() method to handle this correctly.
Original exception text was: data must be an instance of bytes.
[13/Mar/2018 16:42:15] ERROR [/media/thqbop/data/Hoctap/NNLaptrinh/Python/Projects/RiBo-Core/src/ribo_api/services/utils.py:189] Got a `TypeError` when calling `User.objects.create()`. This may be because you have a writable field on the serializer class that is not a valid argument to `User.objects.create()`. You may need to make the field read-only, or override the UserSerializer.create() method to handle this correctly.
Original exception text was: data must be an instance of bytes.
Traceback (most recent call last):
  File "/media/thqbop/data/Hoctap/NNLaptrinh/Python/Projects/RiBo-Core/env/lib/python3.5/site-packages/rest_framework_mongoengine/serializers.py", line 151, in create
    instance = self.recursive_save(validated_data)
  File "/media/thqbop/data/Hoctap/NNLaptrinh/Python/Projects/RiBo-Core/env/lib/python3.5/site-packages/rest_framework_mongoengine/serializers.py", line 262, in recursive_save
    instance.save()
  File "/media/thqbop/data/Hoctap/NNLaptrinh/Python/Projects/RiBo-Core/env/lib/python3.5/site-packages/mongoengine/document.py", line 360, in save
    doc = self.to_mongo()
  File "/media/thqbop/data/Hoctap/NNLaptrinh/Python/Projects/RiBo-Core/env/lib/python3.5/site-packages/mongoengine/document.py", line 242, in to_mongo
    data = super(Document, self).to_mongo(*args, **kwargs)
  File "/media/thqbop/data/Hoctap/NNLaptrinh/Python/Projects/RiBo-Core/env/lib/python3.5/site-packages/mongoengine/base/document.py", line 333, in to_mongo
    value = field.to_mongo(value, **ex_vars)
  File "/media/thqbop/data/Hoctap/NNLaptrinh/Python/Projects/RiBo-Core/env/lib/python3.5/site-packages/mongoengine/fields.py", line 1403, in to_mongo
    return Binary(value)
  File "/media/thqbop/data/Hoctap/NNLaptrinh/Python/Projects/RiBo-Core/env/lib/python3.5/site-packages/bson/binary.py", line 147, in __new__
    raise TypeError("data must be an instance of bytes")
TypeError: data must be an instance of bytes

During handling of the above exception, another exception occurred:

Traceback (most recent call last):
  File "/media/thqbop/data/Hoctap/NNLaptrinh/Python/Projects/RiBo-Core/src/ribo_api/views/user.py", line 63, in create
    serializer.save()
  File "/media/thqbop/data/Hoctap/NNLaptrinh/Python/Projects/RiBo-Core/env/lib/python3.5/site-packages/rest_framework/serializers.py", line 191, in save
    self.instance = self.create(validated_data)
  File "/media/thqbop/data/Hoctap/NNLaptrinh/Python/Projects/RiBo-Core/env/lib/python3.5/site-packages/rest_framework_mongoengine/serializers.py", line 167, in create
    raise TypeError(msg)
TypeError: Got a `TypeError` when calling `User.objects.create()`. This may be because you have a writable field on the serializer class that is not a valid argument to `User.objects.create()`. You may need to make the field read-only, or override the UserSerializer.create() method to handle this correctly.
Original exception text was: data must be an instance of bytes.
[13/Mar/2018 17:06:07] ERROR [/media/thqbop/data/Hoctap/NNLaptrinh/Python/Projects/RiBo-Core/src/ribo_api/services/utils.py:189] Got a `TypeError` when calling `User.objects.create()`. This may be because you have a writable field on the serializer class that is not a valid argument to `User.objects.create()`. You may need to make the field read-only, or override the UserSerializer.create() method to handle this correctly.
Original exception text was: data must be an instance of bytes.
Traceback (most recent call last):
  File "/media/thqbop/data/Hoctap/NNLaptrinh/Python/Projects/RiBo-Core/env/lib/python3.5/site-packages/rest_framework_mongoengine/serializers.py", line 151, in create
    instance = self.recursive_save(validated_data)
  File "/media/thqbop/data/Hoctap/NNLaptrinh/Python/Projects/RiBo-Core/env/lib/python3.5/site-packages/rest_framework_mongoengine/serializers.py", line 262, in recursive_save
    instance.save()
  File "/media/thqbop/data/Hoctap/NNLaptrinh/Python/Projects/RiBo-Core/env/lib/python3.5/site-packages/mongoengine/document.py", line 360, in save
    doc = self.to_mongo()
  File "/media/thqbop/data/Hoctap/NNLaptrinh/Python/Projects/RiBo-Core/env/lib/python3.5/site-packages/mongoengine/document.py", line 242, in to_mongo
    data = super(Document, self).to_mongo(*args, **kwargs)
  File "/media/thqbop/data/Hoctap/NNLaptrinh/Python/Projects/RiBo-Core/env/lib/python3.5/site-packages/mongoengine/base/document.py", line 333, in to_mongo
    value = field.to_mongo(value, **ex_vars)
  File "/media/thqbop/data/Hoctap/NNLaptrinh/Python/Projects/RiBo-Core/env/lib/python3.5/site-packages/mongoengine/fields.py", line 1403, in to_mongo
    return Binary(value)
  File "/media/thqbop/data/Hoctap/NNLaptrinh/Python/Projects/RiBo-Core/env/lib/python3.5/site-packages/bson/binary.py", line 147, in __new__
    raise TypeError("data must be an instance of bytes")
TypeError: data must be an instance of bytes

During handling of the above exception, another exception occurred:

Traceback (most recent call last):
  File "/media/thqbop/data/Hoctap/NNLaptrinh/Python/Projects/RiBo-Core/src/ribo_api/views/user.py", line 63, in create
    serializer.save()
  File "/media/thqbop/data/Hoctap/NNLaptrinh/Python/Projects/RiBo-Core/env/lib/python3.5/site-packages/rest_framework/serializers.py", line 191, in save
    self.instance = self.create(validated_data)
  File "/media/thqbop/data/Hoctap/NNLaptrinh/Python/Projects/RiBo-Core/env/lib/python3.5/site-packages/rest_framework_mongoengine/serializers.py", line 167, in create
    raise TypeError(msg)
TypeError: Got a `TypeError` when calling `User.objects.create()`. This may be because you have a writable field on the serializer class that is not a valid argument to `User.objects.create()`. You may need to make the field read-only, or override the UserSerializer.create() method to handle this correctly.
Original exception text was: data must be an instance of bytes.
[13/Mar/2018 17:08:30] ERROR [/media/thqbop/data/Hoctap/NNLaptrinh/Python/Projects/RiBo-Core/src/ribo_api/services/utils.py:189] Got a `TypeError` when calling `User.objects.create()`. This may be because you have a writable field on the serializer class that is not a valid argument to `User.objects.create()`. You may need to make the field read-only, or override the UserSerializer.create() method to handle this correctly.
Original exception text was: data must be an instance of bytes.
Traceback (most recent call last):
  File "/media/thqbop/data/Hoctap/NNLaptrinh/Python/Projects/RiBo-Core/env/lib/python3.5/site-packages/rest_framework_mongoengine/serializers.py", line 151, in create
    instance = self.recursive_save(validated_data)
  File "/media/thqbop/data/Hoctap/NNLaptrinh/Python/Projects/RiBo-Core/env/lib/python3.5/site-packages/rest_framework_mongoengine/serializers.py", line 262, in recursive_save
    instance.save()
  File "/media/thqbop/data/Hoctap/NNLaptrinh/Python/Projects/RiBo-Core/env/lib/python3.5/site-packages/mongoengine/document.py", line 360, in save
    doc = self.to_mongo()
  File "/media/thqbop/data/Hoctap/NNLaptrinh/Python/Projects/RiBo-Core/env/lib/python3.5/site-packages/mongoengine/document.py", line 242, in to_mongo
    data = super(Document, self).to_mongo(*args, **kwargs)
  File "/media/thqbop/data/Hoctap/NNLaptrinh/Python/Projects/RiBo-Core/env/lib/python3.5/site-packages/mongoengine/base/document.py", line 333, in to_mongo
    value = field.to_mongo(value, **ex_vars)
  File "/media/thqbop/data/Hoctap/NNLaptrinh/Python/Projects/RiBo-Core/env/lib/python3.5/site-packages/mongoengine/fields.py", line 1403, in to_mongo
    return Binary(value)
  File "/media/thqbop/data/Hoctap/NNLaptrinh/Python/Projects/RiBo-Core/env/lib/python3.5/site-packages/bson/binary.py", line 147, in __new__
    raise TypeError("data must be an instance of bytes")
TypeError: data must be an instance of bytes

During handling of the above exception, another exception occurred:

Traceback (most recent call last):
  File "/media/thqbop/data/Hoctap/NNLaptrinh/Python/Projects/RiBo-Core/src/ribo_api/views/user.py", line 63, in create
    serializer.save()
  File "/media/thqbop/data/Hoctap/NNLaptrinh/Python/Projects/RiBo-Core/env/lib/python3.5/site-packages/rest_framework/serializers.py", line 191, in save
    self.instance = self.create(validated_data)
  File "/media/thqbop/data/Hoctap/NNLaptrinh/Python/Projects/RiBo-Core/env/lib/python3.5/site-packages/rest_framework_mongoengine/serializers.py", line 167, in create
    raise TypeError(msg)
TypeError: Got a `TypeError` when calling `User.objects.create()`. This may be because you have a writable field on the serializer class that is not a valid argument to `User.objects.create()`. You may need to make the field read-only, or override the UserSerializer.create() method to handle this correctly.
Original exception text was: data must be an instance of bytes.
[13/Mar/2018 17:15:20] ERROR [/media/thqbop/data/Hoctap/NNLaptrinh/Python/Projects/RiBo-Core/src/ribo_api/services/utils.py:189] data must be an instance of bytes
Traceback (most recent call last):
  File "/media/thqbop/data/Hoctap/NNLaptrinh/Python/Projects/RiBo-Core/src/ribo_api/views/user.py", line 63, in create
    serializer.save()
  File "/media/thqbop/data/Hoctap/NNLaptrinh/Python/Projects/RiBo-Core/env/lib/python3.5/site-packages/rest_framework/serializers.py", line 191, in save
    self.instance = self.create(validated_data)
  File "/media/thqbop/data/Hoctap/NNLaptrinh/Python/Projects/RiBo-Core/src/ribo_api/serializers/user.py", line 12, in create
    obj = User.objects.create(**validated_data)
  File "/media/thqbop/data/Hoctap/NNLaptrinh/Python/Projects/RiBo-Core/env/lib/python3.5/site-packages/mongoengine/queryset/base.py", line 293, in create
    return self._document(**kwargs).save(force_insert=True)
  File "/media/thqbop/data/Hoctap/NNLaptrinh/Python/Projects/RiBo-Core/env/lib/python3.5/site-packages/mongoengine/document.py", line 360, in save
    doc = self.to_mongo()
  File "/media/thqbop/data/Hoctap/NNLaptrinh/Python/Projects/RiBo-Core/env/lib/python3.5/site-packages/mongoengine/document.py", line 242, in to_mongo
    data = super(Document, self).to_mongo(*args, **kwargs)
  File "/media/thqbop/data/Hoctap/NNLaptrinh/Python/Projects/RiBo-Core/env/lib/python3.5/site-packages/mongoengine/base/document.py", line 333, in to_mongo
    value = field.to_mongo(value, **ex_vars)
  File "/media/thqbop/data/Hoctap/NNLaptrinh/Python/Projects/RiBo-Core/env/lib/python3.5/site-packages/mongoengine/fields.py", line 1403, in to_mongo
    return Binary(value)
  File "/media/thqbop/data/Hoctap/NNLaptrinh/Python/Projects/RiBo-Core/env/lib/python3.5/site-packages/bson/binary.py", line 147, in __new__
    raise TypeError("data must be an instance of bytes")
TypeError: data must be an instance of bytes
[13/Mar/2018 17:23:57] ERROR [/media/thqbop/data/Hoctap/NNLaptrinh/Python/Projects/RiBo-Core/src/ribo_api/services/utils.py:189] {'access_token': ['This field is required.'], 'refresh_token': ['This field is required.'], 'email_address': ['This field is required.']}
Traceback (most recent call last):
  File "/media/thqbop/data/Hoctap/NNLaptrinh/Python/Projects/RiBo-Core/src/ribo_api/views/user.py", line 62, in create
    serializer.is_valid(raise_exception=True)
  File "/media/thqbop/data/Hoctap/NNLaptrinh/Python/Projects/RiBo-Core/env/lib/python3.5/site-packages/rest_framework/serializers.py", line 221, in is_valid
    raise ValidationError(self.errors)
rest_framework.exceptions.ValidationError: {'access_token': ['This field is required.'], 'refresh_token': ['This field is required.'], 'email_address': ['This field is required.']}
[13/Mar/2018 17:25:07] ERROR [/media/thqbop/data/Hoctap/NNLaptrinh/Python/Projects/RiBo-Core/src/ribo_api/services/utils.py:189] {'access_token': ['This field is required.'], 'refresh_token': ['This field is required.'], 'email_address': ['This field is required.']}
Traceback (most recent call last):
  File "/media/thqbop/data/Hoctap/NNLaptrinh/Python/Projects/RiBo-Core/src/ribo_api/views/user.py", line 62, in create
    serializer.is_valid(raise_exception=True)
  File "/media/thqbop/data/Hoctap/NNLaptrinh/Python/Projects/RiBo-Core/env/lib/python3.5/site-packages/rest_framework/serializers.py", line 221, in is_valid
    raise ValidationError(self.errors)
rest_framework.exceptions.ValidationError: {'access_token': ['This field is required.'], 'refresh_token': ['This field is required.'], 'email_address': ['This field is required.']}
[13/Mar/2018 17:25:34] ERROR [/media/thqbop/data/Hoctap/NNLaptrinh/Python/Projects/RiBo-Core/src/ribo_api/services/utils.py:189] {'access_token': ['This field is required.'], 'refresh_token': ['This field is required.'], 'email_address': ['This field is required.']}
Traceback (most recent call last):
  File "/media/thqbop/data/Hoctap/NNLaptrinh/Python/Projects/RiBo-Core/src/ribo_api/views/user.py", line 62, in create
    serializer.is_valid(raise_exception=True)
  File "/media/thqbop/data/Hoctap/NNLaptrinh/Python/Projects/RiBo-Core/env/lib/python3.5/site-packages/rest_framework/serializers.py", line 221, in is_valid
    raise ValidationError(self.errors)
rest_framework.exceptions.ValidationError: {'access_token': ['This field is required.'], 'refresh_token': ['This field is required.'], 'email_address': ['This field is required.']}
[13/Mar/2018 17:26:01] ERROR [/media/thqbop/data/Hoctap/NNLaptrinh/Python/Projects/RiBo-Core/src/ribo_api/services/utils.py:189] {'access_token': ['This field is required.'], 'refresh_token': ['This field is required.'], 'email_address': ['This field is required.']}
Traceback (most recent call last):
  File "/media/thqbop/data/Hoctap/NNLaptrinh/Python/Projects/RiBo-Core/src/ribo_api/views/user.py", line 62, in create
    serializer.is_valid(raise_exception=True)
  File "/media/thqbop/data/Hoctap/NNLaptrinh/Python/Projects/RiBo-Core/env/lib/python3.5/site-packages/rest_framework/serializers.py", line 221, in is_valid
    raise ValidationError(self.errors)
rest_framework.exceptions.ValidationError: {'access_token': ['This field is required.'], 'refresh_token': ['This field is required.'], 'email_address': ['This field is required.']}
[13/Mar/2018 17:26:55] ERROR [/media/thqbop/data/Hoctap/NNLaptrinh/Python/Projects/RiBo-Core/src/ribo_api/services/utils.py:189] data must be an instance of bytes
Traceback (most recent call last):
  File "/media/thqbop/data/Hoctap/NNLaptrinh/Python/Projects/RiBo-Core/src/ribo_api/views/user.py", line 63, in create
    serializer.save()
  File "/media/thqbop/data/Hoctap/NNLaptrinh/Python/Projects/RiBo-Core/env/lib/python3.5/site-packages/rest_framework/serializers.py", line 191, in save
    self.instance = self.create(validated_data)
  File "/media/thqbop/data/Hoctap/NNLaptrinh/Python/Projects/RiBo-Core/src/ribo_api/serializers/user.py", line 12, in create
    obj = User.objects.create(**validated_data)
  File "/media/thqbop/data/Hoctap/NNLaptrinh/Python/Projects/RiBo-Core/env/lib/python3.5/site-packages/mongoengine/queryset/base.py", line 293, in create
    return self._document(**kwargs).save(force_insert=True)
  File "/media/thqbop/data/Hoctap/NNLaptrinh/Python/Projects/RiBo-Core/env/lib/python3.5/site-packages/mongoengine/document.py", line 360, in save
    doc = self.to_mongo()
  File "/media/thqbop/data/Hoctap/NNLaptrinh/Python/Projects/RiBo-Core/env/lib/python3.5/site-packages/mongoengine/document.py", line 242, in to_mongo
    data = super(Document, self).to_mongo(*args, **kwargs)
  File "/media/thqbop/data/Hoctap/NNLaptrinh/Python/Projects/RiBo-Core/env/lib/python3.5/site-packages/mongoengine/base/document.py", line 333, in to_mongo
    value = field.to_mongo(value, **ex_vars)
  File "/media/thqbop/data/Hoctap/NNLaptrinh/Python/Projects/RiBo-Core/env/lib/python3.5/site-packages/mongoengine/fields.py", line 1403, in to_mongo
    return Binary(value)
  File "/media/thqbop/data/Hoctap/NNLaptrinh/Python/Projects/RiBo-Core/env/lib/python3.5/site-packages/bson/binary.py", line 147, in __new__
    raise TypeError("data must be an instance of bytes")
TypeError: data must be an instance of bytes
[13/Mar/2018 17:27:09] ERROR [/media/thqbop/data/Hoctap/NNLaptrinh/Python/Projects/RiBo-Core/src/ribo_api/services/utils.py:189] Unsupported media type "text/plain;charset=UTF-8" in request.
Traceback (most recent call last):
  File "/media/thqbop/data/Hoctap/NNLaptrinh/Python/Projects/RiBo-Core/src/ribo_api/views/user.py", line 60, in create
    data = request.data.copy()
  File "/media/thqbop/data/Hoctap/NNLaptrinh/Python/Projects/RiBo-Core/env/lib/python3.5/site-packages/rest_framework/request.py", line 353, in __getattribute__
    return super(Request, self).__getattribute__(attr)
  File "/media/thqbop/data/Hoctap/NNLaptrinh/Python/Projects/RiBo-Core/env/lib/python3.5/site-packages/rest_framework/request.py", line 183, in data
    self._load_data_and_files()
  File "/media/thqbop/data/Hoctap/NNLaptrinh/Python/Projects/RiBo-Core/env/lib/python3.5/site-packages/rest_framework/request.py", line 243, in _load_data_and_files
    self._data, self._files = self._parse()
  File "/media/thqbop/data/Hoctap/NNLaptrinh/Python/Projects/RiBo-Core/env/lib/python3.5/site-packages/rest_framework/request.py", line 286, in _parse
    raise exceptions.UnsupportedMediaType(media_type)
rest_framework.exceptions.UnsupportedMediaType: Unsupported media type "text/plain;charset=UTF-8" in request.
[13/Mar/2018 17:29:51] ERROR [/media/thqbop/data/Hoctap/NNLaptrinh/Python/Projects/RiBo-Core/src/ribo_api/services/utils.py:189] JSON parse error - Expecting property name enclosed in double quotes: line 2 column 2 (char 3)
Traceback (most recent call last):
  File "/media/thqbop/data/Hoctap/NNLaptrinh/Python/Projects/RiBo-Core/env/lib/python3.5/site-packages/rest_framework/parsers.py", line 67, in parse
    return json.loads(data)
  File "/usr/lib/python3.5/json/__init__.py", line 319, in loads
    return _default_decoder.decode(s)
  File "/usr/lib/python3.5/json/decoder.py", line 339, in decode
    obj, end = self.raw_decode(s, idx=_w(s, 0).end())
  File "/usr/lib/python3.5/json/decoder.py", line 355, in raw_decode
    obj, end = self.scan_once(s, idx)
json.decoder.JSONDecodeError: Expecting property name enclosed in double quotes: line 2 column 2 (char 3)

During handling of the above exception, another exception occurred:

Traceback (most recent call last):
  File "/media/thqbop/data/Hoctap/NNLaptrinh/Python/Projects/RiBo-Core/src/ribo_api/views/user.py", line 60, in create
    data = request.data.copy()
  File "/media/thqbop/data/Hoctap/NNLaptrinh/Python/Projects/RiBo-Core/env/lib/python3.5/site-packages/rest_framework/request.py", line 353, in __getattribute__
    return super(Request, self).__getattribute__(attr)
  File "/media/thqbop/data/Hoctap/NNLaptrinh/Python/Projects/RiBo-Core/env/lib/python3.5/site-packages/rest_framework/request.py", line 183, in data
    self._load_data_and_files()
  File "/media/thqbop/data/Hoctap/NNLaptrinh/Python/Projects/RiBo-Core/env/lib/python3.5/site-packages/rest_framework/request.py", line 243, in _load_data_and_files
    self._data, self._files = self._parse()
  File "/media/thqbop/data/Hoctap/NNLaptrinh/Python/Projects/RiBo-Core/env/lib/python3.5/site-packages/rest_framework/request.py", line 289, in _parse
    parsed = parser.parse(stream, media_type, self.parser_context)
  File "/media/thqbop/data/Hoctap/NNLaptrinh/Python/Projects/RiBo-Core/env/lib/python3.5/site-packages/rest_framework/parsers.py", line 69, in parse
    raise ParseError('JSON parse error - %s' % six.text_type(exc))
rest_framework.exceptions.ParseError: JSON parse error - Expecting property name enclosed in double quotes: line 2 column 2 (char 3)
[13/Mar/2018 17:30:07] ERROR [/media/thqbop/data/Hoctap/NNLaptrinh/Python/Projects/RiBo-Core/src/ribo_api/services/utils.py:189] JSON parse error - Expecting property name enclosed in double quotes: line 2 column 2 (char 3)
Traceback (most recent call last):
  File "/media/thqbop/data/Hoctap/NNLaptrinh/Python/Projects/RiBo-Core/env/lib/python3.5/site-packages/rest_framework/parsers.py", line 67, in parse
    return json.loads(data)
  File "/usr/lib/python3.5/json/__init__.py", line 319, in loads
    return _default_decoder.decode(s)
  File "/usr/lib/python3.5/json/decoder.py", line 339, in decode
    obj, end = self.raw_decode(s, idx=_w(s, 0).end())
  File "/usr/lib/python3.5/json/decoder.py", line 355, in raw_decode
    obj, end = self.scan_once(s, idx)
json.decoder.JSONDecodeError: Expecting property name enclosed in double quotes: line 2 column 2 (char 3)

During handling of the above exception, another exception occurred:

Traceback (most recent call last):
  File "/media/thqbop/data/Hoctap/NNLaptrinh/Python/Projects/RiBo-Core/src/ribo_api/views/user.py", line 60, in create
    data = request.data.copy()
  File "/media/thqbop/data/Hoctap/NNLaptrinh/Python/Projects/RiBo-Core/env/lib/python3.5/site-packages/rest_framework/request.py", line 353, in __getattribute__
    return super(Request, self).__getattribute__(attr)
  File "/media/thqbop/data/Hoctap/NNLaptrinh/Python/Projects/RiBo-Core/env/lib/python3.5/site-packages/rest_framework/request.py", line 183, in data
    self._load_data_and_files()
  File "/media/thqbop/data/Hoctap/NNLaptrinh/Python/Projects/RiBo-Core/env/lib/python3.5/site-packages/rest_framework/request.py", line 243, in _load_data_and_files
    self._data, self._files = self._parse()
  File "/media/thqbop/data/Hoctap/NNLaptrinh/Python/Projects/RiBo-Core/env/lib/python3.5/site-packages/rest_framework/request.py", line 289, in _parse
    parsed = parser.parse(stream, media_type, self.parser_context)
  File "/media/thqbop/data/Hoctap/NNLaptrinh/Python/Projects/RiBo-Core/env/lib/python3.5/site-packages/rest_framework/parsers.py", line 69, in parse
    raise ParseError('JSON parse error - %s' % six.text_type(exc))
rest_framework.exceptions.ParseError: JSON parse error - Expecting property name enclosed in double quotes: line 2 column 2 (char 3)
[13/Mar/2018 17:30:46] ERROR [/media/thqbop/data/Hoctap/NNLaptrinh/Python/Projects/RiBo-Core/src/ribo_api/services/utils.py:189] {'sex': ['BinaryField only accepts instances of (bytes, str, Binary)']}
Traceback (most recent call last):
  File "/media/thqbop/data/Hoctap/NNLaptrinh/Python/Projects/RiBo-Core/src/ribo_api/views/user.py", line 62, in create
    serializer.is_valid(raise_exception=True)
  File "/media/thqbop/data/Hoctap/NNLaptrinh/Python/Projects/RiBo-Core/env/lib/python3.5/site-packages/rest_framework/serializers.py", line 221, in is_valid
    raise ValidationError(self.errors)
rest_framework.exceptions.ValidationError: {'sex': ['BinaryField only accepts instances of (bytes, str, Binary)']}
[13/Mar/2018 17:30:57] ERROR [/media/thqbop/data/Hoctap/NNLaptrinh/Python/Projects/RiBo-Core/src/ribo_api/services/utils.py:189] data must be an instance of bytes
Traceback (most recent call last):
  File "/media/thqbop/data/Hoctap/NNLaptrinh/Python/Projects/RiBo-Core/src/ribo_api/views/user.py", line 63, in create
    serializer.save()
  File "/media/thqbop/data/Hoctap/NNLaptrinh/Python/Projects/RiBo-Core/env/lib/python3.5/site-packages/rest_framework/serializers.py", line 191, in save
    self.instance = self.create(validated_data)
  File "/media/thqbop/data/Hoctap/NNLaptrinh/Python/Projects/RiBo-Core/src/ribo_api/serializers/user.py", line 12, in create
    obj = User.objects.create(**validated_data)
  File "/media/thqbop/data/Hoctap/NNLaptrinh/Python/Projects/RiBo-Core/env/lib/python3.5/site-packages/mongoengine/queryset/base.py", line 293, in create
    return self._document(**kwargs).save(force_insert=True)
  File "/media/thqbop/data/Hoctap/NNLaptrinh/Python/Projects/RiBo-Core/env/lib/python3.5/site-packages/mongoengine/document.py", line 360, in save
    doc = self.to_mongo()
  File "/media/thqbop/data/Hoctap/NNLaptrinh/Python/Projects/RiBo-Core/env/lib/python3.5/site-packages/mongoengine/document.py", line 242, in to_mongo
    data = super(Document, self).to_mongo(*args, **kwargs)
  File "/media/thqbop/data/Hoctap/NNLaptrinh/Python/Projects/RiBo-Core/env/lib/python3.5/site-packages/mongoengine/base/document.py", line 333, in to_mongo
    value = field.to_mongo(value, **ex_vars)
  File "/media/thqbop/data/Hoctap/NNLaptrinh/Python/Projects/RiBo-Core/env/lib/python3.5/site-packages/mongoengine/fields.py", line 1403, in to_mongo
    return Binary(value)
  File "/media/thqbop/data/Hoctap/NNLaptrinh/Python/Projects/RiBo-Core/env/lib/python3.5/site-packages/bson/binary.py", line 147, in __new__
    raise TypeError("data must be an instance of bytes")
TypeError: data must be an instance of bytes
[13/Mar/2018 17:31:30] ERROR [/media/thqbop/data/Hoctap/NNLaptrinh/Python/Projects/RiBo-Core/src/ribo_api/services/utils.py:189] data must be an instance of bytes
Traceback (most recent call last):
  File "/media/thqbop/data/Hoctap/NNLaptrinh/Python/Projects/RiBo-Core/src/ribo_api/views/user.py", line 63, in create
    serializer.save()
  File "/media/thqbop/data/Hoctap/NNLaptrinh/Python/Projects/RiBo-Core/env/lib/python3.5/site-packages/rest_framework/serializers.py", line 191, in save
    self.instance = self.create(validated_data)
  File "/media/thqbop/data/Hoctap/NNLaptrinh/Python/Projects/RiBo-Core/src/ribo_api/serializers/user.py", line 12, in create
    obj = User.objects.create(**validated_data)
  File "/media/thqbop/data/Hoctap/NNLaptrinh/Python/Projects/RiBo-Core/env/lib/python3.5/site-packages/mongoengine/queryset/base.py", line 293, in create
    return self._document(**kwargs).save(force_insert=True)
  File "/media/thqbop/data/Hoctap/NNLaptrinh/Python/Projects/RiBo-Core/env/lib/python3.5/site-packages/mongoengine/document.py", line 360, in save
    doc = self.to_mongo()
  File "/media/thqbop/data/Hoctap/NNLaptrinh/Python/Projects/RiBo-Core/env/lib/python3.5/site-packages/mongoengine/document.py", line 242, in to_mongo
    data = super(Document, self).to_mongo(*args, **kwargs)
  File "/media/thqbop/data/Hoctap/NNLaptrinh/Python/Projects/RiBo-Core/env/lib/python3.5/site-packages/mongoengine/base/document.py", line 333, in to_mongo
    value = field.to_mongo(value, **ex_vars)
  File "/media/thqbop/data/Hoctap/NNLaptrinh/Python/Projects/RiBo-Core/env/lib/python3.5/site-packages/mongoengine/fields.py", line 1403, in to_mongo
    return Binary(value)
  File "/media/thqbop/data/Hoctap/NNLaptrinh/Python/Projects/RiBo-Core/env/lib/python3.5/site-packages/bson/binary.py", line 147, in __new__
    raise TypeError("data must be an instance of bytes")
TypeError: data must be an instance of bytes
[13/Mar/2018 17:37:06] ERROR [/media/thqbop/data/Hoctap/NNLaptrinh/Python/Projects/RiBo-Core/src/ribo_api/services/utils.py:189] data must be an instance of bytes
Traceback (most recent call last):
  File "/media/thqbop/data/Hoctap/NNLaptrinh/Python/Projects/RiBo-Core/src/ribo_api/views/user.py", line 63, in create
    serializer.save()
  File "/media/thqbop/data/Hoctap/NNLaptrinh/Python/Projects/RiBo-Core/env/lib/python3.5/site-packages/rest_framework/serializers.py", line 191, in save
    self.instance = self.create(validated_data)
  File "/media/thqbop/data/Hoctap/NNLaptrinh/Python/Projects/RiBo-Core/src/ribo_api/serializers/user.py", line 12, in create
    obj = User.objects.create(**validated_data)
  File "/media/thqbop/data/Hoctap/NNLaptrinh/Python/Projects/RiBo-Core/env/lib/python3.5/site-packages/mongoengine/queryset/base.py", line 293, in create
    return self._document(**kwargs).save(force_insert=True)
  File "/media/thqbop/data/Hoctap/NNLaptrinh/Python/Projects/RiBo-Core/env/lib/python3.5/site-packages/mongoengine/document.py", line 360, in save
    doc = self.to_mongo()
  File "/media/thqbop/data/Hoctap/NNLaptrinh/Python/Projects/RiBo-Core/env/lib/python3.5/site-packages/mongoengine/document.py", line 242, in to_mongo
    data = super(Document, self).to_mongo(*args, **kwargs)
  File "/media/thqbop/data/Hoctap/NNLaptrinh/Python/Projects/RiBo-Core/env/lib/python3.5/site-packages/mongoengine/base/document.py", line 333, in to_mongo
    value = field.to_mongo(value, **ex_vars)
  File "/media/thqbop/data/Hoctap/NNLaptrinh/Python/Projects/RiBo-Core/env/lib/python3.5/site-packages/mongoengine/fields.py", line 1403, in to_mongo
    return Binary(value)
  File "/media/thqbop/data/Hoctap/NNLaptrinh/Python/Projects/RiBo-Core/env/lib/python3.5/site-packages/bson/binary.py", line 147, in __new__
    raise TypeError("data must be an instance of bytes")
TypeError: data must be an instance of bytes
[13/Mar/2018 17:41:49] ERROR [/media/thqbop/data/Hoctap/NNLaptrinh/Python/Projects/RiBo-Core/src/ribo_api/services/utils.py:189] JSON parse error - Expecting value: line 1 column 1 (char 0)
Traceback (most recent call last):
  File "/media/thqbop/data/Hoctap/NNLaptrinh/Python/Projects/RiBo-Core/env/lib/python3.5/site-packages/rest_framework/parsers.py", line 67, in parse
    return json.loads(data)
  File "/usr/lib/python3.5/json/__init__.py", line 319, in loads
    return _default_decoder.decode(s)
  File "/usr/lib/python3.5/json/decoder.py", line 339, in decode
    obj, end = self.raw_decode(s, idx=_w(s, 0).end())
  File "/usr/lib/python3.5/json/decoder.py", line 357, in raw_decode
    raise JSONDecodeError("Expecting value", s, err.value) from None
json.decoder.JSONDecodeError: Expecting value: line 1 column 1 (char 0)

During handling of the above exception, another exception occurred:

Traceback (most recent call last):
  File "/media/thqbop/data/Hoctap/NNLaptrinh/Python/Projects/RiBo-Core/src/ribo_api/views/user.py", line 60, in create
    data = request.data.copy()
  File "/media/thqbop/data/Hoctap/NNLaptrinh/Python/Projects/RiBo-Core/env/lib/python3.5/site-packages/rest_framework/request.py", line 353, in __getattribute__
    return super(Request, self).__getattribute__(attr)
  File "/media/thqbop/data/Hoctap/NNLaptrinh/Python/Projects/RiBo-Core/env/lib/python3.5/site-packages/rest_framework/request.py", line 183, in data
    self._load_data_and_files()
  File "/media/thqbop/data/Hoctap/NNLaptrinh/Python/Projects/RiBo-Core/env/lib/python3.5/site-packages/rest_framework/request.py", line 243, in _load_data_and_files
    self._data, self._files = self._parse()
  File "/media/thqbop/data/Hoctap/NNLaptrinh/Python/Projects/RiBo-Core/env/lib/python3.5/site-packages/rest_framework/request.py", line 289, in _parse
    parsed = parser.parse(stream, media_type, self.parser_context)
  File "/media/thqbop/data/Hoctap/NNLaptrinh/Python/Projects/RiBo-Core/env/lib/python3.5/site-packages/rest_framework/parsers.py", line 69, in parse
    raise ParseError('JSON parse error - %s' % six.text_type(exc))
rest_framework.exceptions.ParseError: JSON parse error - Expecting value: line 1 column 1 (char 0)
[13/Mar/2018 17:42:06] ERROR [/media/thqbop/data/Hoctap/NNLaptrinh/Python/Projects/RiBo-Core/src/ribo_api/services/utils.py:189] ValidationError (User:None) (Field is required: ['email_address'])
Traceback (most recent call last):
  File "/media/thqbop/data/Hoctap/NNLaptrinh/Python/Projects/RiBo-Core/src/ribo_api/views/user.py", line 63, in create
    serializer.save()
  File "/media/thqbop/data/Hoctap/NNLaptrinh/Python/Projects/RiBo-Core/env/lib/python3.5/site-packages/rest_framework/serializers.py", line 191, in save
    self.instance = self.create(validated_data)
  File "/media/thqbop/data/Hoctap/NNLaptrinh/Python/Projects/RiBo-Core/src/ribo_api/serializers/user.py", line 12, in create
    obj = User.objects.create(**validated_data)
  File "/media/thqbop/data/Hoctap/NNLaptrinh/Python/Projects/RiBo-Core/env/lib/python3.5/site-packages/mongoengine/queryset/base.py", line 293, in create
    return self._document(**kwargs).save(force_insert=True)
  File "/media/thqbop/data/Hoctap/NNLaptrinh/Python/Projects/RiBo-Core/env/lib/python3.5/site-packages/mongoengine/document.py", line 355, in save
    self.validate(clean=clean)
  File "/media/thqbop/data/Hoctap/NNLaptrinh/Python/Projects/RiBo-Core/env/lib/python3.5/site-packages/mongoengine/base/document.py", line 395, in validate
    raise ValidationError(message, errors=errors)
mongoengine.errors.ValidationError: ValidationError (User:None) (Field is required: ['email_address'])
[13/Mar/2018 17:42:27] ERROR [/media/thqbop/data/Hoctap/NNLaptrinh/Python/Projects/RiBo-Core/src/ribo_api/services/utils.py:189] ValidationError (User:None) (Field is required: ['email'])
Traceback (most recent call last):
  File "/media/thqbop/data/Hoctap/NNLaptrinh/Python/Projects/RiBo-Core/src/ribo_api/views/user.py", line 63, in create
    serializer.save()
  File "/media/thqbop/data/Hoctap/NNLaptrinh/Python/Projects/RiBo-Core/env/lib/python3.5/site-packages/rest_framework/serializers.py", line 191, in save
    self.instance = self.create(validated_data)
  File "/media/thqbop/data/Hoctap/NNLaptrinh/Python/Projects/RiBo-Core/src/ribo_api/serializers/user.py", line 12, in create
    obj = User.objects.create(**validated_data)
  File "/media/thqbop/data/Hoctap/NNLaptrinh/Python/Projects/RiBo-Core/env/lib/python3.5/site-packages/mongoengine/queryset/base.py", line 293, in create
    return self._document(**kwargs).save(force_insert=True)
  File "/media/thqbop/data/Hoctap/NNLaptrinh/Python/Projects/RiBo-Core/env/lib/python3.5/site-packages/mongoengine/document.py", line 355, in save
    self.validate(clean=clean)
  File "/media/thqbop/data/Hoctap/NNLaptrinh/Python/Projects/RiBo-Core/env/lib/python3.5/site-packages/mongoengine/base/document.py", line 395, in validate
    raise ValidationError(message, errors=errors)
mongoengine.errors.ValidationError: ValidationError (User:None) (Field is required: ['email'])
[13/Mar/2018 17:43:37] ERROR [/media/thqbop/data/Hoctap/NNLaptrinh/Python/Projects/RiBo-Core/src/ribo_api/services/utils.py:189] You cannot call `.save()` after accessing `serializer.data`.If you need to access data before committing to the database then inspect 'serializer.validated_data' instead. 
Traceback (most recent call last):
  File "/media/thqbop/data/Hoctap/NNLaptrinh/Python/Projects/RiBo-Core/src/ribo_api/views/user.py", line 63, in create
    serializer.save()
  File "/media/thqbop/data/Hoctap/NNLaptrinh/Python/Projects/RiBo-Core/env/lib/python3.5/site-packages/rest_framework/serializers.py", line 175, in save
    "You cannot call `.save()` after accessing `serializer.data`."
AssertionError: You cannot call `.save()` after accessing `serializer.data`.If you need to access data before committing to the database then inspect 'serializer.validated_data' instead. 
[13/Mar/2018 17:44:09] ERROR [/media/thqbop/data/Hoctap/NNLaptrinh/Python/Projects/RiBo-Core/src/ribo_api/services/utils.py:189] You cannot call `.save()` after accessing `serializer.data`.If you need to access data before committing to the database then inspect 'serializer.validated_data' instead. 
Traceback (most recent call last):
  File "/media/thqbop/data/Hoctap/NNLaptrinh/Python/Projects/RiBo-Core/src/ribo_api/views/user.py", line 63, in create
    serializer.save()
  File "/media/thqbop/data/Hoctap/NNLaptrinh/Python/Projects/RiBo-Core/env/lib/python3.5/site-packages/rest_framework/serializers.py", line 175, in save
    "You cannot call `.save()` after accessing `serializer.data`."
AssertionError: You cannot call `.save()` after accessing `serializer.data`.If you need to access data before committing to the database then inspect 'serializer.validated_data' instead. 
[13/Mar/2018 17:44:34] ERROR [/media/thqbop/data/Hoctap/NNLaptrinh/Python/Projects/RiBo-Core/src/ribo_api/services/utils.py:189] ValidationError (User:None) (Field is required: ['email'])
Traceback (most recent call last):
  File "/media/thqbop/data/Hoctap/NNLaptrinh/Python/Projects/RiBo-Core/src/ribo_api/views/user.py", line 63, in create
    serializer.save()
  File "/media/thqbop/data/Hoctap/NNLaptrinh/Python/Projects/RiBo-Core/env/lib/python3.5/site-packages/rest_framework/serializers.py", line 191, in save
    self.instance = self.create(validated_data)
  File "/media/thqbop/data/Hoctap/NNLaptrinh/Python/Projects/RiBo-Core/src/ribo_api/serializers/user.py", line 12, in create
    obj = User.objects.create(**validated_data)
  File "/media/thqbop/data/Hoctap/NNLaptrinh/Python/Projects/RiBo-Core/env/lib/python3.5/site-packages/mongoengine/queryset/base.py", line 293, in create
    return self._document(**kwargs).save(force_insert=True)
  File "/media/thqbop/data/Hoctap/NNLaptrinh/Python/Projects/RiBo-Core/env/lib/python3.5/site-packages/mongoengine/document.py", line 355, in save
    self.validate(clean=clean)
  File "/media/thqbop/data/Hoctap/NNLaptrinh/Python/Projects/RiBo-Core/env/lib/python3.5/site-packages/mongoengine/base/document.py", line 395, in validate
    raise ValidationError(message, errors=errors)
mongoengine.errors.ValidationError: ValidationError (User:None) (Field is required: ['email'])
[13/Mar/2018 17:44:52] ERROR [/media/thqbop/data/Hoctap/NNLaptrinh/Python/Projects/RiBo-Core/src/ribo_api/services/utils.py:189] ValidationError (User:None) (Field is required: ['email'])
Traceback (most recent call last):
  File "/media/thqbop/data/Hoctap/NNLaptrinh/Python/Projects/RiBo-Core/src/ribo_api/views/user.py", line 63, in create
    serializer.save()
  File "/media/thqbop/data/Hoctap/NNLaptrinh/Python/Projects/RiBo-Core/env/lib/python3.5/site-packages/rest_framework/serializers.py", line 191, in save
    self.instance = self.create(validated_data)
  File "/media/thqbop/data/Hoctap/NNLaptrinh/Python/Projects/RiBo-Core/src/ribo_api/serializers/user.py", line 12, in create
    obj = User.objects.create(**validated_data)
  File "/media/thqbop/data/Hoctap/NNLaptrinh/Python/Projects/RiBo-Core/env/lib/python3.5/site-packages/mongoengine/queryset/base.py", line 293, in create
    return self._document(**kwargs).save(force_insert=True)
  File "/media/thqbop/data/Hoctap/NNLaptrinh/Python/Projects/RiBo-Core/env/lib/python3.5/site-packages/mongoengine/document.py", line 355, in save
    self.validate(clean=clean)
  File "/media/thqbop/data/Hoctap/NNLaptrinh/Python/Projects/RiBo-Core/env/lib/python3.5/site-packages/mongoengine/base/document.py", line 395, in validate
    raise ValidationError(message, errors=errors)
mongoengine.errors.ValidationError: ValidationError (User:None) (Field is required: ['email'])
[13/Mar/2018 17:45:08] ERROR [/media/thqbop/data/Hoctap/NNLaptrinh/Python/Projects/RiBo-Core/src/ribo_api/services/utils.py:189] ValidationError (User:None) (Field is required: ['email'])
Traceback (most recent call last):
  File "/media/thqbop/data/Hoctap/NNLaptrinh/Python/Projects/RiBo-Core/src/ribo_api/views/user.py", line 63, in create
    serializer.save()
  File "/media/thqbop/data/Hoctap/NNLaptrinh/Python/Projects/RiBo-Core/env/lib/python3.5/site-packages/rest_framework/serializers.py", line 191, in save
    self.instance = self.create(validated_data)
  File "/media/thqbop/data/Hoctap/NNLaptrinh/Python/Projects/RiBo-Core/src/ribo_api/serializers/user.py", line 12, in create
    obj = User.objects.create(**validated_data)
  File "/media/thqbop/data/Hoctap/NNLaptrinh/Python/Projects/RiBo-Core/env/lib/python3.5/site-packages/mongoengine/queryset/base.py", line 293, in create
    return self._document(**kwargs).save(force_insert=True)
  File "/media/thqbop/data/Hoctap/NNLaptrinh/Python/Projects/RiBo-Core/env/lib/python3.5/site-packages/mongoengine/document.py", line 355, in save
    self.validate(clean=clean)
  File "/media/thqbop/data/Hoctap/NNLaptrinh/Python/Projects/RiBo-Core/env/lib/python3.5/site-packages/mongoengine/base/document.py", line 395, in validate
    raise ValidationError(message, errors=errors)
mongoengine.errors.ValidationError: ValidationError (User:None) (Field is required: ['email'])
[13/Mar/2018 17:45:57] ERROR [/media/thqbop/data/Hoctap/NNLaptrinh/Python/Projects/RiBo-Core/src/ribo_api/services/utils.py:189] ValidationError (User:None) (Field is required: ['email'])
Traceback (most recent call last):
  File "/media/thqbop/data/Hoctap/NNLaptrinh/Python/Projects/RiBo-Core/src/ribo_api/views/user.py", line 63, in create
    serializer.save()
  File "/media/thqbop/data/Hoctap/NNLaptrinh/Python/Projects/RiBo-Core/env/lib/python3.5/site-packages/rest_framework/serializers.py", line 191, in save
    self.instance = self.create(validated_data)
  File "/media/thqbop/data/Hoctap/NNLaptrinh/Python/Projects/RiBo-Core/src/ribo_api/serializers/user.py", line 12, in create
    obj = User.objects.create(**validated_data)
  File "/media/thqbop/data/Hoctap/NNLaptrinh/Python/Projects/RiBo-Core/env/lib/python3.5/site-packages/mongoengine/queryset/base.py", line 293, in create
    return self._document(**kwargs).save(force_insert=True)
  File "/media/thqbop/data/Hoctap/NNLaptrinh/Python/Projects/RiBo-Core/env/lib/python3.5/site-packages/mongoengine/document.py", line 355, in save
    self.validate(clean=clean)
  File "/media/thqbop/data/Hoctap/NNLaptrinh/Python/Projects/RiBo-Core/env/lib/python3.5/site-packages/mongoengine/base/document.py", line 395, in validate
    raise ValidationError(message, errors=errors)
mongoengine.errors.ValidationError: ValidationError (User:None) (Field is required: ['email'])
[13/Mar/2018 17:46:57] ERROR [/media/thqbop/data/Hoctap/NNLaptrinh/Python/Projects/RiBo-Core/src/ribo_api/services/utils.py:189] ValidationError (User:None) (Field is required: ['username'])
Traceback (most recent call last):
  File "/media/thqbop/data/Hoctap/NNLaptrinh/Python/Projects/RiBo-Core/src/ribo_api/views/user.py", line 63, in create
    serializer.save()
  File "/media/thqbop/data/Hoctap/NNLaptrinh/Python/Projects/RiBo-Core/env/lib/python3.5/site-packages/rest_framework/serializers.py", line 191, in save
    self.instance = self.create(validated_data)
  File "/media/thqbop/data/Hoctap/NNLaptrinh/Python/Projects/RiBo-Core/src/ribo_api/serializers/user.py", line 12, in create
    obj = User.objects.create(**validated_data)
  File "/media/thqbop/data/Hoctap/NNLaptrinh/Python/Projects/RiBo-Core/env/lib/python3.5/site-packages/mongoengine/queryset/base.py", line 293, in create
    return self._document(**kwargs).save(force_insert=True)
  File "/media/thqbop/data/Hoctap/NNLaptrinh/Python/Projects/RiBo-Core/env/lib/python3.5/site-packages/mongoengine/document.py", line 355, in save
    self.validate(clean=clean)
  File "/media/thqbop/data/Hoctap/NNLaptrinh/Python/Projects/RiBo-Core/env/lib/python3.5/site-packages/mongoengine/base/document.py", line 395, in validate
    raise ValidationError(message, errors=errors)
mongoengine.errors.ValidationError: ValidationError (User:None) (Field is required: ['username'])
[13/Mar/2018 17:48:29] ERROR [/media/thqbop/data/Hoctap/NNLaptrinh/Python/Projects/RiBo-Core/src/ribo_api/services/utils.py:189] ValidationError (User:None) (Field is required: ['email'])
Traceback (most recent call last):
  File "/media/thqbop/data/Hoctap/NNLaptrinh/Python/Projects/RiBo-Core/src/ribo_api/views/user.py", line 63, in create
    serializer.save()
  File "/media/thqbop/data/Hoctap/NNLaptrinh/Python/Projects/RiBo-Core/env/lib/python3.5/site-packages/rest_framework/serializers.py", line 191, in save
    self.instance = self.create(validated_data)
  File "/media/thqbop/data/Hoctap/NNLaptrinh/Python/Projects/RiBo-Core/src/ribo_api/serializers/user.py", line 12, in create
    obj = User.objects.create(**validated_data)
  File "/media/thqbop/data/Hoctap/NNLaptrinh/Python/Projects/RiBo-Core/env/lib/python3.5/site-packages/mongoengine/queryset/base.py", line 293, in create
    return self._document(**kwargs).save(force_insert=True)
  File "/media/thqbop/data/Hoctap/NNLaptrinh/Python/Projects/RiBo-Core/env/lib/python3.5/site-packages/mongoengine/document.py", line 355, in save
    self.validate(clean=clean)
  File "/media/thqbop/data/Hoctap/NNLaptrinh/Python/Projects/RiBo-Core/env/lib/python3.5/site-packages/mongoengine/base/document.py", line 395, in validate
    raise ValidationError(message, errors=errors)
mongoengine.errors.ValidationError: ValidationError (User:None) (Field is required: ['email'])
[13/Mar/2018 17:49:04] ERROR [/media/thqbop/data/Hoctap/NNLaptrinh/Python/Projects/RiBo-Core/src/ribo_api/services/utils.py:189] ValidationError (User:None) (Field is required: ['email'])
Traceback (most recent call last):
  File "/media/thqbop/data/Hoctap/NNLaptrinh/Python/Projects/RiBo-Core/src/ribo_api/views/user.py", line 63, in create
    serializer.save()
  File "/media/thqbop/data/Hoctap/NNLaptrinh/Python/Projects/RiBo-Core/env/lib/python3.5/site-packages/rest_framework/serializers.py", line 191, in save
    self.instance = self.create(validated_data)
  File "/media/thqbop/data/Hoctap/NNLaptrinh/Python/Projects/RiBo-Core/src/ribo_api/serializers/user.py", line 12, in create
    obj = User.objects.create(**validated_data)
  File "/media/thqbop/data/Hoctap/NNLaptrinh/Python/Projects/RiBo-Core/env/lib/python3.5/site-packages/mongoengine/queryset/base.py", line 293, in create
    return self._document(**kwargs).save(force_insert=True)
  File "/media/thqbop/data/Hoctap/NNLaptrinh/Python/Projects/RiBo-Core/env/lib/python3.5/site-packages/mongoengine/document.py", line 355, in save
    self.validate(clean=clean)
  File "/media/thqbop/data/Hoctap/NNLaptrinh/Python/Projects/RiBo-Core/env/lib/python3.5/site-packages/mongoengine/base/document.py", line 395, in validate
    raise ValidationError(message, errors=errors)
mongoengine.errors.ValidationError: ValidationError (User:None) (Field is required: ['email'])
[13/Mar/2018 17:49:20] ERROR [/media/thqbop/data/Hoctap/NNLaptrinh/Python/Projects/RiBo-Core/src/ribo_api/services/utils.py:189] ValidationError (User:None) (Field is required: ['email'])
Traceback (most recent call last):
  File "/media/thqbop/data/Hoctap/NNLaptrinh/Python/Projects/RiBo-Core/src/ribo_api/views/user.py", line 63, in create
    serializer.save()
  File "/media/thqbop/data/Hoctap/NNLaptrinh/Python/Projects/RiBo-Core/env/lib/python3.5/site-packages/rest_framework/serializers.py", line 191, in save
    self.instance = self.create(validated_data)
  File "/media/thqbop/data/Hoctap/NNLaptrinh/Python/Projects/RiBo-Core/src/ribo_api/serializers/user.py", line 12, in create
    obj = User.objects.create(**validated_data)
  File "/media/thqbop/data/Hoctap/NNLaptrinh/Python/Projects/RiBo-Core/env/lib/python3.5/site-packages/mongoengine/queryset/base.py", line 293, in create
    return self._document(**kwargs).save(force_insert=True)
  File "/media/thqbop/data/Hoctap/NNLaptrinh/Python/Projects/RiBo-Core/env/lib/python3.5/site-packages/mongoengine/document.py", line 355, in save
    self.validate(clean=clean)
  File "/media/thqbop/data/Hoctap/NNLaptrinh/Python/Projects/RiBo-Core/env/lib/python3.5/site-packages/mongoengine/base/document.py", line 395, in validate
    raise ValidationError(message, errors=errors)
mongoengine.errors.ValidationError: ValidationError (User:None) (Field is required: ['email'])
[13/Mar/2018 17:49:59] ERROR [/media/thqbop/data/Hoctap/NNLaptrinh/Python/Projects/RiBo-Core/src/ribo_api/services/utils.py:189] ValidationError (User:None) (Field is required: ['username'])
Traceback (most recent call last):
  File "/media/thqbop/data/Hoctap/NNLaptrinh/Python/Projects/RiBo-Core/src/ribo_api/views/user.py", line 63, in create
    serializer.save()
  File "/media/thqbop/data/Hoctap/NNLaptrinh/Python/Projects/RiBo-Core/env/lib/python3.5/site-packages/rest_framework/serializers.py", line 191, in save
    self.instance = self.create(validated_data)
  File "/media/thqbop/data/Hoctap/NNLaptrinh/Python/Projects/RiBo-Core/src/ribo_api/serializers/user.py", line 12, in create
    obj = User.objects.create(**validated_data)
  File "/media/thqbop/data/Hoctap/NNLaptrinh/Python/Projects/RiBo-Core/env/lib/python3.5/site-packages/mongoengine/queryset/base.py", line 293, in create
    return self._document(**kwargs).save(force_insert=True)
  File "/media/thqbop/data/Hoctap/NNLaptrinh/Python/Projects/RiBo-Core/env/lib/python3.5/site-packages/mongoengine/document.py", line 355, in save
    self.validate(clean=clean)
  File "/media/thqbop/data/Hoctap/NNLaptrinh/Python/Projects/RiBo-Core/env/lib/python3.5/site-packages/mongoengine/base/document.py", line 395, in validate
    raise ValidationError(message, errors=errors)
mongoengine.errors.ValidationError: ValidationError (User:None) (Field is required: ['username'])
[13/Mar/2018 17:50:54] ERROR [/media/thqbop/data/Hoctap/NNLaptrinh/Python/Projects/RiBo-Core/src/ribo_api/services/utils.py:189] You cannot call `.save()` after accessing `serializer.data`.If you need to access data before committing to the database then inspect 'serializer.validated_data' instead. 
Traceback (most recent call last):
  File "/media/thqbop/data/Hoctap/NNLaptrinh/Python/Projects/RiBo-Core/src/ribo_api/views/user.py", line 63, in create
    serializer.save()
  File "/media/thqbop/data/Hoctap/NNLaptrinh/Python/Projects/RiBo-Core/env/lib/python3.5/site-packages/rest_framework/serializers.py", line 175, in save
    "You cannot call `.save()` after accessing `serializer.data`."
AssertionError: You cannot call `.save()` after accessing `serializer.data`.If you need to access data before committing to the database then inspect 'serializer.validated_data' instead. 
[13/Mar/2018 17:54:11] ERROR [/media/thqbop/data/Hoctap/NNLaptrinh/Python/Projects/RiBo-Core/src/ribo_api/services/utils.py:189] You cannot call `.save()` after accessing `serializer.data`.If you need to access data before committing to the database then inspect 'serializer.validated_data' instead. 
Traceback (most recent call last):
  File "/media/thqbop/data/Hoctap/NNLaptrinh/Python/Projects/RiBo-Core/src/ribo_api/views/user.py", line 63, in create
    serializer.save()
  File "/media/thqbop/data/Hoctap/NNLaptrinh/Python/Projects/RiBo-Core/env/lib/python3.5/site-packages/rest_framework/serializers.py", line 175, in save
    "You cannot call `.save()` after accessing `serializer.data`."
AssertionError: You cannot call `.save()` after accessing `serializer.data`.If you need to access data before committing to the database then inspect 'serializer.validated_data' instead. 
[13/Mar/2018 17:54:15] ERROR [/media/thqbop/data/Hoctap/NNLaptrinh/Python/Projects/RiBo-Core/src/ribo_api/services/utils.py:189] ValidationError (User:None) (Field is required: ['email'])
Traceback (most recent call last):
  File "/media/thqbop/data/Hoctap/NNLaptrinh/Python/Projects/RiBo-Core/src/ribo_api/views/user.py", line 63, in create
    serializer.save()
  File "/media/thqbop/data/Hoctap/NNLaptrinh/Python/Projects/RiBo-Core/env/lib/python3.5/site-packages/rest_framework/serializers.py", line 191, in save
    self.instance = self.create(validated_data)
  File "/media/thqbop/data/Hoctap/NNLaptrinh/Python/Projects/RiBo-Core/src/ribo_api/serializers/user.py", line 13, in create
    obj = User.objects.create(**validated_data)
  File "/media/thqbop/data/Hoctap/NNLaptrinh/Python/Projects/RiBo-Core/env/lib/python3.5/site-packages/mongoengine/queryset/base.py", line 293, in create
    return self._document(**kwargs).save(force_insert=True)
  File "/media/thqbop/data/Hoctap/NNLaptrinh/Python/Projects/RiBo-Core/env/lib/python3.5/site-packages/mongoengine/document.py", line 355, in save
    self.validate(clean=clean)
  File "/media/thqbop/data/Hoctap/NNLaptrinh/Python/Projects/RiBo-Core/env/lib/python3.5/site-packages/mongoengine/base/document.py", line 395, in validate
    raise ValidationError(message, errors=errors)
mongoengine.errors.ValidationError: ValidationError (User:None) (Field is required: ['email'])
[13/Mar/2018 17:55:12] ERROR [/media/thqbop/data/Hoctap/NNLaptrinh/Python/Projects/RiBo-Core/src/ribo_api/services/utils.py:189] JSON parse error - Expecting value: line 1 column 1 (char 0)
Traceback (most recent call last):
  File "/media/thqbop/data/Hoctap/NNLaptrinh/Python/Projects/RiBo-Core/env/lib/python3.5/site-packages/rest_framework/parsers.py", line 67, in parse
    return json.loads(data)
  File "/usr/lib/python3.5/json/__init__.py", line 319, in loads
    return _default_decoder.decode(s)
  File "/usr/lib/python3.5/json/decoder.py", line 339, in decode
    obj, end = self.raw_decode(s, idx=_w(s, 0).end())
  File "/usr/lib/python3.5/json/decoder.py", line 357, in raw_decode
    raise JSONDecodeError("Expecting value", s, err.value) from None
json.decoder.JSONDecodeError: Expecting value: line 1 column 1 (char 0)

During handling of the above exception, another exception occurred:

Traceback (most recent call last):
  File "/media/thqbop/data/Hoctap/NNLaptrinh/Python/Projects/RiBo-Core/src/ribo_api/views/user.py", line 60, in create
    data = request.data.copy()
  File "/media/thqbop/data/Hoctap/NNLaptrinh/Python/Projects/RiBo-Core/env/lib/python3.5/site-packages/rest_framework/request.py", line 353, in __getattribute__
    return super(Request, self).__getattribute__(attr)
  File "/media/thqbop/data/Hoctap/NNLaptrinh/Python/Projects/RiBo-Core/env/lib/python3.5/site-packages/rest_framework/request.py", line 183, in data
    self._load_data_and_files()
  File "/media/thqbop/data/Hoctap/NNLaptrinh/Python/Projects/RiBo-Core/env/lib/python3.5/site-packages/rest_framework/request.py", line 243, in _load_data_and_files
    self._data, self._files = self._parse()
  File "/media/thqbop/data/Hoctap/NNLaptrinh/Python/Projects/RiBo-Core/env/lib/python3.5/site-packages/rest_framework/request.py", line 289, in _parse
    parsed = parser.parse(stream, media_type, self.parser_context)
  File "/media/thqbop/data/Hoctap/NNLaptrinh/Python/Projects/RiBo-Core/env/lib/python3.5/site-packages/rest_framework/parsers.py", line 69, in parse
    raise ParseError('JSON parse error - %s' % six.text_type(exc))
rest_framework.exceptions.ParseError: JSON parse error - Expecting value: line 1 column 1 (char 0)
[13/Mar/2018 17:55:21] ERROR [/media/thqbop/data/Hoctap/NNLaptrinh/Python/Projects/RiBo-Core/src/ribo_api/services/utils.py:189] ValidationError (User:None) (Field is required: ['email_address'])
Traceback (most recent call last):
  File "/media/thqbop/data/Hoctap/NNLaptrinh/Python/Projects/RiBo-Core/src/ribo_api/views/user.py", line 63, in create
    serializer.save()
  File "/media/thqbop/data/Hoctap/NNLaptrinh/Python/Projects/RiBo-Core/env/lib/python3.5/site-packages/rest_framework/serializers.py", line 191, in save
    self.instance = self.create(validated_data)
  File "/media/thqbop/data/Hoctap/NNLaptrinh/Python/Projects/RiBo-Core/src/ribo_api/serializers/user.py", line 13, in create
    obj = User.objects.create(**validated_data)
  File "/media/thqbop/data/Hoctap/NNLaptrinh/Python/Projects/RiBo-Core/env/lib/python3.5/site-packages/mongoengine/queryset/base.py", line 293, in create
    return self._document(**kwargs).save(force_insert=True)
  File "/media/thqbop/data/Hoctap/NNLaptrinh/Python/Projects/RiBo-Core/env/lib/python3.5/site-packages/mongoengine/document.py", line 355, in save
    self.validate(clean=clean)
  File "/media/thqbop/data/Hoctap/NNLaptrinh/Python/Projects/RiBo-Core/env/lib/python3.5/site-packages/mongoengine/base/document.py", line 395, in validate
    raise ValidationError(message, errors=errors)
mongoengine.errors.ValidationError: ValidationError (User:None) (Field is required: ['email_address'])
[13/Mar/2018 17:55:42] ERROR [/media/thqbop/data/Hoctap/NNLaptrinh/Python/Projects/RiBo-Core/src/ribo_api/services/utils.py:189] ValidationError (User:None) (Field is required: ['email_address'])
Traceback (most recent call last):
  File "/media/thqbop/data/Hoctap/NNLaptrinh/Python/Projects/RiBo-Core/src/ribo_api/views/user.py", line 63, in create
    serializer.save()
  File "/media/thqbop/data/Hoctap/NNLaptrinh/Python/Projects/RiBo-Core/env/lib/python3.5/site-packages/rest_framework/serializers.py", line 191, in save
    self.instance = self.create(validated_data)
  File "/media/thqbop/data/Hoctap/NNLaptrinh/Python/Projects/RiBo-Core/src/ribo_api/serializers/user.py", line 13, in create
    obj = User.objects.create(**validated_data)
  File "/media/thqbop/data/Hoctap/NNLaptrinh/Python/Projects/RiBo-Core/env/lib/python3.5/site-packages/mongoengine/queryset/base.py", line 293, in create
    return self._document(**kwargs).save(force_insert=True)
  File "/media/thqbop/data/Hoctap/NNLaptrinh/Python/Projects/RiBo-Core/env/lib/python3.5/site-packages/mongoengine/document.py", line 355, in save
    self.validate(clean=clean)
  File "/media/thqbop/data/Hoctap/NNLaptrinh/Python/Projects/RiBo-Core/env/lib/python3.5/site-packages/mongoengine/base/document.py", line 395, in validate
    raise ValidationError(message, errors=errors)
mongoengine.errors.ValidationError: ValidationError (User:None) (Field is required: ['email_address'])
[13/Mar/2018 17:58:57] ERROR [/media/thqbop/data/Hoctap/NNLaptrinh/Python/Projects/RiBo-Core/src/ribo_api/services/utils.py:189] {'email': ['This field must be unique.']}
Traceback (most recent call last):
  File "/media/thqbop/data/Hoctap/NNLaptrinh/Python/Projects/RiBo-Core/src/ribo_api/views/user.py", line 62, in create
    serializer.is_valid(raise_exception=True)
  File "/media/thqbop/data/Hoctap/NNLaptrinh/Python/Projects/RiBo-Core/env/lib/python3.5/site-packages/rest_framework/serializers.py", line 221, in is_valid
    raise ValidationError(self.errors)
rest_framework.exceptions.ValidationError: {'email': ['This field must be unique.']}
